# 陨石浮冰岛的生成文件
# 特点是浮冰岛有含有岩浆的陨石上放着一个装有电路板和陨石块、下面有TNT的陷阱箱
# 在水星的水面生成

weight=1
embed_into_distance=4
acceptable_target_blocks=water
unacceptable_target_blocks=
dimensions=11,13,13
allowable_overhang=0
max_leveling=0
leveling_buffer=0
preserve_water=0
preserve_lava=0
biomesToSpawnIn=<plains>

rule1=0,100,minecraft:packed_ice-0
rule2=0,100,appliedenergistics2:sky_stone_block-0
rule3=0,100,minecraft:lava-14
rule4=0,100,minecraft:lava-2
rule5=0,100,minecraft:lava-4
rule6=0,100,minecraft:lava-0
rule7=0,100,minecraft:lava-6
rule8=0,100,minecraft:tnt-0
rule9=0,100,IInventory;minecraft:trapped_chest;appliedenergistics2:material#1#16#4+appliedenergistics2:material#1#20#11+appliedenergistics2:sky_stone_block#5#0#16+appliedenergistics2:material#1#17#18+appliedenergistics2:sky_stone_block#4#0#23+appliedenergistics2:material#1#18#3-2
rule10=0,100,minecraft:preserveBlock

layer
10,10,10,10,10,10,10,10,10,10,10,10,10
10,10,10,10,10,10,10,10,10,10,10,10,10
10,10,10,10,10,10,10,10,10,10,10,10,10
10,10,10,10,10,10,10,10,10,10,10,10,10
10,10,10,10,10,10,10,10,10,10,10,10,10
10,10,10,10,1,1,1,10,10,10,10,10,10
10,10,10,10,1,1,1,10,10,10,10,10,10
10,10,10,1,1,1,1,10,10,10,10,10,10
10,10,10,1,1,1,10,10,10,10,10,10,10
10,10,10,1,1,1,10,10,10,10,10,10,10
10,10,10,10,10,10,10,10,10,10,10,10,10
10,10,10,10,10,10,10,10,10,10,10,10,10
10,10,10,10,10,10,10,10,10,10,10,10,10
endlayer

layer
10,10,10,10,10,10,10,10,10,10,10,10,10
10,10,10,10,10,10,10,10,10,10,10,10,10
10,10,10,10,10,10,10,10,10,10,10,10,10
10,10,10,1,1,1,10,1,1,1,1,1,10
10,1,1,1,1,1,1,1,1,1,1,1,10
10,1,1,1,1,1,1,1,1,1,1,1,10
10,1,1,1,1,1,1,1,1,1,10,10,10
10,10,1,1,1,1,1,1,1,1,10,10,10
10,10,1,1,1,1,1,1,1,1,10,10,10
10,10,1,1,1,1,1,1,1,1,10,10,10
10,10,10,1,1,1,10,1,1,1,10,10,10
10,10,10,10,10,10,10,10,10,10,10,10,10
10,10,10,10,10,10,10,10,10,10,10,10,10
endlayer

layer
10,10,10,10,10,10,10,10,10,10,10,10,10
10,10,10,10,10,10,10,10,10,10,10,10,10
10,10,10,1,1,1,10,1,1,1,1,1,10
10,1,1,1,1,1,1,1,1,1,1,1,1
1,1,1,1,1,1,1,1,1,1,1,1,1
1,1,1,1,1,1,1,1,1,1,1,1,1
1,1,1,1,1,1,1,1,1,1,1,1,10
10,1,1,1,1,1,1,1,1,1,1,10,10
10,10,1,1,1,1,1,1,1,1,1,10,10
10,10,1,1,1,1,1,1,1,1,1,10,10
10,10,10,1,1,1,1,1,1,1,1,10,10
10,10,10,10,10,10,10,1,1,1,10,10,10
10,10,10,10,10,10,10,10,10,10,10,10,10
endlayer

layer
10,10,10,10,10,10,10,10,10,10,10,10,10
10,10,10,10,10,10,10,10,10,10,10,10,10
10,10,2,1,1,1,1,1,1,1,1,1,10
10,1,1,1,1,1,1,1,1,1,1,1,1
1,1,1,1,1,1,1,1,1,1,1,1,1
1,1,1,1,1,1,1,1,1,1,1,1,1
1,1,1,1,1,1,1,1,1,1,1,1,10
10,1,1,1,1,1,1,1,1,1,1,10,10
10,10,1,1,1,1,1,1,1,1,1,10,10
10,10,1,1,1,1,1,1,1,1,1,10,10
10,10,10,1,1,1,1,1,1,1,1,10,10
10,10,10,10,10,10,10,1,1,1,10,10,10
10,10,10,10,10,10,10,10,10,10,10,10,10
endlayer

layer
10,10,10,10,10,10,10,10,10,10,10,10,10
10,10,10,10,10,10,10,10,10,10,10,10,10
10,2,2,1,1,1,1,1,1,1,1,1,10
2,1,1,1,1,1,1,1,1,1,1,1,1
1,1,1,1,1,1,1,1,1,1,1,1,1
1,1,1,1,1,10,10,1,1,1,1,1,1
1,1,1,1,1,10,10,10,1,1,1,1,10
2,1,1,1,1,1,10,10,1,1,1,10,10
10,2,2,1,1,1,1,1,1,1,1,10,10
10,10,10,1,1,1,1,1,1,1,1,10,10
10,10,10,10,10,1,1,1,1,1,1,10,10
10,10,10,10,10,10,10,1,1,1,10,10,10
10,10,10,10,10,10,10,10,10,10,10,10,10
endlayer

layer
10,10,10,10,10,10,10,10,10,10,10,10,10
10,10,10,10,10,10,10,10,10,10,10,10,10
10,2,2,2,1,1,1,10,10,10,10,10,10
2,2,2,1,1,1,1,1,10,1,1,1,10
2,1,1,1,1,1,1,1,1,1,1,1,10
2,1,1,1,1,1,1,1,1,1,1,1,10
2,1,1,1,1,1,1,1,1,1,10,10,10
2,2,1,1,1,1,1,1,1,1,10,10,10
10,2,2,2,1,1,1,1,1,1,10,10,10
10,10,10,2,2,2,1,1,1,1,10,10,10
10,10,10,10,10,10,10,1,1,1,10,10,10
10,10,10,10,10,10,10,10,10,10,10,10,10
10,10,10,10,10,10,10,10,10,10,10,10,10
endlayer

layer
10,10,10,10,10,10,10,10,10,10,10,10,10
10,10,10,10,10,10,10,10,10,10,10,10,10
10,2,2,2,1,1,1,10,10,10,10,10,10
2,2,2,2,1,1,2,10,10,10,10,10,10
2,2,2,1,1,1,2,1,10,10,10,10,10
2,2,2,1,1,1,1,1,1,10,10,10,10
2,2,2,1,1,2,1,3,1,10,10,10,10
10,2,2,2,1,1,1,4,1,10,10,10,10
10,10,2,2,2,2,1,1,1,10,10,10,10
10,10,10,2,2,10,1,10,10,10,10,10,10
10,10,10,10,10,10,10,10,10,10,10,10,10
10,10,10,10,10,10,10,10,10,10,10,10,10
10,10,10,10,10,10,10,10,10,10,10,10,10
endlayer

layer
10,10,10,10,10,10,10,10,10,10,10,10,10
10,10,10,10,10,10,10,10,10,10,10,10,10
10,10,10,2,2,2,10,10,10,10,10,10,10
10,2,2,2,2,2,2,10,10,10,10,10,10
2,2,2,2,2,2,2,10,10,10,10,10,10
2,2,2,2,2,6,4,5,10,10,10,10,10
10,2,2,2,2,2,2,7,10,10,10,10,10
10,10,2,2,2,2,2,10,10,10,10,10,10
10,10,10,2,2,2,10,10,10,10,10,10,10
10,10,10,10,10,10,10,10,10,10,10,10,10
10,10,10,10,10,10,10,10,10,10,10,10,10
10,10,10,10,10,10,10,10,10,10,10,10,10
10,10,10,10,10,10,10,10,10,10,10,10,10
endlayer

layer
10,10,10,10,10,10,10,10,10,10,10,10,10
10,10,10,10,10,10,10,10,10,10,10,10,10
10,10,10,10,10,10,10,10,10,10,10,10,10
10,10,2,2,2,2,10,10,10,10,10,10,10
10,2,2,2,2,2,10,10,10,10,10,10,10
10,2,2,2,4,5,10,10,10,10,10,10,10
10,10,2,2,6,2,10,10,10,10,10,10,10
10,10,10,2,2,2,10,10,10,10,10,10,10
10,10,10,10,10,10,10,10,10,10,10,10,10
10,10,10,10,10,10,10,10,10,10,10,10,10
10,10,10,10,10,10,10,10,10,10,10,10,10
10,10,10,10,10,10,10,10,10,10,10,10,10
10,10,10,10,10,10,10,10,10,10,10,10,10
endlayer

layer
10,10,10,10,10,10,10,10,10,10,10,10,10
10,10,10,10,10,10,10,10,10,10,10,10,10
10,10,10,10,10,10,10,10,10,10,10,10,10
10,10,10,10,10,10,10,10,10,10,10,10,10
10,10,2,2,2,10,10,10,10,10,10,10,10
10,10,2,8,2,2,10,10,10,10,10,10,10
10,10,10,2,10,10,10,10,10,10,10,10,10
10,10,10,10,10,10,10,10,10,10,10,10,10
10,10,10,10,10,10,10,10,10,10,10,10,10
10,10,10,10,10,10,10,10,10,10,10,10,10
10,10,10,10,10,10,10,10,10,10,10,10,10
10,10,10,10,10,10,10,10,10,10,10,10,10
10,10,10,10,10,10,10,10,10,10,10,10,10
endlayer

layer
10,10,10,10,10,10,10,10,10,10,10,10,10
10,10,10,10,10,10,10,10,10,10,10,10,10
10,10,10,10,10,10,10,10,10,10,10,10,10
10,10,10,10,10,10,10,10,10,10,10,10,10
10,10,10,10,10,10,10,10,10,10,10,10,10
10,10,10,9,10,10,10,10,10,10,10,10,10
10,10,10,10,10,10,10,10,10,10,10,10,10
10,10,10,10,10,10,10,10,10,10,10,10,10
10,10,10,10,10,10,10,10,10,10,10,10,10
10,10,10,10,10,10,10,10,10,10,10,10,10
10,10,10,10,10,10,10,10,10,10,10,10,10
10,10,10,10,10,10,10,10,10,10,10,10,10
10,10,10,10,10,10,10,10,10,10,10,10,10
endlayer

