# 木板浮冰岛的生成文件
# 特点是浮冰岛上有木板和树叶，内部含有蜘蛛网、铁栏杆、苔石和两个地牢箱子
# 在水星的水面生成

weight=1
embed_into_distance=4
acceptable_target_blocks=water
unacceptable_target_blocks=
dimensions=21,17,17
allowable_overhang=0
max_leveling=0
leveling_buffer=0
preserve_water=0
preserve_lava=0
biomesToSpawnIn=<plains>

rule1=0,100,minecraft:packed_ice-0
rule2=0,100,minecraft:ice-0
rule3=0,100,minecraft:water-0
rule4=0,100,minecraft:glowstone-0
rule5=0,100,minecraft:iron_bars-0
rule6=0,100,minecraft:mossy_cobblestone-0
rule7=0,100,ChestGenHook:chests/simple_dungeon:5-2
rule8=0,100,minecraft:web-0
rule9=0,100,minecraft:planks-4
rule10=0,100,minecraft:leaves2-0
rule11=0,100,minecraft:preserveBlock

layer
11,11,11,11,11,11,11,11,11,11,11,11,11,11,11,11,11
11,11,11,11,11,11,11,11,11,11,11,11,11,11,11,11,11
11,11,11,11,11,11,11,11,11,11,11,11,11,11,11,11,11
11,11,11,11,11,11,1,11,11,11,11,11,11,11,11,11,11
11,11,11,11,11,11,11,11,1,1,1,11,11,11,11,11,11
11,11,11,11,11,11,11,11,1,1,1,11,11,11,11,11,11
11,11,11,11,11,11,11,11,1,1,1,11,11,11,11,11,11
11,11,11,11,11,11,11,11,2,11,11,11,11,11,11,11,11
11,11,11,11,11,11,11,11,11,11,11,11,11,11,11,11,11
11,11,11,11,11,11,11,11,11,11,11,11,11,11,11,11,11
11,11,11,11,11,11,11,11,11,11,11,11,11,11,11,11,11
11,11,11,11,11,11,11,11,1,1,1,11,11,11,11,11,11
11,11,11,11,1,1,1,1,1,1,1,11,11,11,11,11,11
11,11,11,11,1,1,1,1,1,1,1,11,11,11,11,11,11
11,11,11,11,1,1,1,1,1,11,11,11,11,11,11,11,11
11,11,11,11,1,1,1,1,1,11,11,11,11,11,11,11,11
11,11,11,11,1,1,1,1,1,11,11,11,11,11,11,11,11
endlayer

layer
11,11,11,11,11,11,11,11,11,11,11,11,11,11,11,11,11
11,11,11,11,11,11,11,11,11,11,11,11,11,11,11,11,11
11,11,11,11,11,2,1,2,11,11,11,11,11,11,11,11,11
11,11,11,2,2,2,3,1,1,1,1,1,11,11,11,11,11
11,11,11,2,2,2,2,1,1,1,1,1,11,11,11,11,11
11,11,11,2,2,2,11,1,1,1,1,1,11,11,11,11,11
11,11,2,2,2,2,2,1,1,1,1,1,11,11,11,11,11
11,11,2,2,2,2,2,1,1,1,1,1,11,11,11,11,11
11,11,2,2,2,2,2,2,2,1,1,1,11,11,11,11,11
11,11,11,11,11,2,2,2,2,1,1,1,11,11,11,11,11
11,11,11,2,2,2,2,1,1,1,1,1,11,11,11,11,11
11,11,11,2,2,1,1,1,1,1,1,1,11,11,11,11,11
11,11,11,2,1,1,1,1,1,1,1,1,11,11,11,11,11
11,11,11,1,1,1,1,1,1,1,1,1,11,11,11,11,11
11,11,11,1,1,1,1,1,1,1,1,1,11,11,11,11,11
11,11,11,1,1,1,1,1,1,1,11,11,11,11,11,11,11
11,11,11,11,1,1,1,1,1,11,11,11,11,11,11,11,11
endlayer

layer
11,11,11,11,11,11,11,11,11,11,11,11,11,11,11,11,11
11,11,11,11,11,2,1,2,11,11,11,11,11,11,11,11,11
11,11,11,2,2,2,3,2,1,1,1,11,11,11,11,11,11
11,11,2,2,2,3,3,1,1,1,1,1,11,11,11,11,11
11,11,2,2,2,2,1,1,1,1,1,1,1,11,11,11,11
11,11,2,2,2,2,1,1,1,1,1,1,1,11,11,11,11
11,2,2,2,2,2,1,1,1,1,1,1,1,11,11,11,11
11,2,2,2,2,2,1,1,1,1,1,1,1,11,11,11,11
11,2,2,2,2,2,1,1,1,1,1,1,1,11,11,11,11
11,2,2,2,2,2,1,1,1,1,1,1,1,11,11,11,11
11,11,2,2,2,2,2,1,1,1,1,1,1,11,11,11,11
11,11,2,2,2,1,1,1,1,1,1,1,1,11,11,11,11
11,11,2,2,1,1,1,1,1,1,1,1,1,11,11,11,11
11,11,11,1,1,1,1,1,1,1,1,1,1,11,11,11,11
11,11,11,1,1,1,1,1,1,1,1,1,11,11,11,11,11
11,11,11,1,1,1,1,1,1,1,1,11,11,11,11,11,11
11,11,11,11,1,1,1,1,1,11,11,11,11,11,11,11,11
endlayer

layer
11,11,11,11,11,11,11,11,11,11,11,11,11,11,11,11,11
11,11,11,11,11,2,1,2,11,11,11,11,11,11,11,11,11
11,11,11,2,2,3,3,3,1,1,1,11,11,11,11,11,11
11,11,2,2,3,3,4,1,1,1,1,1,11,11,11,11,11
11,11,2,2,2,3,1,1,1,1,1,1,1,11,11,11,11
11,11,2,2,2,2,1,1,1,1,1,1,1,11,11,11,11
11,2,2,2,2,1,1,1,1,1,1,1,1,11,11,11,11
2,2,2,2,2,5,11,1,1,1,1,1,1,11,11,11,11
11,2,2,2,2,5,11,1,1,1,1,1,1,1,11,11,11
11,2,2,2,2,7,11,6,1,1,1,1,1,1,11,11,11
11,2,2,2,2,1,6,1,1,1,1,1,1,1,11,11,11
11,11,2,2,2,1,1,1,1,1,1,1,1,11,11,11,11
11,11,2,2,1,1,1,1,1,1,1,1,1,11,11,11,11
11,11,11,1,1,1,1,1,1,1,1,1,1,11,11,11,11
11,11,11,1,1,1,1,1,1,1,1,1,11,11,11,11,11
11,11,11,1,1,1,1,1,1,1,1,11,11,11,11,11,11
11,11,11,11,1,1,1,1,1,11,11,11,11,11,11,11,11
endlayer

layer
11,11,11,11,11,11,11,11,11,11,11,11,11,11,11,11,11
11,11,11,11,11,2,2,2,11,11,11,11,11,11,11,11,11
11,11,11,2,2,2,3,2,1,1,1,11,11,11,11,11,11
11,11,2,2,2,3,3,1,1,1,1,1,11,11,11,11,11
11,11,2,2,2,2,1,1,1,1,1,1,1,11,11,11,11
11,11,2,2,2,2,1,1,1,1,1,1,1,11,11,11,11
11,2,2,2,2,1,1,1,1,1,1,1,1,11,11,11,11
11,2,3,1,7,11,11,11,1,1,1,1,1,11,11,11,11
11,2,1,1,5,11,11,11,11,1,1,1,1,1,11,11,11
11,2,3,1,1,11,11,8,6,1,1,1,1,1,11,11,11
11,11,1,1,1,1,6,1,1,1,1,1,1,1,11,11,11
11,11,2,1,3,3,1,1,1,1,1,1,1,11,11,11,11
11,11,2,2,1,4,1,1,1,1,1,1,1,11,11,11,11
11,11,11,2,1,1,1,1,1,1,1,1,1,11,11,11,11
11,11,11,11,1,1,1,1,1,1,1,1,11,11,11,11,11
11,11,11,11,1,1,1,1,1,1,1,11,11,11,11,11,11
11,11,11,11,1,1,1,1,1,11,11,11,11,11,11,11,11
endlayer

layer
11,11,11,11,11,11,11,11,11,11,11,11,11,11,11,11,11
11,11,11,11,11,11,11,11,11,11,11,11,11,11,11,11,11
11,11,11,11,11,2,2,2,11,11,11,11,11,11,11,11,11
11,11,11,11,2,2,1,1,1,1,1,1,11,11,11,11,11
11,11,11,2,2,2,2,1,1,1,1,1,11,11,11,11,11
11,11,11,2,2,2,1,1,1,1,1,1,11,11,11,11,11
11,11,2,2,1,1,1,1,1,1,1,1,11,11,11,11,11
11,11,1,1,8,11,11,11,11,1,1,1,1,11,11,11,11
11,11,1,1,6,11,11,11,11,1,1,1,1,1,11,11,11
11,11,1,1,1,8,11,11,8,1,1,1,1,1,11,11,11
11,11,1,1,1,1,1,1,1,1,1,1,1,1,11,11,11
11,11,1,1,1,1,1,1,1,1,1,1,1,11,11,11,11
11,11,11,2,1,1,3,1,1,1,1,1,11,11,11,11,11
11,11,11,11,2,1,1,1,1,1,1,1,11,11,11,11,11
11,11,11,11,11,1,9,9,1,1,1,1,11,11,11,11,11
11,11,11,11,11,1,1,1,11,11,11,11,11,11,11,11,11
11,11,11,11,11,11,11,11,11,11,11,11,11,11,11,11,11
endlayer

layer
11,11,11,11,11,11,11,11,11,11,11,11,11,11,11,11,11
11,11,11,11,11,11,11,11,11,11,11,11,11,11,11,11,11
11,11,11,11,11,11,11,11,11,11,11,11,11,11,11,11,11
11,11,11,11,11,9,11,11,11,11,11,11,11,11,11,11,11
11,11,11,11,11,11,2,2,1,1,1,11,11,11,11,11,11
11,11,11,11,11,11,1,1,1,1,1,11,11,11,11,11,11
11,11,11,11,11,1,1,1,1,1,1,11,11,11,11,11,11
11,11,11,1,1,1,1,11,11,11,1,1,1,11,11,11,11
11,11,1,1,1,1,1,11,11,11,1,1,1,11,11,11,11
11,11,9,1,9,1,1,1,1,1,1,1,1,11,11,11,11
11,11,9,1,1,1,1,1,1,1,1,1,1,11,11,11,11
11,11,9,1,1,1,1,1,1,1,1,1,1,11,11,11,11
11,11,11,11,1,1,1,9,1,1,1,11,11,11,11,11,11
11,11,11,11,11,9,1,1,1,1,1,11,11,11,11,11,11
11,11,11,11,11,9,9,11,11,11,11,11,11,11,11,11,11
11,11,11,11,11,11,11,11,11,11,11,11,11,11,11,11,11
11,11,11,11,11,11,11,11,11,11,11,11,11,11,11,11,11
endlayer

layer
11,11,11,11,11,11,11,11,11,11,11,11,11,11,11,11,11
11,11,11,11,11,11,11,11,11,11,11,11,11,11,11,11,11
11,11,11,11,11,11,11,11,11,11,11,11,11,11,11,11,11
11,11,11,11,11,9,11,11,11,11,11,11,11,11,11,11,11
11,11,11,11,11,11,11,11,11,11,11,11,11,11,11,11,11
11,11,11,11,11,11,11,11,9,11,11,11,11,11,11,11,11
11,11,11,11,11,1,1,1,1,1,11,11,11,11,11,11,11
11,11,11,11,11,1,1,1,11,11,9,11,11,11,11,11,11
11,11,11,11,11,1,1,1,1,11,1,1,11,11,11,11,11
11,11,11,11,11,1,1,1,1,1,1,1,11,11,11,11,11
11,11,11,11,9,9,9,1,1,1,1,1,11,11,11,11,11
11,11,11,11,11,9,11,11,11,9,9,11,11,11,11,11,11
11,11,11,11,11,11,11,11,11,11,11,11,11,11,11,11,11
11,11,11,11,11,11,11,11,11,11,11,11,11,11,11,11,11
11,11,11,11,11,9,9,11,11,11,11,11,11,11,11,11,11
11,11,11,11,11,11,11,11,11,11,11,11,11,11,11,11,11
11,11,11,11,11,11,11,11,11,11,11,11,11,11,11,11,11
endlayer

layer
11,11,11,11,11,11,11,11,11,11,11,11,11,11,11,11,11
11,11,11,11,11,11,11,11,11,11,11,11,11,11,11,11,11
11,11,11,11,11,11,11,11,11,11,11,11,11,11,11,11,11
11,11,11,11,11,10,11,11,11,11,11,11,11,11,11,11,11
11,11,11,11,11,11,11,11,11,11,11,11,11,11,11,11,11
11,11,11,11,11,11,11,11,9,11,11,11,11,11,11,11,11
11,11,11,11,11,11,11,9,9,11,11,11,11,11,11,11,11
11,11,11,11,11,11,11,11,11,11,11,11,11,11,11,11,11
11,11,11,11,11,11,11,11,11,11,9,11,11,11,11,11,11
11,11,11,11,11,11,11,11,11,9,9,11,11,11,11,11,11
11,11,11,11,9,9,11,11,11,11,11,11,11,11,11,11,11
11,11,11,11,11,11,11,11,11,11,11,11,11,11,11,11,11
11,11,11,11,11,11,11,11,11,11,11,11,11,11,11,11,11
11,11,11,11,11,11,11,11,11,11,11,11,11,11,11,11,11
11,11,11,11,11,11,9,11,11,11,11,11,11,11,11,11,11
11,11,11,11,11,11,11,11,11,11,11,11,11,11,11,11,11
11,11,11,11,11,11,11,11,11,11,11,11,11,11,11,11,11
endlayer

layer
11,11,11,11,11,11,11,11,11,11,11,11,11,11,11,11,11
11,11,11,11,11,11,11,11,11,11,11,11,11,11,11,11,11
11,11,11,11,11,11,11,11,11,11,11,11,11,11,11,11,11
11,11,11,11,11,10,11,11,11,11,11,11,11,11,11,11,11
11,11,11,11,11,11,11,11,11,11,11,11,11,11,11,11,11
11,11,11,11,11,11,11,11,11,11,11,11,11,11,11,11,11
11,11,11,11,11,11,11,11,9,11,11,11,11,11,11,11,11
11,11,11,11,11,11,11,11,11,11,11,11,11,11,11,11,11
11,11,11,11,11,11,11,11,11,11,11,11,11,11,11,11,11
11,11,11,11,11,11,11,11,11,11,9,11,11,11,11,11,11
11,11,11,11,11,9,11,11,11,11,11,11,11,11,11,11,11
11,11,11,11,11,11,11,11,11,11,11,11,11,11,11,11,11
11,11,11,11,11,11,11,11,11,11,11,11,11,11,11,11,11
11,11,11,11,11,11,11,11,11,11,11,11,11,11,11,11,11
11,11,11,11,11,11,9,11,11,11,11,11,11,11,11,11,11
11,11,11,11,11,11,11,11,11,11,11,11,11,11,11,11,11
11,11,11,11,11,11,11,11,11,11,11,11,11,11,11,11,11
endlayer

layer
11,11,11,11,11,11,11,11,11,11,11,11,11,11,11,11,11
11,11,11,11,11,11,11,11,11,11,11,11,11,11,11,11,11
11,11,11,11,11,11,11,11,11,11,11,11,11,11,11,11,11
11,11,11,11,11,10,11,11,11,11,11,11,11,11,11,11,11
11,11,11,11,11,11,11,11,11,11,11,11,11,11,11,11,11
11,11,11,11,11,11,11,11,11,11,11,11,11,11,11,11,11
11,11,11,11,11,11,11,11,10,11,11,11,11,11,11,11,11
11,11,11,11,11,11,11,11,11,11,11,11,11,11,11,11,11
11,11,11,11,11,11,11,11,11,11,11,11,11,11,11,11,11
11,11,11,11,11,11,11,11,11,11,10,11,11,11,11,11,11
11,11,11,11,11,9,11,11,11,11,11,11,11,11,11,11,11
11,11,11,11,11,11,11,11,11,11,11,11,11,11,11,11,11
11,11,11,11,11,11,11,11,11,11,11,11,11,11,11,11,11
11,11,11,11,11,11,11,11,11,11,11,11,11,11,11,11,11
11,11,11,11,11,11,9,11,11,11,11,11,11,11,11,11,11
11,11,11,11,11,11,11,11,11,11,11,11,11,11,11,11,11
11,11,11,11,11,11,11,11,11,11,11,11,11,11,11,11,11
endlayer

layer
11,11,11,11,11,11,11,11,11,11,11,11,11,11,11,11,11
11,11,11,11,11,11,11,11,11,11,11,11,11,11,11,11,11
11,11,11,11,11,11,11,11,11,11,11,11,11,11,11,11,11
11,11,11,11,11,10,11,11,11,11,11,11,11,11,11,11,11
11,11,11,11,11,11,11,11,11,11,11,11,11,11,11,11,11
11,11,11,11,11,11,11,11,11,11,11,11,11,11,11,11,11
11,11,11,11,11,11,11,11,10,11,11,11,11,11,11,11,11
11,11,11,11,11,11,11,11,11,11,11,11,11,11,11,11,11
11,11,11,11,11,11,11,11,11,11,11,11,11,11,11,11,11
11,11,11,11,11,11,11,11,11,11,10,11,11,11,11,11,11
11,11,11,11,11,9,11,11,11,11,11,11,11,11,11,11,11
11,11,11,11,11,11,11,11,11,11,11,11,11,11,11,11,11
11,11,11,11,11,11,11,11,11,11,11,11,11,11,11,11,11
11,11,11,11,11,11,11,11,11,11,11,11,11,11,11,11,11
11,11,11,11,11,11,10,11,11,11,11,11,11,11,11,11,11
11,11,11,11,11,11,11,11,11,11,11,11,11,11,11,11,11
11,11,11,11,11,11,11,11,11,11,11,11,11,11,11,11,11
endlayer

layer
11,11,11,11,11,11,11,11,11,11,11,11,11,11,11,11,11
11,11,11,11,11,11,11,11,11,11,11,11,11,11,11,11,11
11,11,11,11,11,10,11,11,11,11,11,11,11,11,11,11,11
11,11,11,11,10,10,10,11,11,11,11,11,11,11,11,11,11
11,11,11,11,11,10,11,11,11,11,11,11,11,11,11,11,11
11,11,11,11,11,11,11,11,11,11,11,11,11,11,11,11,11
11,11,11,11,11,11,11,11,10,11,11,11,11,11,11,11,11
11,11,11,11,11,11,11,11,11,11,11,11,11,11,11,11,11
11,11,11,11,11,11,11,11,11,11,11,11,11,11,11,11,11
11,11,11,11,11,11,11,11,11,11,10,11,11,11,11,11,11
11,11,11,11,11,10,11,11,11,11,11,11,11,11,11,11,11
11,11,11,11,11,11,11,11,11,11,11,11,11,11,11,11,11
11,11,11,11,11,11,11,11,11,11,11,11,11,11,11,11,11
11,11,11,11,11,11,11,11,11,11,11,11,11,11,11,11,11
11,11,11,11,11,11,10,11,11,11,11,11,11,11,11,11,11
11,11,11,11,11,11,11,11,11,11,11,11,11,11,11,11,11
11,11,11,11,11,11,11,11,11,11,11,11,11,11,11,11,11
endlayer

layer
11,11,11,11,11,11,11,11,11,11,11,11,11,11,11,11,11
11,11,11,11,11,11,11,11,11,11,11,11,11,11,11,11,11
11,11,11,11,11,11,11,11,11,11,11,11,11,11,11,11,11
11,11,11,11,11,11,11,11,11,11,11,11,11,11,11,11,11
11,11,11,11,11,11,11,11,11,11,11,11,11,11,11,11,11
11,11,11,11,11,11,11,11,11,11,11,11,11,11,11,11,11
11,11,11,11,11,11,11,11,10,11,11,11,11,11,11,11,11
11,11,11,11,11,11,11,11,11,11,11,11,11,11,11,11,11
11,11,11,11,11,11,11,11,11,11,11,11,11,11,11,11,11
11,11,11,11,11,11,11,11,11,11,10,11,11,11,11,11,11
11,11,11,11,11,10,11,11,11,11,11,11,11,11,11,11,11
11,11,11,11,11,11,11,11,11,11,11,11,11,11,11,11,11
11,11,11,11,11,11,11,11,11,11,11,11,11,11,11,11,11
11,11,11,11,11,11,11,11,11,11,11,11,11,11,11,11,11
11,11,11,11,11,11,10,11,11,11,11,11,11,11,11,11,11
11,11,11,11,11,11,11,11,11,11,11,11,11,11,11,11,11
11,11,11,11,11,11,11,11,11,11,11,11,11,11,11,11,11
endlayer

layer
11,11,11,11,11,11,11,11,11,11,11,11,11,11,11,11,11
11,11,11,11,11,11,11,11,11,11,11,11,11,11,11,11,11
11,11,11,11,11,11,11,11,11,11,11,11,11,11,11,11,11
11,11,11,11,11,11,11,11,11,11,11,11,11,11,11,11,11
11,11,11,11,11,11,11,11,11,11,11,11,11,11,11,11,11
11,11,11,11,11,11,11,11,11,11,11,11,11,11,11,11,11
11,11,11,11,11,11,11,11,10,11,11,11,11,11,11,11,11
11,11,11,11,11,11,11,11,11,11,11,11,11,11,11,11,11
11,11,11,11,11,11,11,11,11,11,11,11,11,11,11,11,11
11,11,11,11,11,11,11,11,11,11,10,11,11,11,11,11,11
11,11,11,11,11,10,11,11,11,11,11,11,11,11,11,11,11
11,11,11,11,11,11,11,11,11,11,11,11,11,11,11,11,11
11,11,11,11,11,11,11,11,11,11,11,11,11,11,11,11,11
11,11,11,11,11,11,11,11,11,11,11,11,11,11,11,11,11
11,11,11,11,11,11,10,11,11,11,11,11,11,11,11,11,11
11,11,11,11,11,11,11,11,11,11,11,11,11,11,11,11,11
11,11,11,11,11,11,11,11,11,11,11,11,11,11,11,11,11
endlayer

layer
11,11,11,11,11,11,11,11,11,11,11,11,11,11,11,11,11
11,11,11,11,11,11,11,11,11,11,11,11,11,11,11,11,11
11,11,11,11,11,11,11,11,11,11,11,11,11,11,11,11,11
11,11,11,11,11,11,11,11,11,11,11,11,11,11,11,11,11
11,11,11,11,11,11,11,11,11,11,11,11,11,11,11,11,11
11,11,11,11,11,11,11,11,11,11,11,11,11,11,11,11,11
11,11,11,11,11,11,11,11,10,11,11,11,11,11,11,11,11
11,11,11,11,11,11,11,11,11,11,11,11,11,11,11,11,11
11,11,11,11,11,11,11,11,11,11,10,11,11,11,11,11,11
11,11,11,11,11,11,11,11,11,10,10,10,11,11,11,11,11
11,11,11,11,11,10,11,11,11,11,10,11,11,11,11,11,11
11,11,11,11,11,11,11,11,11,11,11,11,11,11,11,11,11
11,11,11,11,11,11,11,11,11,11,11,11,11,11,11,11,11
11,11,11,11,11,11,11,11,11,11,11,11,11,11,11,11,11
11,11,11,11,11,11,10,11,11,11,11,11,11,11,11,11,11
11,11,11,11,11,11,11,11,11,11,11,11,11,11,11,11,11
11,11,11,11,11,11,11,11,11,11,11,11,11,11,11,11,11
endlayer

layer
11,11,11,11,11,11,11,11,11,11,11,11,11,11,11,11,11
11,11,11,11,11,11,11,11,11,11,11,11,11,11,11,11,11
11,11,11,11,11,11,11,11,11,11,11,11,11,11,11,11,11
11,11,11,11,11,11,11,11,11,11,11,11,11,11,11,11,11
11,11,11,11,11,11,11,11,11,11,11,11,11,11,11,11,11
11,11,11,11,11,11,11,11,11,11,11,11,11,11,11,11,11
11,11,11,11,11,11,11,11,10,11,11,11,11,11,11,11,11
11,11,11,11,11,11,11,11,11,11,11,11,11,11,11,11,11
11,11,11,11,11,11,11,11,11,11,11,11,11,11,11,11,11
11,11,11,11,11,11,11,11,11,11,11,11,11,11,11,11,11
11,11,11,11,11,10,11,11,11,11,11,11,11,11,11,11,11
11,11,11,11,11,11,11,11,11,11,11,11,11,11,11,11,11
11,11,11,11,11,11,11,11,11,11,11,11,11,11,11,11,11
11,11,11,11,11,11,10,11,11,11,11,11,11,11,11,11,11
11,11,11,11,11,10,10,10,11,11,11,11,11,11,11,11,11
11,11,11,11,11,11,10,11,11,11,11,11,11,11,11,11,11
11,11,11,11,11,11,11,11,11,11,11,11,11,11,11,11,11
endlayer

layer
11,11,11,11,11,11,11,11,11,11,11,11,11,11,11,11,11
11,11,11,11,11,11,11,11,11,11,11,11,11,11,11,11,11
11,11,11,11,11,11,11,11,11,11,11,11,11,11,11,11,11
11,11,11,11,11,11,11,11,11,11,11,11,11,11,11,11,11
11,11,11,11,11,11,11,11,11,11,11,11,11,11,11,11,11
11,11,11,11,11,11,11,11,11,11,11,11,11,11,11,11,11
11,11,11,11,11,11,11,11,10,11,11,11,11,11,11,11,11
11,11,11,11,11,11,11,11,11,11,11,11,11,11,11,11,11
11,11,11,11,11,11,11,11,11,11,11,11,11,11,11,11,11
11,11,11,11,11,11,11,11,11,11,11,11,11,11,11,11,11
11,11,11,11,11,10,11,11,11,11,11,11,11,11,11,11,11
11,11,11,11,11,11,11,11,11,11,11,11,11,11,11,11,11
11,11,11,11,11,11,11,11,11,11,11,11,11,11,11,11,11
11,11,11,11,11,11,11,11,11,11,11,11,11,11,11,11,11
11,11,11,11,11,11,11,11,11,11,11,11,11,11,11,11,11
11,11,11,11,11,11,11,11,11,11,11,11,11,11,11,11,11
11,11,11,11,11,11,11,11,11,11,11,11,11,11,11,11,11
endlayer

layer
11,11,11,11,11,11,11,11,11,11,11,11,11,11,11,11,11
11,11,11,11,11,11,11,11,11,11,11,11,11,11,11,11,11
11,11,11,11,11,11,11,11,11,11,11,11,11,11,11,11,11
11,11,11,11,11,11,11,11,11,11,11,11,11,11,11,11,11
11,11,11,11,11,11,11,11,11,11,11,11,11,11,11,11,11
11,11,11,11,11,11,11,11,11,11,11,11,11,11,11,11,11
11,11,11,11,11,11,11,11,10,11,11,11,11,11,11,11,11
11,11,11,11,11,11,11,11,11,11,11,11,11,11,11,11,11
11,11,11,11,11,11,11,11,11,11,11,11,11,11,11,11,11
11,11,11,11,11,11,11,11,11,11,11,11,11,11,11,11,11
11,11,11,11,11,10,11,11,11,11,11,11,11,11,11,11,11
11,11,11,11,11,11,11,11,11,11,11,11,11,11,11,11,11
11,11,11,11,11,11,11,11,11,11,11,11,11,11,11,11,11
11,11,11,11,11,11,11,11,11,11,11,11,11,11,11,11,11
11,11,11,11,11,11,11,11,11,11,11,11,11,11,11,11,11
11,11,11,11,11,11,11,11,11,11,11,11,11,11,11,11,11
11,11,11,11,11,11,11,11,11,11,11,11,11,11,11,11,11
endlayer

layer
11,11,11,11,11,11,11,11,11,11,11,11,11,11,11,11,11
11,11,11,11,11,11,11,11,11,11,11,11,11,11,11,11,11
11,11,11,11,11,11,11,11,11,11,11,11,11,11,11,11,11
11,11,11,11,11,11,11,11,11,11,11,11,11,11,11,11,11
11,11,11,11,11,11,11,11,11,11,11,11,11,11,11,11,11
11,11,11,11,11,11,11,11,10,11,11,11,11,11,11,11,11
11,11,11,11,11,11,11,10,10,10,11,11,11,11,11,11,11
11,11,11,11,11,11,11,11,10,11,11,11,11,11,11,11,11
11,11,11,11,11,11,11,11,11,11,11,11,11,11,11,11,11
11,11,11,11,11,11,11,11,11,11,11,11,11,11,11,11,11
11,11,11,11,11,10,11,11,11,11,11,11,11,11,11,11,11
11,11,11,11,11,11,11,11,11,11,11,11,11,11,11,11,11
11,11,11,11,11,11,11,11,11,11,11,11,11,11,11,11,11
11,11,11,11,11,11,11,11,11,11,11,11,11,11,11,11,11
11,11,11,11,11,11,11,11,11,11,11,11,11,11,11,11,11
11,11,11,11,11,11,11,11,11,11,11,11,11,11,11,11,11
11,11,11,11,11,11,11,11,11,11,11,11,11,11,11,11,11
endlayer

layer
11,11,11,11,11,11,11,11,11,11,11,11,11,11,11,11,11
11,11,11,11,11,11,11,11,11,11,11,11,11,11,11,11,11
11,11,11,11,11,11,11,11,11,11,11,11,11,11,11,11,11
11,11,11,11,11,11,11,11,11,11,11,11,11,11,11,11,11
11,11,11,11,11,11,11,11,11,11,11,11,11,11,11,11,11
11,11,11,11,11,11,11,11,11,11,11,11,11,11,11,11,11
11,11,11,11,11,11,11,11,11,11,11,11,11,11,11,11,11
11,11,11,11,11,11,11,11,11,11,11,11,11,11,11,11,11
11,11,11,11,11,11,11,11,11,11,11,11,11,11,11,11,11
11,11,11,11,11,10,11,11,11,11,11,11,11,11,11,11,11
11,11,11,11,10,10,10,11,11,11,11,11,11,11,11,11,11
11,11,11,11,11,10,11,11,11,11,11,11,11,11,11,11,11
11,11,11,11,11,11,11,11,11,11,11,11,11,11,11,11,11
11,11,11,11,11,11,11,11,11,11,11,11,11,11,11,11,11
11,11,11,11,11,11,11,11,11,11,11,11,11,11,11,11,11
11,11,11,11,11,11,11,11,11,11,11,11,11,11,11,11,11
11,11,11,11,11,11,11,11,11,11,11,11,11,11,11,11,11
endlayer

