# 地狱疣浮冰岛的生成文件
# 特点是浮冰岛上的灵魂沙上长着些许地狱疣
# 在水星的水面生成

weight=1
embed_into_distance=4
acceptable_target_blocks=water
unacceptable_target_blocks=
dimensions=19,13,13
allowable_overhang=0
max_leveling=0
leveling_buffer=0
preserve_water=0
preserve_lava=0
biomesToSpawnIn=<plains>

rule1=0,100,minecraft:packed_ice-0
rule2=0,100,minecraft:ice-0
rule3=0,100,minecraft:soul_sand-0
rule4=0,100,minecraft:nether_wart-0
rule5=0,100,minecraft:nether_wart-3
rule6=0,100,minecraft:nether_wart-1
rule7=0,100,minecraft:preserveBlock

layer
7,7,7,7,7,7,7,7,7,7,7,7,7
7,7,7,7,7,7,7,7,7,7,7,7,7
7,7,7,7,7,7,7,7,7,7,7,7,7
7,7,7,7,7,7,7,7,7,7,7,7,7
7,7,7,7,7,7,7,7,7,7,7,7,7
7,7,7,7,7,7,7,7,7,7,7,7,7
7,7,7,7,7,1,7,7,7,7,7,7,7
7,7,7,1,1,1,1,1,7,7,7,7,7
7,7,7,1,1,1,7,1,1,1,7,7,7
7,7,7,1,1,1,1,1,1,1,7,7,7
7,7,7,7,7,7,7,1,1,1,7,7,7
7,7,7,7,7,7,7,7,7,7,7,7,7
7,7,7,7,7,7,7,7,7,7,7,7,7
endlayer

layer
7,7,7,7,7,7,7,7,7,7,7,7,7
7,7,7,7,7,7,7,7,7,7,7,7,7
7,7,7,7,7,7,7,7,7,7,7,7,7
7,7,7,7,7,7,7,7,7,7,7,7,7
7,7,1,1,1,7,7,7,1,1,1,7,7
7,7,1,1,1,1,1,7,1,1,1,7,7
7,7,1,1,1,1,1,1,1,1,1,7,7
7,7,1,1,1,1,1,1,1,1,7,7,7
7,7,1,1,1,1,1,1,1,1,1,7,7
7,7,1,1,1,1,1,1,1,1,1,7,7
7,7,7,1,1,1,1,1,1,1,1,7,7
7,7,7,7,7,7,7,1,1,1,7,7,7
7,7,7,7,7,7,7,7,7,7,7,7,7
endlayer

layer
7,7,7,7,7,7,7,7,7,7,7,7,7
7,7,7,7,7,7,7,7,7,7,7,7,7
7,7,7,7,7,7,7,7,7,7,7,7,7
7,7,1,1,1,7,7,7,1,1,1,7,7
7,1,1,1,1,1,1,1,1,1,1,1,7
7,1,1,1,1,1,1,1,1,1,1,1,7
7,1,1,1,1,1,1,1,1,1,1,1,7
7,7,1,1,1,1,1,1,1,1,1,7,7
7,7,1,1,1,1,1,1,1,1,1,7,7
7,7,1,1,1,1,1,1,1,1,1,7,7
7,7,7,1,1,1,2,1,1,1,1,7,7
7,7,7,7,7,7,7,1,1,1,7,7,7
7,7,7,7,7,7,7,7,7,7,7,7,7
endlayer

layer
7,7,7,7,7,7,7,7,7,7,7,7,7
7,7,7,7,7,7,7,7,7,7,7,7,7
7,7,7,7,7,7,7,7,7,7,7,7,7
7,7,1,2,1,7,7,7,2,1,1,7,7
7,1,1,1,1,2,2,2,2,1,1,1,7
7,1,1,1,1,1,1,1,1,1,1,1,7
7,1,1,1,1,1,1,1,1,1,1,1,7
7,7,1,1,1,1,1,1,1,1,1,7,7
7,7,1,1,1,1,1,1,1,1,1,7,7
7,7,1,1,1,1,1,1,1,1,1,7,7
7,7,7,1,1,1,2,1,1,1,1,7,7
7,7,7,7,7,7,7,1,1,1,7,7,7
7,7,7,7,7,7,7,7,7,7,7,7,7
endlayer

layer
7,7,7,7,7,7,7,7,7,7,7,7,7
7,7,7,7,7,7,7,7,7,7,7,7,7
7,7,7,7,7,7,7,7,7,7,7,7,7
7,7,1,2,1,7,7,7,1,1,1,7,7
7,1,1,1,1,1,1,1,1,1,1,1,7
7,1,1,1,1,1,1,1,1,1,1,1,7
7,1,1,1,1,1,1,1,1,1,1,1,7
7,7,1,1,1,1,1,1,1,1,1,7,7
7,7,7,1,1,1,1,1,1,1,1,7,7
7,7,7,1,1,1,2,1,1,1,7,7,7
7,7,7,7,7,7,1,1,1,1,7,7,7
7,7,7,7,7,7,7,7,7,7,7,7,7
7,7,7,7,7,7,7,7,7,7,7,7,7
endlayer

layer
7,7,7,7,7,7,7,7,7,7,7,7,7
7,7,7,7,7,7,7,7,7,7,7,7,7
7,7,7,7,7,7,7,7,7,7,7,7,7
7,7,7,7,7,7,7,7,7,7,7,7,7
7,7,1,2,1,2,2,2,1,1,1,7,7
7,1,1,2,3,1,1,2,2,1,1,7,7
7,1,1,3,3,3,1,1,1,2,1,7,7
7,7,2,3,3,1,3,1,1,1,7,7,7
7,7,7,2,2,2,3,1,1,1,7,7,7
7,7,7,7,7,7,7,7,7,7,7,7,7
7,7,7,7,7,7,7,7,7,7,7,7,7
7,7,7,7,7,7,7,7,7,7,7,7,7
7,7,7,7,7,7,7,7,7,7,7,7,7
endlayer

layer
7,7,7,7,7,7,7,7,7,7,7,7,7
7,7,7,7,7,7,7,7,7,7,7,7,7
7,7,7,7,7,7,7,7,7,7,7,7,7
7,7,7,7,7,7,7,7,7,7,7,7,7
7,7,1,7,7,7,7,7,7,7,7,7,7
7,7,1,1,4,7,7,1,1,1,7,7,7
7,7,1,7,5,7,1,1,1,1,7,7,7
7,7,7,5,4,7,5,1,1,1,7,7,7
7,7,7,7,7,7,6,7,1,7,7,7,7
7,7,7,7,7,7,7,7,7,7,7,7,7
7,7,7,7,7,7,7,7,7,7,7,7,7
7,7,7,7,7,7,7,7,7,7,7,7,7
7,7,7,7,7,7,7,7,7,7,7,7,7
endlayer

layer
7,7,7,7,7,7,7,7,7,7,7,7,7
7,7,7,7,7,7,7,7,7,7,7,7,7
7,7,7,7,7,7,7,7,7,7,7,7,7
7,7,7,7,7,7,7,7,7,7,7,7,7
7,7,1,7,7,7,7,7,7,7,7,7,7
7,7,1,1,7,7,7,1,1,1,7,7,7
7,7,1,7,7,7,1,1,1,1,7,7,7
7,7,7,7,7,7,7,1,1,1,7,7,7
7,7,7,7,7,7,7,7,1,7,7,7,7
7,7,7,7,7,7,7,7,7,7,7,7,7
7,7,7,7,7,7,7,7,7,7,7,7,7
7,7,7,7,7,7,7,7,7,7,7,7,7
7,7,7,7,7,7,7,7,7,7,7,7,7
endlayer

layer
7,7,7,7,7,7,7,7,7,7,7,7,7
7,7,7,7,7,7,7,7,7,7,7,7,7
7,7,7,7,7,7,7,7,7,7,7,7,7
7,7,7,7,7,7,7,7,7,7,7,7,7
7,7,7,7,7,7,7,7,7,7,7,7,7
7,7,1,1,7,7,7,7,7,1,7,7,7
7,7,1,7,7,7,1,1,1,1,7,7,7
7,7,7,7,7,7,7,7,1,7,7,7,7
7,7,7,7,7,7,7,7,7,7,7,7,7
7,7,7,7,7,7,7,7,7,7,7,7,7
7,7,7,7,7,7,7,7,7,7,7,7,7
7,7,7,7,7,7,7,7,7,7,7,7,7
7,7,7,7,7,7,7,7,7,7,7,7,7
endlayer

layer
7,7,7,7,7,7,7,7,7,7,7,7,7
7,7,7,7,7,7,7,7,7,7,7,7,7
7,7,7,7,7,7,7,7,7,7,7,7,7
7,7,7,7,7,7,7,7,7,7,7,7,7
7,7,7,7,7,7,7,7,7,7,7,7,7
7,7,1,7,7,7,7,1,1,1,7,7,7
7,7,1,7,7,7,7,1,1,1,7,7,7
7,7,7,7,7,7,7,7,1,7,7,7,7
7,7,7,7,7,7,7,7,7,7,7,7,7
7,7,7,7,7,7,7,7,7,7,7,7,7
7,7,7,7,7,7,7,7,7,7,7,7,7
7,7,7,7,7,7,7,7,7,7,7,7,7
7,7,7,7,7,7,7,7,7,7,7,7,7
endlayer

layer
7,7,7,7,7,7,7,7,7,7,7,7,7
7,7,7,7,7,7,7,7,7,7,7,7,7
7,7,7,7,7,7,7,7,7,7,7,7,7
7,7,7,7,7,7,7,7,7,7,7,7,7
7,7,7,7,7,7,7,7,7,7,7,7,7
7,7,1,7,7,7,7,7,1,1,7,7,7
7,7,7,7,7,7,7,1,1,7,7,7,7
7,7,7,7,7,7,7,7,1,7,7,7,7
7,7,7,7,7,7,7,7,7,7,7,7,7
7,7,7,7,7,7,7,7,7,7,7,7,7
7,7,7,7,7,7,7,7,7,7,7,7,7
7,7,7,7,7,7,7,7,7,7,7,7,7
7,7,7,7,7,7,7,7,7,7,7,7,7
endlayer

layer
7,7,7,7,7,7,7,7,7,7,7,7,7
7,7,7,7,7,7,7,7,7,7,7,7,7
7,7,7,7,7,7,7,7,7,7,7,7,7
7,7,7,7,7,7,7,7,7,7,7,7,7
7,7,7,7,7,7,7,7,7,7,7,7,7
7,7,1,7,7,7,7,7,1,1,7,7,7
7,7,7,7,7,7,7,1,1,7,7,7,7
7,7,7,7,7,7,7,7,1,7,7,7,7
7,7,7,7,7,7,7,7,7,7,7,7,7
7,7,7,7,7,7,7,7,7,7,7,7,7
7,7,7,7,7,7,7,7,7,7,7,7,7
7,7,7,7,7,7,7,7,7,7,7,7,7
7,7,7,7,7,7,7,7,7,7,7,7,7
endlayer

layer
7,7,7,7,7,7,7,7,7,7,7,7,7
7,7,7,7,7,7,7,7,7,7,7,7,7
7,7,7,7,7,7,7,7,7,7,7,7,7
7,7,7,7,7,7,7,7,7,7,7,7,7
7,7,7,7,7,7,7,7,7,7,7,7,7
7,7,7,7,7,7,7,7,1,7,7,7,7
7,7,7,7,7,7,7,1,1,7,7,7,7
7,7,7,7,7,7,7,7,7,7,7,7,7
7,7,7,7,7,7,7,7,7,7,7,7,7
7,7,7,7,7,7,7,7,7,7,7,7,7
7,7,7,7,7,7,7,7,7,7,7,7,7
7,7,7,7,7,7,7,7,7,7,7,7,7
7,7,7,7,7,7,7,7,7,7,7,7,7
endlayer

layer
7,7,7,7,7,7,7,7,7,7,7,7,7
7,7,7,7,7,7,7,7,7,7,7,7,7
7,7,7,7,7,7,7,7,7,7,7,7,7
7,7,7,7,7,7,7,7,7,7,7,7,7
7,7,7,7,7,7,7,7,7,7,7,7,7
7,7,7,7,7,7,7,7,7,7,7,7,7
7,7,7,7,7,7,7,1,1,7,7,7,7
7,7,7,7,7,7,7,7,7,7,7,7,7
7,7,7,7,7,7,7,7,7,7,7,7,7
7,7,7,7,7,7,7,7,7,7,7,7,7
7,7,7,7,7,7,7,7,7,7,7,7,7
7,7,7,7,7,7,7,7,7,7,7,7,7
7,7,7,7,7,7,7,7,7,7,7,7,7
endlayer

layer
7,7,7,7,7,7,7,7,7,7,7,7,7
7,7,7,7,7,7,7,7,7,7,7,7,7
7,7,7,7,7,7,7,7,7,7,7,7,7
7,7,7,7,7,7,7,7,7,7,7,7,7
7,7,7,7,7,7,7,7,7,7,7,7,7
7,7,7,7,7,7,7,7,7,7,7,7,7
7,7,7,7,7,7,7,1,1,7,7,7,7
7,7,7,7,7,7,7,7,7,7,7,7,7
7,7,7,7,7,7,7,7,7,7,7,7,7
7,7,7,7,7,7,7,7,7,7,7,7,7
7,7,7,7,7,7,7,7,7,7,7,7,7
7,7,7,7,7,7,7,7,7,7,7,7,7
7,7,7,7,7,7,7,7,7,7,7,7,7
endlayer

layer
7,7,7,7,7,7,7,7,7,7,7,7,7
7,7,7,7,7,7,7,7,7,7,7,7,7
7,7,7,7,7,7,7,7,7,7,7,7,7
7,7,7,7,7,7,7,7,7,7,7,7,7
7,7,7,7,7,7,7,7,7,7,7,7,7
7,7,7,7,7,7,7,7,7,7,7,7,7
7,7,7,7,7,7,7,7,1,7,7,7,7
7,7,7,7,7,7,7,7,7,7,7,7,7
7,7,7,7,7,7,7,7,7,7,7,7,7
7,7,7,7,7,7,7,7,7,7,7,7,7
7,7,7,7,7,7,7,7,7,7,7,7,7
7,7,7,7,7,7,7,7,7,7,7,7,7
7,7,7,7,7,7,7,7,7,7,7,7,7
endlayer

layer
7,7,7,7,7,7,7,7,7,7,7,7,7
7,7,7,7,7,7,7,7,7,7,7,7,7
7,7,7,7,7,7,7,7,7,7,7,7,7
7,7,7,7,7,7,7,7,7,7,7,7,7
7,7,7,7,7,7,7,7,7,7,7,7,7
7,7,7,7,7,7,7,7,7,7,7,7,7
7,7,7,7,7,7,7,7,1,7,7,7,7
7,7,7,7,7,7,7,7,7,7,7,7,7
7,7,7,7,7,7,7,7,7,7,7,7,7
7,7,7,7,7,7,7,7,7,7,7,7,7
7,7,7,7,7,7,7,7,7,7,7,7,7
7,7,7,7,7,7,7,7,7,7,7,7,7
7,7,7,7,7,7,7,7,7,7,7,7,7
endlayer

layer
7,7,7,7,7,7,7,7,7,7,7,7,7
7,7,7,7,7,7,7,7,7,7,7,7,7
7,7,7,7,7,7,7,7,7,7,7,7,7
7,7,7,7,7,7,7,7,7,7,7,7,7
7,7,7,7,7,7,7,7,7,7,7,7,7
7,7,7,7,7,7,7,7,7,7,7,7,7
7,7,7,7,7,7,7,7,1,7,7,7,7
7,7,7,7,7,7,7,7,7,7,7,7,7
7,7,7,7,7,7,7,7,7,7,7,7,7
7,7,7,7,7,7,7,7,7,7,7,7,7
7,7,7,7,7,7,7,7,7,7,7,7,7
7,7,7,7,7,7,7,7,7,7,7,7,7
7,7,7,7,7,7,7,7,7,7,7,7,7
endlayer

layer
7,7,7,7,7,7,7,7,7,7,7,7,7
7,7,7,7,7,7,7,7,7,7,7,7,7
7,7,7,7,7,7,7,7,7,7,7,7,7
7,7,7,7,7,7,7,7,7,7,7,7,7
7,7,7,7,7,7,7,7,7,7,7,7,7
7,7,7,7,7,7,7,7,7,7,7,7,7
7,7,7,7,7,7,7,7,1,7,7,7,7
7,7,7,7,7,7,7,7,7,7,7,7,7
7,7,7,7,7,7,7,7,7,7,7,7,7
7,7,7,7,7,7,7,7,7,7,7,7,7
7,7,7,7,7,7,7,7,7,7,7,7,7
7,7,7,7,7,7,7,7,7,7,7,7,7
7,7,7,7,7,7,7,7,7,7,7,7,7
endlayer

