# 苔石浮冰岛的生成文件
# 特点是浮冰岛中有一个苔石遗迹，遗迹中有两个地牢箱子、熔炉、地毯、床和一个发射器岩浆陷阱
# 在水星的水面生成

weight=1
embed_into_distance=20
acceptable_target_blocks=water
unacceptable_target_blocks=
dimensions=33,21,20
allowable_overhang=0
max_leveling=0
leveling_buffer=0
preserve_water=0
preserve_lava=0
biomesToSpawnIn=<plains>

rule1=0,100,minecraft:packed_ice-0
rule2=0,100,chisel:cobblestonemossy1-9
rule3=0,100,minecraft:mossy_cobblestone-0
rule4=0,100,minecraft:cobblestone-0
rule5=0,100,minecraft:carpet-14
rule6=0,100,minecraft:tripwire_hook-4
rule7=0,100,minecraft:tripwire-6
rule8=0,100,minecraft:tripwire-2
rule9=0,100,minecraft:tripwire_hook-6
rule10=0,100,minecraft:anvil-1
rule11=0,100,exnihilocreatio:block_barrel1-0
rule12=0,100,ChestGenHook:chests/simple_dungeon:5-3
rule13=0,100,minecraft:carpet-15
rule14=0,100,tconstruct:stone_torch-2
rule15=0,100,minecraft:vine-1
rule16=0,100,IInventory;minecraft:dispenser;minecraft:lava_bucket#1#0#4-3
rule17=0,100,minecraft:leaves-7
rule18=0,100,minecraft:furnace-4
rule19=0,100,tconstruct:stone_torch-4
rule20=0,100,MobSpawner:minecraft:spider
rule21=0,100,minecraft:bed-0
rule22=0,100,minecraft:bed-8
rule23=0,100,minecraft:glowstone-0
rule24=0,100,tconstruct:stone_torch-1
rule25=0,100,minecraft:iron_bars-0
rule26=0,100,minecraft:preserveBlock
rule27=0,100,minecraft:air-0

layer
26,26,26,26,26,26,26,26,26,26,26,26,26,26,26,26,26,26,26,26
26,26,26,26,26,26,26,26,26,26,26,26,26,26,26,26,26,26,26,26
26,26,26,26,26,26,26,26,26,26,26,26,26,26,26,26,26,26,26,26
26,26,26,26,26,26,26,26,26,26,26,26,26,26,26,26,26,26,26,26
26,26,26,26,26,26,26,26,26,26,26,26,26,26,26,26,26,26,26,26
26,26,26,26,26,26,26,26,26,26,26,26,26,26,26,26,26,26,26,26
26,26,26,26,26,26,26,26,26,26,26,26,26,26,26,26,26,26,26,26
26,26,26,26,26,26,26,26,26,26,26,26,26,26,26,26,26,26,26,26
26,26,26,26,26,26,26,26,26,26,26,26,26,26,26,26,26,26,26,26
26,26,26,26,26,26,26,26,26,26,26,26,26,26,26,26,26,26,26,26
26,26,26,26,26,26,26,26,26,26,1,26,26,26,26,26,26,26,26,26
26,26,26,26,26,26,26,26,26,26,1,26,26,26,26,26,26,26,26,26
26,26,26,26,26,26,26,26,26,26,26,26,26,26,26,26,26,26,26,26
26,26,26,26,26,26,26,26,26,26,26,26,26,26,26,26,26,26,26,26
26,26,26,26,26,26,26,26,26,26,26,26,26,26,26,26,26,26,26,26
26,26,26,26,26,26,26,26,26,26,26,26,26,26,26,26,26,26,26,26
26,26,26,26,26,26,26,26,26,26,26,26,26,26,26,26,26,26,26,26
26,26,26,26,26,26,26,26,26,26,26,26,26,26,26,26,26,26,26,26
26,26,26,26,26,26,26,26,26,26,26,26,26,26,26,26,26,26,26,26
26,26,26,26,26,26,26,26,26,26,26,26,26,26,26,26,26,26,26,26
26,26,26,26,26,26,26,26,26,26,26,26,26,26,26,26,26,26,26,26
endlayer

layer
26,26,26,26,26,26,26,26,26,26,26,26,26,26,26,26,26,26,26,26
26,26,26,26,26,26,26,26,26,26,26,26,26,26,26,26,26,26,26,26
26,26,26,26,26,26,26,26,26,26,26,26,26,26,26,26,26,26,26,26
26,26,26,26,26,26,26,26,26,26,26,26,26,26,26,26,26,26,26,26
26,26,26,26,26,26,26,26,26,26,26,26,26,26,26,26,26,26,26,26
26,26,26,26,26,26,26,26,26,26,26,26,26,26,26,26,26,26,26,26
26,26,26,26,26,26,26,26,26,26,26,26,26,26,26,26,26,26,26,26
26,26,26,26,26,26,26,26,26,26,26,26,26,26,26,26,26,26,26,26
26,26,26,26,26,26,26,26,26,26,26,26,26,26,26,26,26,26,26,26
26,26,26,26,26,26,26,26,26,26,26,26,26,26,26,26,26,26,26,26
26,26,26,26,26,26,26,26,26,26,1,26,26,26,26,26,26,26,26,26
26,26,26,26,26,26,26,26,26,1,1,1,26,26,26,26,26,26,26,26
26,26,26,26,26,26,26,26,26,26,1,26,26,26,26,26,26,26,26,26
26,26,26,26,26,26,26,26,26,26,26,26,26,26,26,26,26,26,26,26
26,26,26,26,26,26,26,26,26,26,26,26,26,26,26,26,26,26,26,26
26,26,26,26,26,26,26,26,26,26,26,26,26,26,26,26,26,26,26,26
26,26,26,26,26,26,26,26,26,26,26,26,26,26,26,26,26,26,26,26
26,26,26,26,26,26,26,26,26,26,26,26,26,26,26,26,26,26,26,26
26,26,26,26,26,26,26,26,26,26,26,26,26,26,26,26,26,26,26,26
26,26,26,26,26,26,26,26,26,26,26,26,26,26,26,26,26,26,26,26
26,26,26,26,26,26,26,26,26,26,26,26,26,26,26,26,26,26,26,26
endlayer

layer
26,26,26,26,26,26,26,26,26,26,26,26,26,26,26,26,26,26,26,26
26,26,26,26,26,26,26,26,26,26,26,26,26,26,26,26,26,26,26,26
26,26,26,26,26,26,26,26,26,26,26,26,26,26,26,26,26,26,26,26
26,26,26,26,26,26,26,26,26,26,26,26,26,26,26,26,26,26,26,26
26,26,26,26,26,26,26,26,26,26,26,26,26,26,26,26,26,26,26,26
26,26,26,26,26,26,26,26,26,26,26,26,26,26,26,26,26,26,26,26
26,26,26,26,26,26,26,26,26,26,26,26,26,26,26,26,26,26,26,26
26,26,26,26,26,26,26,26,26,26,26,26,26,26,26,26,26,26,26,26
26,26,26,26,26,26,26,26,26,26,26,26,26,26,26,26,26,26,26,26
26,26,26,26,26,26,26,26,26,26,26,26,26,26,26,26,26,26,26,26
26,26,26,26,26,26,26,26,26,1,1,1,26,26,26,26,26,26,26,26
26,26,26,26,26,26,26,26,26,1,1,1,26,26,26,26,26,26,26,26
26,26,26,26,26,26,26,26,26,1,1,1,26,26,26,26,26,26,26,26
26,26,26,26,26,26,26,26,26,26,26,26,26,26,26,26,26,26,26,26
26,26,26,26,26,26,26,26,26,26,26,26,26,26,26,26,26,26,26,26
26,26,26,26,26,26,26,26,26,26,26,26,26,26,26,26,26,26,26,26
26,26,26,26,26,26,26,26,26,26,26,26,26,26,26,26,26,26,26,26
26,26,26,26,26,26,26,26,26,26,26,26,26,26,26,26,26,26,26,26
26,26,26,26,26,26,26,26,26,26,26,26,26,26,26,26,26,26,26,26
26,26,26,26,26,26,26,26,26,26,26,26,26,26,26,26,26,26,26,26
26,26,26,26,26,26,26,26,26,26,26,26,26,26,26,26,26,26,26,26
endlayer

layer
26,26,26,26,26,26,26,26,26,26,26,26,26,26,26,26,26,26,26,26
26,26,26,26,26,26,26,26,26,26,26,26,26,26,26,26,26,26,26,26
26,26,26,26,26,26,26,26,26,26,26,26,26,26,26,26,26,26,26,26
26,26,26,26,26,26,26,26,26,26,26,26,26,26,26,26,26,26,26,26
26,26,26,26,26,26,26,26,26,26,26,26,26,26,26,26,26,26,26,26
26,26,26,26,26,26,26,26,26,26,26,26,26,26,26,26,26,26,26,26
26,26,26,26,26,26,26,26,26,26,26,26,26,26,26,26,26,26,26,26
26,26,26,26,26,26,26,26,26,26,26,26,26,26,26,26,26,26,26,26
26,26,26,26,26,26,26,26,26,26,1,26,26,26,26,26,26,26,26,26
26,26,26,26,26,26,26,26,26,1,1,1,26,26,26,26,26,26,26,26
26,26,26,26,26,26,26,26,26,1,1,1,26,26,26,26,26,26,26,26
26,26,26,26,26,26,26,26,1,1,1,1,1,26,26,26,26,26,26,26
26,26,26,26,26,26,26,26,26,1,1,1,26,26,26,26,26,26,26,26
26,26,26,26,26,26,26,26,26,26,1,26,26,26,26,26,26,26,26,26
26,26,26,26,26,26,26,26,26,26,26,26,26,26,26,26,26,26,26,26
26,26,26,26,26,26,26,26,26,26,26,26,26,26,26,26,26,26,26,26
26,26,26,26,26,26,26,26,26,26,26,26,26,26,26,26,26,26,26,26
26,26,26,26,26,26,26,26,26,26,26,26,26,26,26,26,26,26,26,26
26,26,26,26,26,26,26,26,26,26,26,26,26,26,26,26,26,26,26,26
26,26,26,26,26,26,26,26,26,26,26,26,26,26,26,26,26,26,26,26
26,26,26,26,26,26,26,26,26,26,26,26,26,26,26,26,26,26,26,26
endlayer

layer
26,26,26,26,26,26,26,26,26,26,26,26,26,26,26,26,26,26,26,26
26,26,26,26,26,26,26,26,26,26,26,26,26,26,26,26,26,26,26,26
26,26,26,26,26,26,26,26,26,26,26,26,26,26,26,26,26,26,26,26
26,26,26,26,26,26,26,26,26,26,26,26,26,26,26,26,26,26,26,26
26,26,26,26,26,26,26,26,26,26,26,26,26,26,26,26,26,26,26,26
26,26,26,26,26,26,26,26,26,26,26,26,26,26,26,26,26,26,26,26
26,26,26,26,26,26,26,26,26,26,26,26,26,26,26,26,26,26,26,26
26,26,26,26,26,26,26,26,26,26,26,26,26,26,26,26,26,26,26,26
26,26,26,26,26,26,26,26,26,1,1,1,26,26,26,26,26,26,26,26
26,26,26,26,26,26,26,26,26,1,1,1,26,26,26,26,26,26,26,26
26,26,26,26,26,26,26,26,1,1,1,1,1,26,26,26,26,26,26,26
26,26,26,26,26,26,26,1,1,1,1,1,1,1,26,26,26,26,26,26
26,26,26,26,26,26,26,1,1,1,1,1,1,26,26,26,26,26,26,26
26,26,26,26,26,26,26,1,1,1,1,1,26,26,26,26,26,26,26,26
26,26,26,26,26,26,26,26,26,26,1,26,26,26,26,26,26,26,26,26
26,26,26,26,26,26,26,26,26,26,26,26,26,26,26,26,26,26,26,26
26,26,26,26,26,26,26,26,26,26,26,26,26,26,26,26,26,26,26,26
26,26,26,26,26,26,26,26,26,26,26,26,26,26,26,26,26,26,26,26
26,26,26,26,26,26,26,26,26,26,26,26,26,26,26,26,26,26,26,26
26,26,26,26,26,26,26,26,26,26,26,26,26,26,26,26,26,26,26,26
26,26,26,26,26,26,26,26,26,26,26,26,26,26,26,26,26,26,26,26
endlayer

layer
26,26,26,26,26,26,26,26,26,26,26,26,26,26,26,26,26,26,26,26
26,26,26,26,26,26,26,26,26,26,26,26,26,26,26,26,26,26,26,26
26,26,26,26,26,26,26,26,26,26,26,26,26,26,26,26,26,26,26,26
26,26,26,26,26,26,26,26,26,26,26,26,26,26,26,26,26,26,26,26
26,26,26,26,26,26,26,26,26,26,26,26,26,26,26,26,26,26,26,26
26,26,26,26,26,26,26,26,26,26,26,26,26,26,26,26,26,26,26,26
26,26,26,26,26,26,26,26,26,26,26,26,26,26,26,26,26,26,26,26
26,26,26,26,26,26,26,26,26,26,26,26,26,26,26,26,26,26,26,26
26,26,26,26,26,26,26,1,1,1,1,26,26,26,26,26,26,26,26,26
26,26,26,26,26,26,26,1,1,1,1,1,26,26,26,26,26,26,26,26
26,26,26,26,26,1,1,1,1,1,1,1,1,1,26,26,26,26,26,26
26,26,26,26,26,1,1,1,1,1,1,1,1,1,26,26,26,26,26,26
26,26,26,26,26,1,1,1,1,1,1,1,1,1,26,26,26,26,26,26
26,26,26,26,26,26,1,1,1,1,1,1,26,26,26,26,26,26,26,26
26,26,26,26,26,26,26,1,1,1,1,1,26,26,26,26,26,26,26,26
26,26,26,26,26,26,26,1,1,1,26,26,26,26,26,26,26,26,26,26
26,26,26,26,26,26,26,26,26,26,26,26,26,26,26,26,26,26,26,26
26,26,26,26,26,26,26,26,26,26,26,26,26,26,26,26,26,26,26,26
26,26,26,26,26,26,26,26,26,26,26,26,26,26,26,26,26,26,26,26
26,26,26,26,26,26,26,26,26,26,26,26,26,26,26,26,26,26,26,26
26,26,26,26,26,26,26,26,26,26,26,26,26,26,26,26,26,26,26,26
endlayer

layer
26,26,26,26,26,26,26,26,26,26,26,26,26,26,26,26,26,26,26,26
26,26,26,26,26,26,26,26,26,26,26,26,26,26,26,26,26,26,26,26
26,26,26,26,26,26,26,26,26,26,26,26,26,26,26,26,26,26,26,26
26,26,26,26,26,26,26,26,26,26,26,26,26,26,26,26,26,26,26,26
26,26,26,26,26,26,26,26,26,26,26,26,26,26,26,26,26,26,26,26
26,26,26,26,26,26,26,26,26,26,26,26,26,26,26,26,26,26,26,26
26,26,26,26,26,26,26,26,26,26,26,26,26,26,26,26,26,26,26,26
26,26,26,26,26,26,26,1,1,1,1,1,1,26,26,26,26,26,26,26
26,26,26,26,26,26,1,1,1,1,1,1,1,26,26,26,26,26,26,26
26,26,26,26,26,1,1,1,1,1,1,1,1,26,26,26,26,26,26,26
26,26,26,26,1,1,1,1,1,1,1,1,1,1,26,26,26,26,26,26
26,26,26,26,1,1,1,1,1,1,1,1,1,1,26,26,26,26,26,26
26,26,26,26,1,1,1,1,1,1,1,1,1,1,26,26,26,26,26,26
26,26,26,26,26,1,1,1,1,1,1,1,1,1,26,26,26,26,26,26
26,26,26,26,26,26,1,1,1,1,1,1,1,1,26,26,26,26,26,26
26,26,26,26,26,26,1,1,1,1,1,26,26,26,26,26,26,26,26,26
26,26,26,26,26,26,26,1,1,1,26,26,26,26,26,26,26,26,26,26
26,26,26,26,26,26,26,26,26,26,26,26,26,26,26,26,26,26,26,26
26,26,26,26,26,26,26,26,26,26,26,26,26,26,26,26,26,26,26,26
26,26,26,26,26,26,26,26,26,26,26,26,26,26,26,26,26,26,26,26
26,26,26,26,26,26,26,26,26,26,26,26,26,26,26,26,26,26,26,26
endlayer

layer
26,26,26,26,26,26,26,26,26,26,26,26,26,26,26,26,26,26,26,26
26,26,26,26,26,26,26,26,26,26,26,26,26,26,26,26,26,26,26,26
26,26,26,26,26,26,26,26,26,26,26,26,26,26,26,26,26,26,26,26
26,26,26,26,26,26,26,26,26,26,26,26,26,26,26,26,26,26,26,26
26,26,26,26,26,26,26,26,26,26,26,26,26,26,26,26,26,26,26,26
26,26,26,26,26,26,26,26,26,26,26,26,26,26,26,26,26,26,26,26
26,26,26,26,26,26,26,26,26,26,1,1,1,26,26,26,26,26,26,26
26,26,26,26,26,26,26,1,1,1,1,1,1,1,26,26,26,26,26,26
26,26,26,26,26,26,1,1,1,1,1,1,1,1,26,26,26,26,26,26
26,26,26,26,26,1,1,1,1,1,1,1,1,1,26,26,26,26,26,26
26,26,26,26,1,1,1,1,1,1,1,1,1,1,26,26,26,26,26,26
26,26,26,26,1,1,1,1,1,1,1,1,1,1,26,26,26,26,26,26
26,26,26,26,1,1,1,1,1,1,1,1,1,1,1,26,26,26,26,26
26,26,26,26,26,1,1,1,1,1,1,1,1,1,1,26,26,26,26,26
26,26,26,26,26,26,1,1,1,1,1,1,1,1,1,26,26,26,26,26
26,26,26,26,26,26,1,1,1,1,1,1,1,1,26,26,26,26,26,26
26,26,26,26,26,26,26,1,1,1,26,26,26,26,26,26,26,26,26,26
26,26,26,26,26,26,26,26,26,26,26,26,26,26,26,26,26,26,26,26
26,26,26,26,26,26,26,26,26,26,26,26,26,26,26,26,26,26,26,26
26,26,26,26,26,26,26,26,26,26,26,26,26,26,26,26,26,26,26,26
26,26,26,26,26,26,26,26,26,26,26,26,26,26,26,26,26,26,26,26
endlayer

layer
26,26,26,26,26,26,26,26,26,26,26,26,26,26,26,26,26,26,26,26
26,26,26,26,26,26,26,26,26,26,26,26,26,26,26,26,26,26,26,26
26,26,26,26,26,26,26,26,26,26,26,26,26,26,26,26,26,26,26,26
26,26,26,26,26,26,26,26,26,26,26,26,26,26,26,26,26,26,26,26
26,26,26,26,26,26,26,26,26,26,26,26,26,26,26,26,26,26,26,26
26,26,26,26,26,26,26,26,26,26,26,26,26,26,26,26,26,26,26,26
26,26,26,26,26,26,26,26,26,26,1,1,1,26,26,26,26,26,26,26
26,26,26,26,26,26,26,1,1,1,1,1,1,1,26,26,26,26,26,26
26,26,26,26,26,26,1,1,1,1,1,1,1,1,26,26,26,26,26,26
26,26,26,26,26,1,1,1,1,1,1,1,1,1,26,26,26,26,26,26
26,26,26,26,1,1,1,1,1,1,1,1,1,1,26,26,26,26,26,26
26,26,26,26,1,1,1,1,1,1,1,1,1,1,26,26,26,26,26,26
26,26,26,26,1,1,1,1,1,1,1,1,1,1,1,26,26,26,26,26
26,26,26,26,26,1,1,1,1,1,1,1,1,1,1,26,26,26,26,26
26,26,26,26,26,1,1,1,1,1,1,1,1,1,1,26,26,26,26,26
26,26,26,26,26,1,1,1,1,1,1,1,1,1,26,26,26,26,26,26
26,26,26,26,26,26,26,1,1,1,26,26,26,26,26,26,26,26,26,26
26,26,26,26,26,26,26,26,26,26,26,26,26,26,26,26,26,26,26,26
26,26,26,26,26,26,26,26,26,26,26,26,26,26,26,26,26,26,26,26
26,26,26,26,26,26,26,26,26,26,26,26,26,26,26,26,26,26,26,26
26,26,26,26,26,26,26,26,26,26,26,26,26,26,26,26,26,26,26,26
endlayer

layer
26,26,26,26,26,26,26,26,26,26,26,26,26,26,26,26,26,26,26,26
26,26,26,26,26,26,26,26,26,26,26,26,26,26,26,26,26,26,26,26
26,26,26,26,26,26,26,26,26,26,26,26,26,26,26,26,26,26,26,26
26,26,26,26,26,26,26,26,26,26,26,26,26,26,26,26,26,26,26,26
26,26,26,26,26,26,26,26,26,26,26,26,26,26,26,26,26,26,26,26
26,26,26,26,26,26,26,26,26,26,26,26,26,26,26,26,26,26,26,26
26,26,26,26,26,26,26,26,26,26,1,1,1,26,26,26,26,26,26,26
26,26,26,26,26,26,26,1,1,1,1,1,1,1,26,26,26,26,26,26
26,26,26,26,26,26,1,1,1,1,1,1,1,1,26,26,26,26,26,26
26,26,26,26,26,1,1,1,1,1,1,1,1,1,26,26,26,26,26,26
26,26,26,26,26,1,1,1,1,1,1,1,1,26,26,26,26,26,26,26
26,26,26,26,26,1,1,1,1,1,1,1,1,1,26,26,26,26,26,26
26,26,26,26,1,1,1,1,1,1,1,1,1,1,1,26,26,26,26,26
26,26,26,26,1,1,1,1,1,1,1,1,1,1,1,26,26,26,26,26
26,26,26,26,1,1,1,1,1,1,1,1,1,1,1,26,26,26,26,26
26,26,26,26,26,1,1,1,1,1,1,1,1,1,26,26,26,26,26,26
26,26,26,26,26,26,1,1,1,26,1,1,1,26,26,26,26,26,26,26
26,26,26,26,26,26,26,26,26,26,26,26,26,26,26,26,26,26,26,26
26,26,26,26,26,26,26,26,26,26,26,26,26,26,26,26,26,26,26,26
26,26,26,26,26,26,26,26,26,26,26,26,26,26,26,26,26,26,26,26
26,26,26,26,26,26,26,26,26,26,26,26,26,26,26,26,26,26,26,26
endlayer

layer
26,26,26,26,26,26,26,26,26,26,26,26,26,26,26,26,26,26,26,26
26,26,26,26,26,26,26,26,26,26,26,26,26,26,26,26,26,26,26,26
26,26,26,26,26,26,26,26,26,26,26,26,26,26,26,26,26,26,26,26
26,26,26,26,26,26,26,26,26,26,26,26,26,26,26,26,26,26,26,26
26,26,26,26,26,26,26,26,26,26,26,26,26,26,26,26,26,26,26,26
26,26,26,26,26,26,26,26,26,26,26,26,26,26,26,26,26,26,26,26
26,26,26,26,26,26,26,26,26,26,26,26,26,26,26,26,26,26,26,26
26,26,26,26,26,26,26,1,1,1,1,1,1,26,26,26,26,26,26,26
26,26,26,26,26,26,1,1,1,1,1,1,1,26,26,26,26,26,26,26
26,26,26,26,26,1,1,1,1,1,1,1,1,26,26,26,26,26,26,26
26,26,26,26,26,1,1,1,1,1,1,1,1,26,26,26,26,26,26,26
26,26,26,26,26,1,1,1,1,1,1,1,1,1,26,26,26,26,26,26
26,26,26,26,1,1,1,1,1,1,1,1,1,1,1,26,26,26,26,26
26,26,26,26,1,1,1,1,1,1,1,1,1,1,1,26,26,26,26,26
26,26,26,26,1,1,1,1,1,1,1,1,1,1,1,26,26,26,26,26
26,26,26,26,26,1,1,1,1,1,1,1,1,1,26,26,26,26,26,26
26,26,26,26,26,26,1,1,1,26,1,1,1,26,26,26,26,26,26,26
26,26,26,26,26,26,26,26,26,26,26,26,26,26,26,26,26,26,26,26
26,26,26,26,26,26,26,26,26,26,26,26,26,26,26,26,26,26,26,26
26,26,26,26,26,26,26,26,26,26,26,26,26,26,26,26,26,26,26,26
26,26,26,26,26,26,26,26,26,26,26,26,26,26,26,26,26,26,26,26
endlayer

layer
26,26,26,26,26,26,26,26,26,26,26,26,26,26,26,26,26,26,26,26
26,26,26,26,26,26,26,26,26,26,26,26,26,26,26,26,26,26,26,26
26,26,26,26,26,26,26,26,26,26,26,26,26,26,26,26,26,26,26,26
26,26,26,26,26,26,26,26,26,26,26,26,26,26,26,26,26,26,26,26
26,26,26,26,26,26,26,26,26,26,26,26,26,26,26,26,26,26,26,26
26,26,26,26,26,26,26,26,26,26,26,26,26,26,26,26,26,26,26,26
26,26,26,26,26,26,26,26,26,26,26,26,26,26,26,26,26,26,26,26
26,26,26,26,26,26,26,26,1,1,1,1,1,26,26,26,26,26,26,26
26,26,26,26,26,26,1,1,1,1,1,1,1,26,26,26,26,26,26,26
26,26,26,26,26,26,1,1,1,1,1,1,1,1,1,26,26,26,26,26
26,26,26,26,26,26,1,1,1,1,1,1,1,1,1,26,26,26,26,26
26,26,26,26,26,1,1,1,1,1,1,1,1,1,1,26,26,26,26,26
26,26,26,26,1,1,1,1,1,1,1,1,1,1,1,26,26,26,26,26
26,26,26,26,1,1,1,1,1,1,1,1,1,1,1,26,26,26,26,26
26,26,26,26,1,1,1,1,1,1,1,1,1,1,1,26,26,26,26,26
26,26,26,26,26,1,1,1,1,1,1,1,1,1,26,26,26,26,26,26
26,26,26,26,26,1,1,1,1,1,1,1,1,26,26,26,26,26,26,26
26,26,26,26,26,26,26,26,26,26,26,26,26,26,26,26,26,26,26,26
26,26,26,26,26,26,26,26,26,26,26,26,26,26,26,26,26,26,26,26
26,26,26,26,26,26,26,26,26,26,26,26,26,26,26,26,26,26,26,26
26,26,26,26,26,26,26,26,26,26,26,26,26,26,26,26,26,26,26,26
endlayer

layer
26,26,26,26,26,26,26,26,26,26,26,26,26,26,26,26,26,26,26,26
26,26,26,26,26,26,26,26,26,26,26,26,26,26,26,26,26,26,26,26
26,26,26,26,26,26,26,26,26,26,26,26,26,26,26,26,26,26,26,26
26,26,26,26,26,26,26,26,26,26,26,26,26,26,26,26,26,26,26,26
26,26,26,26,26,26,26,26,26,26,26,26,26,26,26,26,26,26,26,26
26,26,26,26,26,26,26,26,26,26,26,26,26,26,26,26,26,26,26,26
26,26,26,26,26,26,26,26,26,1,1,1,1,1,26,26,26,26,26,26
26,26,26,26,26,26,26,26,1,1,1,1,1,1,26,26,26,26,26,26
26,26,26,26,26,26,26,1,1,1,1,1,1,1,1,1,26,26,26,26
26,26,26,26,26,26,1,1,1,1,1,1,1,1,1,1,26,26,26,26
26,26,26,26,26,26,1,1,1,1,1,1,1,1,1,1,26,26,26,26
26,26,26,26,26,1,1,1,1,1,1,1,1,1,1,1,26,26,26,26
26,26,26,26,26,1,1,1,1,1,1,1,1,1,1,1,26,26,26,26
26,26,26,26,1,1,1,1,1,1,1,1,1,1,26,26,26,26,26,26
26,26,26,26,1,1,1,1,1,1,1,1,1,1,26,26,26,26,26,26
26,26,26,26,1,1,1,1,1,1,1,1,1,1,26,26,26,26,26,26
26,26,26,26,26,1,1,1,1,1,26,26,26,26,26,26,26,26,26,26
26,26,26,26,26,26,1,1,1,26,26,26,26,26,26,26,26,26,26,26
26,26,26,26,26,26,26,26,26,26,26,26,26,26,26,26,26,26,26,26
26,26,26,26,26,26,26,26,26,26,26,26,26,26,26,26,26,26,26,26
26,26,26,26,26,26,26,26,26,26,26,26,26,26,26,26,26,26,26,26
endlayer

layer
26,26,26,26,26,26,26,26,26,26,26,26,26,26,26,26,26,26,26,26
26,26,26,26,26,26,26,26,26,26,26,26,26,26,26,26,26,26,26,26
26,26,26,26,26,26,26,26,26,26,26,26,26,26,26,26,26,26,26,26
26,26,26,26,26,26,26,26,26,26,26,26,26,26,26,26,26,26,26,26
26,26,26,26,26,26,26,26,26,26,26,26,26,26,26,26,26,26,26,26
26,26,26,26,26,26,26,26,26,26,1,1,1,26,26,26,26,26,26,26
26,26,26,26,26,26,26,26,26,1,1,1,1,1,26,26,26,26,26,26
26,26,26,26,26,26,26,26,1,1,1,1,1,1,1,26,26,26,26,26
26,26,26,26,26,26,26,1,1,1,1,1,1,1,1,1,26,26,26,26
26,26,26,26,26,26,1,1,1,1,1,1,1,1,1,1,1,26,26,26
26,26,26,26,26,26,1,1,1,1,1,1,1,1,1,1,1,26,26,26
26,26,26,26,26,26,1,1,1,1,1,1,1,1,1,1,1,26,26,26
26,26,26,26,26,1,1,1,1,1,1,1,1,1,1,1,26,26,26,26
26,26,26,26,1,1,1,1,1,1,1,1,1,1,1,26,26,26,26,26
26,26,26,26,1,1,1,1,1,1,1,1,1,26,26,26,26,26,26,26
26,26,26,26,1,1,1,1,1,1,1,1,26,26,26,26,26,26,26,26
26,26,26,26,26,1,1,1,1,1,26,26,26,26,26,26,26,26,26,26
26,26,26,26,26,26,1,1,1,26,26,26,26,26,26,26,26,26,26,26
26,26,26,26,26,26,26,26,26,26,26,26,26,26,26,26,26,26,26,26
26,26,26,26,26,26,26,26,26,26,26,26,26,26,26,26,26,26,26,26
26,26,26,26,26,26,26,26,26,26,26,26,26,26,26,26,26,26,26,26
endlayer

layer
26,26,26,26,26,26,26,26,26,26,26,26,26,26,26,26,26,26,26,26
26,26,26,26,26,26,26,26,26,26,26,26,26,26,26,26,26,26,26,26
26,26,26,26,26,26,26,26,26,26,26,26,26,26,26,26,26,26,26,26
26,26,26,26,26,26,26,26,26,26,26,26,26,26,26,26,26,26,26,26
26,26,26,26,26,26,26,26,26,26,26,26,26,26,26,26,26,26,26,26
26,26,26,26,26,26,26,26,26,26,1,1,1,26,26,26,26,26,26,26
26,26,26,26,26,26,26,26,26,1,1,1,1,1,26,26,26,26,26,26
26,26,26,26,26,26,26,26,1,1,1,1,1,1,1,26,26,26,26,26
26,26,26,26,26,26,26,1,1,1,1,1,1,1,1,1,26,26,26,26
26,26,26,26,26,1,1,1,1,1,1,1,1,1,1,1,1,26,26,26
26,26,26,26,26,1,1,1,1,1,1,1,1,1,1,1,1,26,26,26
26,26,26,26,26,1,1,1,1,1,1,1,1,1,1,1,1,26,26,26
26,26,26,26,26,1,1,1,1,1,1,1,1,1,1,1,26,26,26,26
26,26,26,26,1,1,1,1,1,1,1,1,1,1,1,26,26,26,26,26
26,26,26,26,1,1,1,1,1,1,1,1,1,26,26,26,26,26,26,26
26,26,26,26,1,1,1,1,1,1,1,1,26,26,26,26,26,26,26,26
26,26,26,26,26,1,1,1,1,1,26,26,26,26,26,26,26,26,26,26
26,26,26,26,26,26,1,1,1,26,26,26,26,26,26,26,26,26,26,26
26,26,26,26,26,26,26,26,26,26,26,26,26,26,26,26,26,26,26,26
26,26,26,26,26,26,26,26,26,26,26,26,26,26,26,26,26,26,26,26
26,26,26,26,26,26,26,26,26,26,26,26,26,26,26,26,26,26,26,26
endlayer

layer
26,26,26,26,26,26,26,26,26,26,26,26,26,26,26,26,26,26,26,26
26,26,26,26,26,26,26,26,26,26,26,26,26,26,26,26,26,26,26,26
26,26,26,26,26,26,26,26,26,26,26,26,26,26,26,26,26,26,26,26
26,26,26,26,26,26,26,26,26,26,26,26,26,26,26,26,26,26,26,26
26,26,26,26,26,26,26,26,26,26,26,26,26,26,26,26,26,26,26,26
26,26,26,26,26,26,26,26,26,26,1,1,1,26,26,26,26,26,26,26
26,26,26,26,26,26,26,26,26,1,1,1,1,1,26,26,26,26,26,26
26,26,26,26,26,26,26,26,1,1,1,1,1,1,1,26,26,26,26,26
26,26,26,26,26,1,1,1,1,1,1,1,1,1,1,1,26,26,26,26
26,26,26,26,26,1,1,1,1,1,1,1,1,1,1,1,1,26,26,26
26,26,26,26,1,1,1,1,1,1,1,1,1,1,1,1,1,1,26,26
26,26,26,26,1,1,1,1,1,1,1,1,1,1,1,1,1,1,26,26
26,26,26,26,1,1,1,1,1,1,1,1,1,1,1,1,1,1,26,26
26,26,26,26,1,1,1,1,1,1,1,1,1,1,1,1,26,26,26,26
26,26,26,26,1,1,1,1,1,1,1,1,1,1,1,1,26,26,26,26
26,26,26,26,1,1,1,1,1,1,1,1,1,1,1,1,26,26,26,26
26,26,26,26,26,1,1,1,1,1,26,26,26,26,26,26,26,26,26,26
26,26,26,26,26,26,1,1,1,26,26,26,26,26,26,26,26,26,26,26
26,26,26,26,26,26,26,26,26,26,26,26,26,26,26,26,26,26,26,26
26,26,26,26,26,26,26,26,26,26,26,26,26,26,26,26,26,26,26,26
26,26,26,26,26,26,26,26,26,26,26,26,26,26,26,26,26,26,26,26
endlayer

layer
26,26,26,26,26,26,26,26,26,26,26,26,26,26,26,26,26,26,26,26
26,26,26,26,26,26,26,26,26,26,26,26,26,26,26,26,26,26,26,26
26,26,26,26,26,26,26,26,26,26,26,26,26,26,26,26,26,26,26,26
26,26,26,26,26,26,26,26,26,26,26,26,26,26,26,26,26,26,26,26
26,26,26,26,26,26,26,26,26,26,26,26,26,26,26,26,26,26,26,26
26,26,26,26,26,26,26,26,26,26,26,26,26,26,26,26,26,26,26,26
26,26,26,26,26,26,26,1,1,1,1,1,1,1,26,26,26,26,26,26
26,26,26,26,1,1,1,1,1,1,1,1,1,1,26,26,26,26,26,26
26,26,26,26,1,1,1,1,1,1,1,1,1,1,1,1,26,26,26,26
26,26,26,26,1,1,1,1,1,1,1,1,1,1,1,1,1,1,1,26
26,26,26,26,1,1,1,1,1,1,1,1,1,1,1,1,1,1,1,26
26,26,26,26,1,1,1,1,1,1,1,1,1,1,1,1,1,1,1,26
26,26,26,26,1,1,1,1,1,1,1,1,1,1,1,1,1,1,1,26
26,26,26,26,1,1,1,1,1,1,1,1,1,1,1,1,1,1,1,26
26,26,26,26,1,1,1,1,1,1,1,1,1,1,1,1,1,26,26,26
26,26,26,26,1,1,1,1,1,1,1,1,1,1,1,1,1,26,26,26
26,26,26,26,26,1,1,1,1,1,1,1,1,1,1,1,1,26,26,26
26,26,26,26,26,26,1,1,1,26,26,26,26,26,26,26,26,26,26,26
26,26,26,26,26,26,26,26,26,26,26,26,26,26,26,26,26,26,26,26
26,26,26,26,26,26,26,26,26,26,26,26,26,26,26,26,26,26,26,26
26,26,26,26,26,26,26,26,26,26,26,26,26,26,26,26,26,26,26,26
endlayer

layer
26,26,26,26,26,26,26,26,26,26,26,26,26,26,26,26,26,26,26,26
26,26,26,26,26,26,26,26,26,26,26,26,26,26,26,26,26,26,26,26
26,26,26,26,26,26,26,26,26,26,26,26,26,26,26,26,26,26,26,26
26,26,26,26,26,26,26,26,26,26,26,26,26,26,26,26,26,26,26,26
26,26,26,26,26,26,26,26,26,26,26,26,26,26,26,26,26,26,26,26
26,26,26,26,26,26,26,26,1,1,1,1,1,1,1,26,26,26,26,26
26,26,26,26,26,1,1,1,1,1,1,1,1,1,1,26,26,26,26,26
26,26,26,26,1,1,1,1,1,1,1,1,1,1,1,26,26,26,26,26
26,26,26,1,1,1,1,1,1,1,1,1,1,1,1,1,1,1,26,26
26,26,26,1,1,1,1,1,1,1,1,1,1,1,1,1,1,1,1,26
26,26,26,1,1,1,1,1,1,1,1,1,1,1,1,1,1,1,1,1
26,26,26,26,1,1,1,1,1,1,1,1,1,1,1,1,1,1,1,1
26,26,26,26,1,1,1,1,1,1,1,1,1,1,1,1,1,1,1,1
26,26,26,26,1,1,1,1,1,1,1,1,1,1,1,1,1,1,1,26
26,26,26,26,1,1,1,1,1,1,1,1,1,1,1,1,1,1,26,26
26,26,26,26,1,1,1,1,1,1,1,1,1,1,1,1,1,1,26,26
26,26,26,26,26,1,1,1,1,1,1,1,1,1,1,1,1,26,26,26
26,26,26,26,26,1,1,1,1,1,1,1,1,1,1,1,26,26,26,26
26,26,26,26,26,26,26,26,26,26,26,26,26,26,26,26,26,26,26,26
26,26,26,26,26,26,26,26,26,26,26,26,26,26,26,26,26,26,26,26
26,26,26,26,26,26,26,26,26,26,26,26,26,26,26,26,26,26,26,26
endlayer

layer
26,26,26,26,26,26,26,26,26,26,26,26,26,26,26,26,26,26,26,26
26,26,26,26,26,26,26,26,26,26,26,26,26,26,26,26,26,26,26,26
26,26,26,26,26,26,26,26,26,26,26,26,26,26,26,26,26,26,26,26
26,26,26,26,26,26,26,26,26,26,26,1,1,1,26,26,26,26,26,26
26,26,26,26,26,26,26,26,26,1,1,1,1,1,26,26,26,26,26,26
26,26,26,26,26,26,26,26,2,2,2,2,1,1,1,26,26,26,26,26
26,26,26,26,26,1,1,3,2,1,1,3,1,1,1,1,26,26,26,26
26,26,26,26,1,1,1,1,1,1,1,1,1,1,1,1,26,26,26,26
26,26,26,1,1,1,1,1,1,1,1,1,1,1,1,1,1,1,26,26
26,26,26,1,1,1,1,1,1,1,1,1,1,1,1,1,1,1,1,26
26,26,26,1,1,1,1,1,1,1,1,1,1,1,1,1,1,1,1,1
26,26,26,26,1,1,2,1,1,1,1,1,1,1,1,1,1,1,1,1
26,26,26,26,26,1,1,2,1,1,1,1,1,1,1,1,1,1,1,1
26,26,26,26,26,1,1,1,1,1,1,1,1,1,1,1,1,1,1,26
26,26,26,26,1,1,1,1,1,1,1,1,1,1,1,1,1,1,26,26
26,26,26,26,1,1,1,1,1,1,1,1,1,1,1,1,1,1,26,26
26,26,26,26,1,1,1,1,1,1,1,1,1,1,1,1,1,26,26,26
26,26,26,26,26,1,1,1,1,1,1,1,1,1,1,1,26,26,26,26
26,26,26,26,26,26,1,1,1,26,1,1,1,26,26,26,26,26,26,26
26,26,26,26,26,26,26,26,26,26,26,26,26,26,26,26,26,26,26,26
26,26,26,26,26,26,26,26,26,26,26,26,26,26,26,26,26,26,26,26
endlayer

layer
26,26,26,26,26,26,26,26,26,26,26,26,26,26,26,26,26,26,26,26
26,26,26,26,26,26,26,26,26,26,26,26,26,26,26,26,26,26,26,26
26,26,26,26,26,26,26,26,26,26,26,1,1,1,26,26,26,26,26,26
26,26,26,26,26,26,26,26,1,1,1,1,1,1,1,26,26,26,26,26
26,26,26,26,26,26,26,26,3,1,3,3,1,1,1,26,26,26,26,26
26,26,26,26,1,1,1,3,3,27,27,27,3,1,1,26,26,26,26,26
26,26,26,26,1,1,1,3,27,27,27,27,2,1,1,1,26,26,26,26
26,26,1,1,1,1,27,27,27,27,27,27,1,1,1,1,1,26,26,26
26,26,1,1,1,1,5,27,1,4,27,27,1,1,1,1,1,1,26,26
26,26,1,1,1,5,27,5,2,1,1,1,1,1,1,1,1,1,1,26
26,26,1,2,9,8,7,7,7,6,2,1,1,1,1,1,1,1,1,1
26,26,1,1,1,11,27,5,5,10,1,1,1,1,1,1,1,1,1,1
26,26,26,1,1,1,5,27,13,12,1,1,1,1,1,1,1,1,1,1
26,26,26,1,1,1,5,5,13,1,1,1,1,1,1,1,1,1,1,26
26,26,26,26,1,1,1,1,1,1,1,1,1,1,1,1,1,1,1,26
26,26,26,1,1,1,1,1,1,1,1,1,1,1,1,1,1,1,26,26
26,26,26,1,1,1,1,1,1,1,1,1,1,1,1,1,1,26,26,26
26,26,26,1,1,1,1,1,1,1,1,1,1,1,1,1,26,26,26,26
26,26,26,26,26,26,1,1,1,1,1,1,1,26,26,26,26,26,26,26
26,26,26,26,26,26,26,26,26,26,26,26,26,26,26,26,26,26,26,26
26,26,26,26,26,26,26,26,26,26,26,26,26,26,26,26,26,26,26,26
endlayer

layer
26,26,26,26,26,26,26,26,26,26,26,26,26,26,26,26,26,26,26,26
26,26,26,26,26,26,26,26,26,26,1,1,1,1,1,26,26,26,26,26
26,26,26,26,26,26,26,1,1,1,1,1,1,1,1,26,26,26,26,26
26,26,26,26,26,26,26,1,1,1,1,1,1,1,1,26,26,26,26,26
26,26,26,1,1,1,1,1,1,1,1,1,1,1,1,26,26,26,26,26
26,26,26,1,1,1,1,1,3,26,26,26,1,1,1,26,26,26,26,26
26,26,26,1,1,1,1,3,26,26,26,26,2,1,1,1,1,1,26,26
26,26,1,1,1,1,26,26,26,14,26,26,2,1,1,1,1,1,26,26
26,1,1,1,1,1,26,26,1,4,26,26,1,1,1,1,1,1,26,26
26,1,1,1,1,15,26,26,2,1,26,26,1,1,1,1,1,1,1,26
26,1,1,1,2,15,26,26,26,16,1,1,1,1,1,1,1,1,1,26
26,26,1,1,1,26,26,26,26,17,1,1,1,1,1,1,1,1,1,1
26,26,1,1,1,26,26,26,26,26,1,1,1,1,1,1,1,1,1,1
26,26,1,1,1,2,26,26,26,5,1,1,1,1,1,1,1,1,1,1
26,26,1,1,1,1,18,18,5,1,1,1,1,1,1,1,1,1,1,26
26,26,1,1,1,1,1,1,1,1,1,1,1,1,1,1,1,1,26,26
26,26,1,1,1,1,1,1,1,1,1,1,1,1,1,1,1,26,26,26
26,26,1,1,1,1,1,1,1,1,1,1,1,1,1,1,26,26,26,26
26,26,1,1,1,1,1,1,1,1,1,1,1,1,1,26,26,26,26,26
26,26,26,26,26,26,26,26,1,1,1,26,26,26,26,26,26,26,26,26
26,26,26,26,26,26,26,26,26,26,26,26,26,26,26,26,26,26,26,26
endlayer

layer
26,26,26,26,26,26,26,26,26,26,26,1,1,1,26,26,26,26,26,26
26,26,26,26,26,26,26,26,1,1,1,1,1,1,1,26,26,26,26,26
26,26,26,26,26,26,26,1,1,1,1,1,1,1,1,1,26,26,26,26
26,26,26,26,1,1,1,1,1,1,1,1,1,1,1,1,26,26,26,26
26,26,26,1,1,1,1,1,1,1,1,1,1,1,1,1,26,26,26,26
26,26,1,1,1,1,1,1,26,26,26,26,1,1,1,1,1,26,26,26
26,26,1,1,1,1,1,1,26,26,26,26,1,1,1,1,1,1,26,26
26,26,1,1,1,1,2,1,26,26,26,26,1,1,1,1,1,1,1,26
26,1,1,1,1,1,2,2,1,4,19,26,1,1,1,1,1,1,1,26
26,1,1,1,1,1,26,2,3,2,26,26,1,1,1,1,1,1,1,26
26,1,1,1,2,15,26,26,26,2,26,26,1,1,1,1,1,1,1,26
26,1,1,1,2,15,26,26,26,26,1,1,1,1,1,1,1,1,1,1
26,1,1,1,1,2,15,26,26,26,1,1,1,1,1,1,1,1,1,1
26,1,1,1,1,3,26,26,26,26,1,1,1,1,1,1,1,1,1,1
26,26,1,1,1,1,22,21,26,20,1,1,1,1,1,1,1,1,1,26
26,1,1,1,1,1,1,1,1,1,1,1,1,1,1,1,1,1,26,26
26,1,1,1,1,1,1,1,1,1,1,1,1,1,1,1,1,26,26,26
26,1,1,1,1,1,1,1,1,1,1,1,1,1,1,1,26,26,26,26
26,26,1,1,1,1,1,1,1,1,1,1,1,1,1,26,26,26,26,26
26,26,26,1,1,1,1,1,1,1,1,26,26,26,26,26,26,26,26,26
26,26,26,26,26,26,26,26,26,26,26,26,26,26,26,26,26,26,26,26
endlayer

layer
26,26,26,26,26,26,26,26,26,26,26,1,1,1,26,26,26,26,26,26
26,26,26,26,26,26,26,26,1,1,1,1,1,1,1,26,26,26,26,26
26,26,26,26,26,26,26,1,1,1,1,1,1,1,1,1,26,26,26,26
26,26,26,26,1,1,1,1,1,1,1,1,1,1,1,1,26,26,26,26
26,26,26,1,1,1,1,1,1,1,1,1,1,1,1,1,26,26,26,26
26,26,1,1,1,1,1,1,1,1,1,1,1,1,1,1,1,26,26,26
26,26,1,1,1,1,1,1,1,1,1,1,1,1,1,1,1,1,26,26
26,26,1,1,1,1,1,1,1,1,1,1,1,1,1,1,1,1,1,26
26,1,1,1,1,1,1,1,1,4,26,26,1,1,1,1,1,1,1,26
26,1,1,1,1,1,1,1,1,4,26,26,2,1,1,1,1,1,1,26
26,1,1,1,1,1,1,1,1,4,26,26,1,1,1,1,1,1,1,26
26,1,1,1,1,1,1,1,1,4,26,26,1,1,1,1,1,1,1,1
26,1,1,1,1,1,1,23,1,1,2,2,1,1,1,1,1,1,1,1
26,1,1,1,1,1,1,1,1,1,2,1,1,1,1,1,1,1,1,1
26,26,1,1,1,1,1,1,1,1,1,1,1,1,1,1,1,1,1,26
26,1,1,1,1,1,1,1,1,1,1,1,1,1,1,1,1,1,26,26
26,1,1,1,1,1,1,1,1,1,1,1,1,1,1,1,1,26,26,26
26,1,1,1,1,1,1,1,1,1,1,1,1,1,1,1,26,26,26,26
26,26,1,1,1,1,1,1,1,1,1,1,1,1,1,26,26,26,26,26
26,26,26,1,1,1,1,1,1,1,1,26,26,26,26,26,26,26,26,26
26,26,26,26,26,26,26,26,26,26,26,26,26,26,26,26,26,26,26,26
endlayer

layer
26,26,26,26,26,26,26,26,26,26,26,1,1,1,26,26,26,26,26,26
26,26,26,26,26,26,26,26,1,1,1,1,1,1,1,26,26,26,26,26
26,26,26,26,26,26,26,1,1,1,1,1,1,1,1,1,26,26,26,26
26,26,26,26,1,1,1,1,1,1,1,1,1,1,1,1,26,26,26,26
26,26,26,1,1,1,1,1,1,1,1,1,1,1,1,1,26,26,26,26
26,26,1,1,1,1,1,1,1,1,1,1,1,1,1,1,1,26,26,26
26,26,1,1,1,1,1,1,1,1,1,1,1,1,1,1,1,1,26,26
26,26,1,1,1,1,1,1,1,1,1,1,1,1,1,1,1,1,1,26
26,26,1,1,1,1,1,1,1,1,1,1,1,1,1,1,1,1,1,26
26,26,1,1,1,1,1,1,1,4,26,26,1,1,1,1,1,1,1,26
26,26,1,1,1,1,1,1,1,2,26,26,2,1,1,1,1,1,1,26
26,1,1,1,1,1,1,1,1,4,26,26,2,1,1,1,1,1,1,26
26,1,1,1,1,1,1,1,1,26,26,26,1,1,1,1,1,1,1,26
26,1,1,1,1,1,1,1,1,26,26,12,1,1,1,1,1,1,1,26
26,26,1,1,1,1,1,1,1,1,1,1,1,1,1,1,1,1,1,26
26,1,1,1,1,1,1,1,1,1,1,1,1,1,1,1,26,26,26,26
26,1,1,1,1,1,1,1,1,1,1,1,1,1,1,1,26,26,26,26
26,1,1,1,1,1,1,1,1,1,1,1,1,1,1,1,26,26,26,26
26,26,1,1,1,1,1,1,1,1,1,1,26,26,26,26,26,26,26,26
26,26,26,1,1,1,1,1,1,26,26,26,26,26,26,26,26,26,26,26
26,26,26,26,26,26,26,26,26,26,26,26,26,26,26,26,26,26,26,26
endlayer

layer
26,26,26,26,26,26,26,26,26,26,26,26,26,26,26,26,26,26,26,26
26,26,26,26,26,26,26,26,26,26,1,1,1,1,1,26,26,26,26,26
26,26,26,26,26,26,26,1,1,1,1,1,1,1,1,26,26,26,26,26
26,26,26,26,26,26,26,1,1,1,1,1,1,1,1,1,26,26,26,26
26,26,26,1,1,1,1,1,1,1,1,1,1,1,1,1,26,26,26,26
26,26,26,1,1,1,1,1,1,1,1,1,1,1,1,1,26,26,26,26
26,26,26,1,1,1,1,1,1,1,1,1,1,1,1,1,1,1,26,26
26,26,26,1,1,1,1,1,1,1,1,1,1,1,1,1,1,1,26,26
26,26,26,1,1,1,1,1,1,1,1,1,1,1,1,1,1,1,26,26
26,26,26,1,1,1,1,1,1,1,1,1,1,1,1,1,1,1,26,26
26,26,1,1,1,1,1,1,1,4,26,26,2,1,1,1,1,1,26,26
26,26,1,1,1,1,1,1,2,4,19,26,2,1,1,1,1,1,26,26
26,26,1,1,1,1,1,1,26,26,26,26,2,1,1,1,1,1,26,26
26,26,1,1,1,1,1,1,26,26,26,26,1,1,1,1,1,1,26,26
26,26,1,1,1,1,1,1,1,1,1,1,1,1,1,26,26,26,26,26
26,26,1,1,1,1,1,1,1,1,1,1,1,1,1,26,26,26,26,26
26,26,1,1,1,1,1,1,1,1,1,1,1,1,1,26,26,26,26,26
26,26,1,1,1,1,1,1,1,1,1,26,26,26,26,26,26,26,26,26
26,26,1,1,1,1,1,1,1,1,26,26,26,26,26,26,26,26,26,26
26,26,26,26,26,26,26,26,26,26,26,26,26,26,26,26,26,26,26,26
26,26,26,26,26,26,26,26,26,26,26,26,26,26,26,26,26,26,26,26
endlayer

layer
26,26,26,26,26,26,26,26,26,26,26,26,26,26,26,26,26,26,26,26
26,26,26,26,26,26,26,26,26,26,26,26,26,26,26,26,26,26,26,26
26,26,26,26,26,26,26,26,26,26,26,1,1,1,26,26,26,26,26,26
26,26,26,26,26,26,26,26,1,1,1,1,1,1,1,26,26,26,26,26
26,26,26,26,26,26,26,26,1,1,1,1,1,1,1,26,26,26,26,26
26,26,26,26,1,1,1,1,1,1,1,1,1,1,1,1,26,26,26,26
26,26,26,26,1,1,1,1,1,1,1,1,1,1,1,1,1,26,26,26
26,26,26,26,1,1,1,1,1,1,1,1,1,1,1,1,1,26,26,26
26,26,26,26,1,1,1,1,1,1,1,1,1,1,1,1,1,26,26,26
26,26,26,26,1,1,1,1,1,1,1,1,1,1,1,1,1,26,26,26
26,26,26,26,1,1,1,1,1,1,1,1,1,1,1,1,26,26,26,26
26,26,26,1,1,1,1,4,2,2,26,26,1,1,1,1,26,26,26,26
26,26,26,1,1,1,1,26,26,26,26,26,1,1,1,1,26,26,26,26
26,26,26,1,1,1,1,26,26,26,26,26,2,1,26,26,26,26,26,26
26,26,26,1,1,1,1,1,1,1,1,1,1,1,26,26,26,26,26,26
26,26,26,1,1,1,1,1,1,1,1,1,1,1,26,26,26,26,26,26
26,26,26,1,1,1,1,1,1,26,26,26,26,26,26,26,26,26,26,26
26,26,26,1,1,1,1,1,1,26,26,26,26,26,26,26,26,26,26,26
26,26,26,26,26,26,26,26,26,26,26,26,26,26,26,26,26,26,26,26
26,26,26,26,26,26,26,26,26,26,26,26,26,26,26,26,26,26,26,26
26,26,26,26,26,26,26,26,26,26,26,26,26,26,26,26,26,26,26,26
endlayer

layer
26,26,26,26,26,26,26,26,26,26,26,26,26,26,26,26,26,26,26,26
26,26,26,26,26,26,26,26,26,26,26,26,26,26,26,26,26,26,26,26
26,26,26,26,26,26,26,26,26,26,26,26,26,26,26,26,26,26,26,26
26,26,26,26,26,26,26,26,26,26,26,26,26,26,26,26,26,26,26,26
26,26,26,26,26,26,26,26,26,26,26,26,26,26,26,26,26,26,26,26
26,26,26,26,26,26,26,26,26,1,1,1,26,26,26,26,26,26,26,26
26,26,26,26,26,26,26,26,1,1,1,1,26,26,26,26,26,26,26,26
26,26,26,26,26,26,1,1,1,1,1,1,1,26,26,26,26,26,26,26
26,26,26,26,26,26,1,1,1,1,1,1,1,26,26,26,26,26,26,26
26,26,26,26,26,26,1,1,1,1,1,1,1,26,26,26,26,26,26,26
26,26,26,26,26,26,1,1,1,1,1,1,1,26,26,26,26,26,26,26
26,26,26,26,26,26,1,2,2,4,1,1,1,26,26,26,26,26,26,26
26,26,26,26,1,2,26,26,26,24,1,1,1,26,26,26,26,26,26,26
26,26,26,26,1,2,26,26,26,26,1,1,1,26,26,26,26,26,26,26
26,26,26,26,1,1,1,1,1,1,1,1,26,26,26,26,26,26,26,26
26,26,26,26,1,1,1,1,1,1,1,26,26,26,26,26,26,26,26,26
26,26,26,26,1,1,1,1,26,26,26,26,26,26,26,26,26,26,26,26
26,26,26,26,26,26,26,26,26,26,26,26,26,26,26,26,26,26,26,26
26,26,26,26,26,26,26,26,26,26,26,26,26,26,26,26,26,26,26,26
26,26,26,26,26,26,26,26,26,26,26,26,26,26,26,26,26,26,26,26
26,26,26,26,26,26,26,26,26,26,26,26,26,26,26,26,26,26,26,26
endlayer

layer
26,26,26,26,26,26,26,26,26,26,26,26,26,26,26,26,26,26,26,26
26,26,26,26,26,26,26,26,26,26,26,26,26,26,26,26,26,26,26,26
26,26,26,26,26,26,26,26,26,26,26,26,26,26,26,26,26,26,26,26
26,26,26,26,26,26,26,26,26,26,26,26,26,26,26,26,26,26,26,26
26,26,26,26,26,26,26,26,26,26,26,26,26,26,26,26,26,26,26,26
26,26,26,26,26,26,26,26,26,26,26,26,26,26,26,26,26,26,26,26
26,26,26,26,26,26,26,26,26,26,26,26,26,26,26,26,26,26,26,26
26,26,26,26,26,26,26,26,26,26,26,26,26,26,26,26,26,26,26,26
26,26,26,26,26,26,26,26,26,26,26,26,26,26,26,26,26,26,26,26
26,26,26,26,26,26,26,4,4,1,1,26,26,26,26,26,26,26,26,26
26,26,26,26,26,26,26,26,1,1,1,26,26,26,26,26,26,26,26,26
26,26,26,26,26,26,26,26,26,4,1,26,26,26,26,26,26,26,26,26
26,26,26,26,26,26,26,26,26,26,1,26,26,26,26,26,26,26,26,26
26,26,26,26,26,26,26,26,26,1,1,26,26,26,26,26,26,26,26,26
26,26,26,26,26,26,26,2,2,1,1,26,26,26,26,26,26,26,26,26
26,26,26,26,26,4,4,4,3,26,26,26,26,26,26,26,26,26,26,26
26,26,26,26,26,26,26,26,26,26,26,26,26,26,26,26,26,26,26,26
26,26,26,26,26,26,26,26,26,26,26,26,26,26,26,26,26,26,26,26
26,26,26,26,26,26,26,26,26,26,26,26,26,26,26,26,26,26,26,26
26,26,26,26,26,26,26,26,26,26,26,26,26,26,26,26,26,26,26,26
26,26,26,26,26,26,26,26,26,26,26,26,26,26,26,26,26,26,26,26
endlayer

layer
26,26,26,26,26,26,26,26,26,26,26,26,26,26,26,26,26,26,26,26
26,26,26,26,26,26,26,26,26,26,26,26,26,26,26,26,26,26,26,26
26,26,26,26,26,26,26,26,26,26,26,26,26,26,26,26,26,26,26,26
26,26,26,26,26,26,26,26,26,26,26,26,26,26,26,26,26,26,26,26
26,26,26,26,26,26,26,26,26,26,26,26,26,26,26,26,26,26,26,26
26,26,26,26,26,26,26,26,26,26,26,26,26,26,26,26,26,26,26,26
26,26,26,26,26,26,26,26,26,26,26,26,26,26,26,26,26,26,26,26
26,26,26,26,26,26,26,26,26,26,26,26,26,26,26,26,26,26,26,26
26,26,26,26,26,26,26,26,26,26,26,26,26,26,26,26,26,26,26,26
26,26,26,26,26,26,26,26,25,26,26,26,26,26,26,26,26,26,26,26
26,26,26,26,26,26,26,26,25,4,26,26,26,26,26,26,26,26,26,26
26,26,26,26,26,26,26,26,26,4,3,26,26,26,26,26,26,26,26,26
26,26,26,26,26,26,26,26,26,2,3,26,26,26,26,26,26,26,26,26
26,26,26,26,26,26,26,26,26,2,3,26,26,26,26,26,26,26,26,26
26,26,26,26,26,26,26,25,3,3,26,26,26,26,26,26,26,26,26,26
26,26,26,26,26,26,26,26,26,26,26,26,26,26,26,26,26,26,26,26
26,26,26,26,26,26,26,26,26,26,26,26,26,26,26,26,26,26,26,26
26,26,26,26,26,26,26,26,26,26,26,26,26,26,26,26,26,26,26,26
26,26,26,26,26,26,26,26,26,26,26,26,26,26,26,26,26,26,26,26
26,26,26,26,26,26,26,26,26,26,26,26,26,26,26,26,26,26,26,26
26,26,26,26,26,26,26,26,26,26,26,26,26,26,26,26,26,26,26,26
endlayer

layer
26,26,26,26,26,26,26,26,26,26,26,26,26,26,26,26,26,26,26,26
26,26,26,26,26,26,26,26,26,26,26,26,26,26,26,26,26,26,26,26
26,26,26,26,26,26,26,26,26,26,26,26,26,26,26,26,26,26,26,26
26,26,26,26,26,26,26,26,26,26,26,26,26,26,26,26,26,26,26,26
26,26,26,26,26,26,26,26,26,26,26,26,26,26,26,26,26,26,26,26
26,26,26,26,26,26,26,26,26,26,26,26,26,26,26,26,26,26,26,26
26,26,26,26,26,26,26,26,26,26,26,26,26,26,26,26,26,26,26,26
26,26,26,26,26,26,26,26,26,26,26,26,26,26,26,26,26,26,26,26
26,26,26,26,26,26,26,26,26,26,26,26,26,26,26,26,26,26,26,26
26,26,26,26,26,26,26,26,26,26,26,26,26,26,26,26,26,26,26,26
26,26,26,26,26,26,26,26,25,4,26,26,26,26,26,26,26,26,26,26
26,26,26,26,26,26,26,26,26,2,26,26,26,26,26,26,26,26,26,26
26,26,26,26,26,26,26,26,26,3,26,26,26,26,26,26,26,26,26,26
26,26,26,26,26,26,26,26,26,3,26,26,26,26,26,26,26,26,26,26
26,26,26,26,26,26,26,25,25,3,26,26,26,26,26,26,26,26,26,26
26,26,26,26,26,26,26,26,26,26,26,26,26,26,26,26,26,26,26,26
26,26,26,26,26,26,26,26,26,26,26,26,26,26,26,26,26,26,26,26
26,26,26,26,26,26,26,26,26,26,26,26,26,26,26,26,26,26,26,26
26,26,26,26,26,26,26,26,26,26,26,26,26,26,26,26,26,26,26,26
26,26,26,26,26,26,26,26,26,26,26,26,26,26,26,26,26,26,26,26
26,26,26,26,26,26,26,26,26,26,26,26,26,26,26,26,26,26,26,26
endlayer

layer
26,26,26,26,26,26,26,26,26,26,26,26,26,26,26,26,26,26,26,26
26,26,26,26,26,26,26,26,26,26,26,26,26,26,26,26,26,26,26,26
26,26,26,26,26,26,26,26,26,26,26,26,26,26,26,26,26,26,26,26
26,26,26,26,26,26,26,26,26,26,26,26,26,26,26,26,26,26,26,26
26,26,26,26,26,26,26,26,26,26,26,26,26,26,26,26,26,26,26,26
26,26,26,26,26,26,26,26,26,26,26,26,26,26,26,26,26,26,26,26
26,26,26,26,26,26,26,26,26,26,26,26,26,26,26,26,26,26,26,26
26,26,26,26,26,26,26,26,26,26,26,26,26,26,26,26,26,26,26,26
26,26,26,26,26,26,26,26,26,26,26,26,26,26,26,26,26,26,26,26
26,26,26,26,26,26,26,26,26,26,26,26,26,26,26,26,26,26,26,26
26,26,26,26,26,26,26,26,25,4,26,26,26,26,26,26,26,26,26,26
26,26,26,26,26,26,26,26,26,3,26,26,26,26,26,26,26,26,26,26
26,26,26,26,26,26,26,26,26,25,26,26,26,26,26,26,26,26,26,26
26,26,26,26,26,26,26,26,26,3,26,26,26,26,26,26,26,26,26,26
26,26,26,26,26,26,26,26,26,25,26,26,26,26,26,26,26,26,26,26
26,26,26,26,26,26,26,26,26,26,26,26,26,26,26,26,26,26,26,26
26,26,26,26,26,26,26,26,26,26,26,26,26,26,26,26,26,26,26,26
26,26,26,26,26,26,26,26,26,26,26,26,26,26,26,26,26,26,26,26
26,26,26,26,26,26,26,26,26,26,26,26,26,26,26,26,26,26,26,26
26,26,26,26,26,26,26,26,26,26,26,26,26,26,26,26,26,26,26,26
26,26,26,26,26,26,26,26,26,26,26,26,26,26,26,26,26,26,26,26
endlayer

layer
26,26,26,26,26,26,26,26,26,26,26,26,26,26,26,26,26,26,26,26
26,26,26,26,26,26,26,26,26,26,26,26,26,26,26,26,26,26,26,26
26,26,26,26,26,26,26,26,26,26,26,26,26,26,26,26,26,26,26,26
26,26,26,26,26,26,26,26,26,26,26,26,26,26,26,26,26,26,26,26
26,26,26,26,26,26,26,26,26,26,26,26,26,26,26,26,26,26,26,26
26,26,26,26,26,26,26,26,26,26,26,26,26,26,26,26,26,26,26,26
26,26,26,26,26,26,26,26,26,26,26,26,26,26,26,26,26,26,26,26
26,26,26,26,26,26,26,26,26,26,26,26,26,26,26,26,26,26,26,26
26,26,26,26,26,26,26,26,26,26,26,26,26,26,26,26,26,26,26,26
26,26,26,26,26,26,26,26,26,26,26,26,26,26,26,26,26,26,26,26
26,26,26,26,26,26,26,26,26,2,26,26,26,26,26,26,26,26,26,26
26,26,26,26,26,26,26,26,26,25,26,26,26,26,26,26,26,26,26,26
26,26,26,26,26,26,26,26,26,25,26,26,26,26,26,26,26,26,26,26
26,26,26,26,26,26,26,26,26,3,26,26,26,26,26,26,26,26,26,26
26,26,26,26,26,26,26,26,26,25,26,26,26,26,26,26,26,26,26,26
26,26,26,26,26,26,26,26,26,26,26,26,26,26,26,26,26,26,26,26
26,26,26,26,26,26,26,26,26,26,26,26,26,26,26,26,26,26,26,26
26,26,26,26,26,26,26,26,26,26,26,26,26,26,26,26,26,26,26,26
26,26,26,26,26,26,26,26,26,26,26,26,26,26,26,26,26,26,26,26
26,26,26,26,26,26,26,26,26,26,26,26,26,26,26,26,26,26,26,26
26,26,26,26,26,26,26,26,26,26,26,26,26,26,26,26,26,26,26,26
endlayer

layer
26,26,26,26,26,26,26,26,26,26,26,26,26,26,26,26,26,26,26,26
26,26,26,26,26,26,26,26,26,26,26,26,26,26,26,26,26,26,26,26
26,26,26,26,26,26,26,26,26,26,26,26,26,26,26,26,26,26,26,26
26,26,26,26,26,26,26,26,26,26,26,26,26,26,26,26,26,26,26,26
26,26,26,26,26,26,26,26,26,26,26,26,26,26,26,26,26,26,26,26
26,26,26,26,26,26,26,26,26,26,26,26,26,26,26,26,26,26,26,26
26,26,26,26,26,26,26,26,26,26,26,26,26,26,26,26,26,26,26,26
26,26,26,26,26,26,26,26,26,26,26,26,26,26,26,26,26,26,26,26
26,26,26,26,26,26,26,26,26,26,26,26,26,26,26,26,26,26,26,26
26,26,26,26,26,26,26,26,26,26,26,26,26,26,26,26,26,26,26,26
26,26,26,26,26,26,26,26,26,2,26,26,26,26,26,26,26,26,26,26
26,26,26,26,26,26,26,26,26,26,26,26,26,26,26,26,26,26,26,26
26,26,26,26,26,26,26,26,26,26,26,26,26,26,26,26,26,26,26,26
26,26,26,26,26,26,26,26,26,26,26,26,26,26,26,26,26,26,26,26
26,26,26,26,26,26,26,26,26,26,26,26,26,26,26,26,26,26,26,26
26,26,26,26,26,26,26,26,26,26,26,26,26,26,26,26,26,26,26,26
26,26,26,26,26,26,26,26,26,26,26,26,26,26,26,26,26,26,26,26
26,26,26,26,26,26,26,26,26,26,26,26,26,26,26,26,26,26,26,26
26,26,26,26,26,26,26,26,26,26,26,26,26,26,26,26,26,26,26,26
26,26,26,26,26,26,26,26,26,26,26,26,26,26,26,26,26,26,26,26
26,26,26,26,26,26,26,26,26,26,26,26,26,26,26,26,26,26,26,26
endlayer

