# 复杂白桦浮冰岛的生成文件
# 特点是浮冰岛上有一颗极高的白桦树和一些沙砾
# 在水星的水面生成

weight=1
embed_into_distance=4
acceptable_target_blocks=water
unacceptable_target_blocks=
dimensions=39,13,13
allowable_overhang=0
max_leveling=0
leveling_buffer=0
preserve_water=0
preserve_lava=0
biomesToSpawnIn=<plains>

rule1=0,100,minecraft:ice-0
rule2=0,100,minecraft:packed_ice-0
rule3=0,100,minecraft:leaves-4
rule4=0,100,minecraft:dirt-0
rule5=0,100,minecraft:log-2
rule6=0,100,minecraft:gravel-0
rule7=0,100,minecraft:leaves-12
rule8=0,100,minecraft:vine-8
rule9=0,100,minecraft:vine-1
rule10=0,100,minecraft:vine-2
rule11=0,100,minecraft:vine-4
rule12=0,100,minecraft:vine-0
rule13=0,100,minecraft:leaves-6
rule14=0,100,minecraft:leaves-14
rule15=0,100,minecraft:preserveBlock

layer
15,15,15,15,15,15,15,15,15,15,15,15,15
15,15,15,15,15,15,15,15,15,15,15,15,15
15,15,15,15,15,15,15,15,15,15,15,15,15
15,15,15,15,15,15,15,15,15,15,15,15,15
15,15,15,15,15,15,15,15,15,15,15,15,15
15,15,15,15,15,15,15,15,15,15,15,15,15
15,15,15,15,15,15,15,15,15,15,15,15,15
15,15,15,15,15,15,15,1,15,15,15,15,15
15,15,15,15,15,15,15,15,15,15,15,15,15
15,15,15,15,15,15,15,15,15,15,15,15,15
15,15,15,15,15,15,15,15,15,15,15,15,15
15,15,15,15,15,15,15,15,15,15,15,15,15
15,15,15,15,15,15,15,15,15,15,15,15,15
endlayer

layer
15,15,15,15,15,15,15,15,15,15,15,15,15
15,15,15,15,15,15,15,15,15,15,15,15,15
15,15,15,15,15,2,2,2,15,2,2,2,15
15,15,15,2,2,2,2,2,2,2,2,2,15
15,15,15,2,2,2,2,2,2,2,2,2,15
15,2,2,2,2,2,15,2,2,2,2,2,15
15,2,2,2,2,2,2,2,2,2,2,2,15
15,2,2,2,2,2,2,2,2,2,2,2,15
15,15,2,2,2,2,2,2,2,15,15,15,15
15,15,2,2,2,2,2,15,15,15,15,15,15
15,15,2,2,2,2,2,15,15,15,15,15,15
15,15,15,15,15,15,15,15,15,15,15,15,15
15,15,15,15,15,15,15,15,15,15,15,15,15
endlayer

layer
15,15,15,15,15,15,15,15,15,15,15,15,15
15,15,15,15,15,2,2,2,2,2,2,2,15
15,15,15,2,2,2,2,2,2,2,2,2,2
15,15,2,2,2,2,2,2,2,2,2,2,2
15,2,2,2,2,2,2,2,2,2,2,2,2
2,2,2,2,2,2,2,2,2,2,2,2,2
2,2,2,2,2,2,2,2,2,2,2,2,2
2,2,2,2,2,2,2,2,2,2,2,2,2
15,2,2,2,2,2,2,2,2,2,2,2,15
15,2,2,2,2,2,2,2,2,2,15,15,15
15,2,2,2,2,2,2,2,15,15,15,15,15
15,15,2,2,2,2,2,15,15,15,15,15,15
15,15,15,15,15,15,15,15,15,15,15,15,15
endlayer

layer
15,15,15,15,15,15,15,15,15,15,15,15,15
15,15,15,15,15,2,2,2,2,2,2,2,15
15,15,15,2,2,2,2,2,2,2,2,2,2
15,15,2,2,2,2,2,2,2,2,2,2,2
15,2,2,2,2,2,2,2,2,2,2,2,2
2,2,2,2,2,2,2,2,2,2,2,2,2
2,2,2,2,2,2,2,2,2,2,2,2,2
2,2,2,2,2,2,2,2,2,2,2,2,2
15,2,2,2,2,2,2,2,2,2,2,2,15
15,2,2,2,2,2,2,2,2,2,15,15,15
15,2,2,2,2,2,2,2,2,15,15,15,15
15,15,2,2,2,2,2,15,15,15,15,15,15
15,15,15,15,15,15,15,15,15,15,15,15,15
endlayer

layer
15,15,15,15,15,15,15,15,15,15,15,15,15
15,15,15,15,15,2,2,2,2,2,2,2,15
15,15,15,2,2,2,2,2,2,2,2,2,2
15,15,2,2,2,2,2,2,2,2,2,2,2
15,2,2,2,2,2,2,2,2,2,2,2,2
15,2,2,2,2,2,2,2,2,2,2,2,2
2,2,2,2,2,2,2,2,2,2,2,2,2
2,2,2,2,2,2,2,2,2,2,2,2,2
15,2,2,2,2,2,2,2,2,2,2,2,15
15,2,2,2,2,2,2,2,2,2,15,15,15
15,2,2,2,2,2,2,2,2,15,15,15,15
15,15,2,2,2,2,2,15,15,15,15,15,15
15,15,15,15,15,15,15,15,15,15,15,15,15
endlayer

layer
15,15,15,15,15,15,15,15,15,15,15,15,15
15,15,15,15,15,15,15,3,15,15,15,15,15
15,15,15,15,15,2,2,2,2,2,2,2,15
15,15,15,2,2,2,2,2,2,2,2,2,15
15,2,2,2,2,2,2,2,2,2,2,2,15
15,2,2,2,2,2,2,2,4,2,2,2,15
15,2,2,2,2,2,2,2,2,2,2,2,15
15,2,2,2,2,2,2,2,2,2,2,2,15
15,2,2,2,2,2,2,2,2,2,2,15,15
15,15,2,2,2,2,2,2,2,2,15,15,15
15,15,2,2,2,2,2,2,2,15,15,15,15
15,15,15,15,15,15,15,15,15,15,15,15,15
15,15,15,15,15,15,15,15,15,15,15,15,15
endlayer

layer
15,15,15,15,15,15,15,15,15,15,15,15,15
15,15,15,15,15,15,15,3,15,15,15,15,15
15,15,15,15,15,15,3,5,3,15,15,15,15
15,15,15,15,15,15,15,3,15,15,15,15,15
15,15,15,15,6,6,6,6,6,15,15,15,15
15,15,15,6,3,6,2,6,5,6,15,15,15
15,15,15,3,5,2,6,2,6,6,15,15,15
15,15,15,6,7,6,6,2,6,2,15,15,15
15,15,15,15,15,6,2,2,2,2,3,15,15
15,15,15,15,15,2,2,2,2,2,15,15,15
15,15,15,15,15,15,15,15,15,15,15,15,15
15,15,15,15,15,15,15,15,15,15,15,15,15
15,15,15,15,15,15,15,15,15,15,15,15,15
endlayer

layer
15,15,15,15,15,15,15,15,15,15,15,15,15
15,15,15,15,15,15,15,3,15,15,15,15,15
15,15,15,15,15,15,3,5,3,15,15,15,15
15,15,15,15,15,15,15,3,15,15,15,15,15
15,15,15,15,15,15,15,15,15,15,15,15,15
15,15,15,15,3,15,15,15,5,15,15,15,15
15,15,15,3,3,3,15,15,6,15,15,15,15
15,15,15,15,3,15,15,15,15,3,15,15,15
15,15,15,15,15,15,15,15,7,5,3,15,15
15,15,15,15,15,15,15,15,15,7,15,15,15
15,15,15,15,15,15,15,15,15,15,15,15,15
15,15,15,15,15,15,15,15,15,15,15,15,15
15,15,15,15,15,15,15,15,15,15,15,15,15
endlayer

layer
15,15,15,15,15,15,15,15,15,15,15,15,15
15,15,15,15,15,15,15,3,15,15,15,15,15
15,15,15,15,15,15,3,3,3,15,15,15,15
15,15,15,15,15,15,15,3,15,15,15,15,15
15,15,15,15,15,15,15,15,8,15,15,15,15
15,15,15,15,15,15,15,15,5,15,15,15,15
15,15,15,15,15,15,15,15,15,15,15,15,15
15,15,15,15,15,15,15,15,15,3,15,15,15
15,15,15,15,15,15,15,15,7,7,3,15,15
15,15,15,15,15,15,15,15,15,3,15,15,15
15,15,15,15,15,15,15,15,15,15,15,15,15
15,15,15,15,15,15,15,15,15,15,15,15,15
15,15,15,15,15,15,15,15,15,15,15,15,15
endlayer

layer
15,15,15,15,15,15,15,15,15,15,15,15,15
15,15,15,15,15,15,15,15,15,15,15,15,15
15,15,15,15,15,15,15,15,15,15,15,15,15
15,15,15,15,15,15,15,15,15,15,15,15,15
15,15,15,15,15,15,15,15,8,15,15,15,15
15,15,15,15,15,15,15,15,5,15,15,15,15
15,15,15,15,15,15,15,15,15,15,15,15,15
15,15,15,15,15,15,15,15,15,15,15,15,15
15,15,15,15,15,15,15,15,15,15,15,15,15
15,15,15,15,15,15,15,15,15,15,15,15,15
15,15,15,15,15,15,15,15,15,15,15,15,15
15,15,15,15,15,15,15,15,15,15,15,15,15
15,15,15,15,15,15,15,15,15,15,15,15,15
endlayer

layer
15,15,15,15,15,15,15,15,15,15,15,15,15
15,15,15,15,15,15,15,15,15,15,15,15,15
15,15,15,15,15,15,15,15,15,15,15,15,15
15,15,15,15,15,15,15,15,15,15,15,15,15
15,15,15,15,15,15,15,15,8,15,15,15,15
15,15,15,15,15,15,15,15,5,15,15,15,15
15,15,15,15,15,15,15,15,15,15,15,15,15
15,15,15,15,15,15,15,15,15,15,15,15,15
15,15,15,15,15,15,15,15,15,15,15,15,15
15,15,15,15,15,15,15,15,15,15,15,15,15
15,15,15,15,15,15,15,15,15,15,15,15,15
15,15,15,15,15,15,15,15,15,15,15,15,15
15,15,15,15,15,15,15,15,15,15,15,15,15
endlayer

layer
15,15,15,15,15,15,15,15,15,15,15,15,15
15,15,15,15,15,15,15,15,15,15,15,15,15
15,15,15,15,15,15,15,15,15,15,15,15,15
15,15,15,15,15,15,15,15,15,15,15,15,15
15,15,15,15,15,15,15,15,8,15,15,15,15
15,15,15,15,15,15,15,15,5,9,15,15,15
15,15,15,15,15,15,15,15,10,15,15,15,15
15,15,15,15,15,15,15,15,15,15,15,15,15
15,15,15,15,15,15,15,15,15,15,15,15,15
15,15,15,15,15,15,15,15,15,15,15,15,15
15,15,15,15,15,15,15,15,15,15,15,15,15
15,15,15,15,15,15,15,15,15,15,15,15,15
15,15,15,15,15,15,15,15,15,15,15,15,15
endlayer

layer
15,15,15,15,15,15,15,15,15,15,15,15,15
15,15,15,15,15,15,15,15,15,15,15,15,15
15,15,15,15,15,15,15,15,15,15,15,15,15
15,15,15,15,15,15,15,15,15,15,15,15,15
15,15,15,15,15,15,15,15,8,15,15,15,15
15,15,15,15,15,15,15,11,5,9,15,15,15
15,15,15,15,15,15,15,15,10,15,15,15,15
15,15,15,15,15,15,15,15,15,15,15,15,15
15,15,15,15,15,15,15,15,15,15,15,15,15
15,15,15,15,15,15,15,15,15,15,15,15,15
15,15,15,15,15,15,15,15,15,15,15,15,15
15,15,15,15,15,15,15,15,15,15,15,15,15
15,15,15,15,15,15,15,15,15,15,15,15,15
endlayer

layer
15,15,15,15,15,15,15,15,15,15,15,15,15
15,15,15,15,15,15,15,15,15,15,15,15,15
15,15,15,15,15,15,15,15,15,15,15,15,15
15,15,15,15,15,15,15,15,15,15,15,15,15
15,15,15,15,15,15,15,15,8,15,15,15,15
15,15,15,15,15,15,15,11,5,9,15,15,15
15,15,15,15,15,15,15,15,10,15,15,15,15
15,15,15,15,15,15,15,15,15,15,15,15,15
15,15,15,15,15,15,15,15,15,15,15,15,15
15,15,15,15,15,15,15,15,15,15,15,15,15
15,15,15,15,15,15,15,15,15,15,15,15,15
15,15,15,15,15,15,15,15,15,15,15,15,15
15,15,15,15,15,15,15,15,15,15,15,15,15
endlayer

layer
15,15,15,15,15,15,15,15,15,15,15,15,15
15,15,15,15,15,15,15,15,15,15,15,15,15
15,15,15,15,15,15,15,15,15,15,15,15,15
15,15,15,15,15,15,15,15,15,15,15,15,15
15,15,15,15,15,15,15,15,8,15,15,15,15
15,15,15,15,15,15,15,11,5,9,15,15,15
15,15,15,15,15,15,15,15,15,15,15,15,15
15,15,15,15,15,15,15,15,15,15,15,15,15
15,15,15,15,15,15,15,15,15,15,15,15,15
15,15,15,15,15,15,15,15,15,15,15,15,15
15,15,15,15,15,15,15,15,15,15,15,15,15
15,15,15,15,15,15,15,15,15,15,15,15,15
15,15,15,15,15,15,15,15,15,15,15,15,15
endlayer

layer
15,15,15,15,15,15,15,15,15,15,15,15,15
15,15,15,15,15,15,15,15,15,15,15,15,15
15,15,15,15,15,15,15,15,15,15,15,15,15
15,15,15,15,15,15,15,15,15,15,15,15,15
15,15,15,15,15,15,15,15,8,15,15,15,15
15,15,15,15,15,15,15,11,5,9,15,15,15
15,15,15,15,15,15,15,15,15,15,15,15,15
15,15,15,15,15,15,15,15,15,15,15,15,15
15,15,15,15,15,15,15,15,15,15,15,15,15
15,15,15,15,15,15,15,15,15,15,15,15,15
15,15,15,15,15,15,15,15,15,15,15,15,15
15,15,15,15,15,15,15,15,15,15,15,15,15
15,15,15,15,15,15,15,15,15,15,15,15,15
endlayer

layer
15,15,15,15,15,15,15,15,15,15,15,15,15
15,15,15,15,15,15,15,15,15,15,15,15,15
15,15,15,15,15,15,15,15,15,15,15,15,15
15,15,15,15,15,15,15,15,15,15,15,15,15
15,15,15,15,15,15,15,15,15,15,15,15,15
15,15,15,15,15,15,15,11,5,15,15,15,15
15,15,15,15,15,15,15,15,10,15,15,15,15
15,15,15,15,15,15,15,15,15,15,15,15,15
15,15,15,15,15,15,15,15,15,15,15,15,15
15,15,15,15,15,15,15,15,15,15,15,15,15
15,15,15,15,15,15,15,15,15,15,15,15,15
15,15,15,15,15,15,15,15,15,15,15,15,15
15,15,15,15,15,15,15,15,15,15,15,15,15
endlayer

layer
15,15,15,15,15,15,15,15,15,15,15,15,15
15,15,15,15,15,15,15,15,15,15,15,15,15
15,15,15,15,15,15,15,15,15,15,15,15,15
15,15,15,15,15,15,15,15,15,15,15,15,15
15,15,15,15,15,15,15,15,8,15,15,15,15
15,15,15,15,15,15,15,11,5,9,15,15,15
15,15,15,15,15,15,15,15,10,15,15,15,15
15,15,15,15,15,15,15,15,15,15,15,15,15
15,15,15,15,15,15,15,15,15,15,15,15,15
15,15,15,15,15,15,15,15,15,15,15,15,15
15,15,15,15,15,15,15,15,15,15,15,15,15
15,15,15,15,15,15,15,15,15,15,15,15,15
15,15,15,15,15,15,15,15,15,15,15,15,15
endlayer

layer
15,15,15,15,15,15,15,15,15,15,15,15,15
15,15,15,15,15,15,15,15,15,15,15,15,15
15,15,15,15,15,15,15,15,15,15,15,15,15
15,15,15,15,15,15,15,15,15,15,15,15,15
15,15,15,15,15,15,15,15,15,15,15,15,15
15,15,15,15,15,15,15,11,5,15,15,15,15
15,15,15,15,15,15,15,15,10,15,15,15,15
15,15,15,15,15,15,15,15,15,15,15,15,15
15,15,15,15,15,15,15,15,15,15,15,15,15
15,15,15,15,15,15,15,15,15,15,15,15,15
15,15,15,15,15,15,15,15,15,15,15,15,15
15,15,15,15,15,15,15,15,15,15,15,15,15
15,15,15,15,15,15,15,15,15,15,15,15,15
endlayer

layer
15,15,15,15,15,15,15,15,15,15,15,15,15
15,15,15,15,15,15,15,15,15,15,15,15,15
15,15,15,15,15,15,15,15,15,15,15,15,15
15,15,15,15,15,15,15,15,15,15,15,15,15
15,15,15,15,15,15,15,15,8,15,15,15,15
15,15,15,15,15,15,15,11,5,15,15,15,15
15,15,15,15,15,15,15,15,10,15,15,15,15
15,15,15,15,15,15,15,15,15,15,15,15,15
15,15,15,15,15,15,15,15,15,15,15,15,15
15,15,15,15,15,15,15,15,15,15,15,15,15
15,15,15,15,15,15,15,15,15,15,15,15,15
15,15,15,15,15,15,15,15,15,15,15,15,15
15,15,15,15,15,15,15,15,15,15,15,15,15
endlayer

layer
15,15,15,15,15,15,15,15,15,15,15,15,15
15,15,15,15,15,15,15,15,15,15,15,15,15
15,15,15,15,15,15,15,15,15,15,15,15,15
15,15,15,15,15,15,15,15,15,15,15,15,15
15,15,15,15,15,15,15,15,8,15,15,15,15
15,15,15,15,15,15,15,11,5,15,15,15,15
15,15,15,15,15,15,15,15,10,15,15,15,15
15,15,15,15,15,15,15,15,15,15,15,15,15
15,15,15,15,15,15,15,15,15,15,15,15,15
15,15,15,15,15,15,15,15,15,15,15,15,15
15,15,15,15,15,15,15,15,15,15,15,15,15
15,15,15,15,15,15,15,15,15,15,15,15,15
15,15,15,15,15,15,15,15,15,15,15,15,15
endlayer

layer
15,15,15,15,15,15,15,15,15,15,15,15,15
15,15,15,15,15,15,15,15,15,15,15,15,15
15,15,15,15,15,15,15,15,15,15,15,15,15
15,15,15,15,15,15,15,15,15,15,15,15,15
15,15,15,15,15,15,15,15,8,15,15,15,15
15,15,15,15,15,15,15,11,5,15,15,15,15
15,15,15,15,15,15,15,15,10,15,15,15,15
15,15,15,15,15,15,15,15,15,15,15,15,15
15,15,15,15,15,15,15,15,15,15,15,15,15
15,15,15,15,15,15,15,15,15,15,15,15,15
15,15,15,15,15,15,15,15,15,15,15,15,15
15,15,15,15,15,15,15,15,15,15,15,15,15
15,15,15,15,15,15,15,15,15,15,15,15,15
endlayer

layer
15,15,15,15,15,15,15,15,15,15,15,15,15
15,15,15,15,15,15,15,15,15,15,15,15,15
15,15,15,15,15,15,15,15,15,15,15,15,15
15,15,15,15,15,15,15,15,15,15,15,15,15
15,15,15,15,15,15,15,15,8,15,15,15,15
15,15,15,15,15,15,15,15,5,15,15,15,15
15,15,15,15,15,15,15,15,10,15,15,15,15
15,15,15,15,15,15,15,15,15,15,15,15,15
15,15,15,15,15,15,15,15,15,15,15,15,15
15,15,15,15,15,15,15,15,15,15,15,15,15
15,15,15,15,15,15,15,15,15,15,15,15,15
15,15,15,15,15,15,15,15,15,15,15,15,15
15,15,15,15,15,15,15,15,15,15,15,15,15
endlayer

layer
15,15,15,15,15,15,15,15,15,15,15,15,15
15,15,15,15,15,15,15,15,15,15,15,15,15
15,15,15,15,15,15,15,15,15,15,15,15,15
15,15,15,15,15,15,15,15,15,15,15,15,15
15,15,15,15,15,15,15,15,8,15,15,15,15
15,15,15,15,15,15,15,15,5,9,15,15,15
15,15,15,15,15,15,15,15,10,15,15,15,15
15,15,15,15,15,15,15,15,15,15,15,15,15
15,15,15,15,15,15,15,15,15,15,15,15,15
15,15,15,15,15,15,15,15,15,15,15,15,15
15,15,15,15,15,15,15,15,15,15,15,15,15
15,15,15,15,15,15,15,15,15,15,15,15,15
15,15,15,15,15,15,15,15,15,15,15,15,15
endlayer

layer
15,15,15,15,15,15,15,15,15,15,15,15,15
15,15,15,15,15,15,15,15,15,15,15,15,15
15,15,15,15,15,15,15,15,15,15,15,15,15
15,15,15,15,15,15,15,15,15,15,15,15,15
15,15,15,15,15,15,15,15,8,15,15,15,15
15,15,15,15,15,15,15,11,5,9,15,15,15
15,15,15,15,15,15,15,15,10,15,15,15,15
15,15,15,15,15,15,15,15,15,15,15,15,15
15,15,15,15,15,15,15,15,15,15,15,15,15
15,15,15,15,15,15,15,15,15,15,15,15,15
15,15,15,15,15,15,15,15,15,15,15,15,15
15,15,15,15,15,15,15,15,15,15,15,15,15
15,15,15,15,15,15,15,15,15,15,15,15,15
endlayer

layer
15,15,15,15,15,15,15,15,15,15,15,15,15
15,15,15,15,15,15,15,15,15,15,15,15,15
15,15,15,15,15,15,15,15,15,15,15,15,15
15,15,15,15,15,15,15,15,15,15,15,15,15
15,15,15,15,15,15,15,15,8,15,15,15,15
15,15,15,15,15,15,15,11,5,9,15,15,15
15,15,15,15,15,15,15,15,10,15,15,15,15
15,15,15,15,15,15,15,15,15,15,15,15,15
15,15,15,15,15,15,15,15,15,15,15,15,15
15,15,15,15,15,15,15,15,15,15,15,15,15
15,15,15,15,15,15,15,15,15,15,15,15,15
15,15,15,15,15,15,15,15,15,15,15,15,15
15,15,15,15,15,15,15,15,15,15,15,15,15
endlayer

layer
15,15,15,15,15,15,15,15,15,15,15,15,15
15,15,15,15,15,15,15,15,15,15,15,15,15
15,15,15,15,15,15,15,15,15,15,15,15,15
15,15,15,15,15,15,15,15,15,15,15,15,15
15,15,15,15,15,15,15,15,8,15,15,15,15
15,15,15,15,15,15,15,11,5,9,15,15,15
15,15,15,15,15,15,15,15,10,15,15,15,15
15,15,15,15,15,15,15,15,15,15,15,15,15
15,15,15,15,15,15,15,15,15,15,15,15,15
15,15,15,15,15,15,15,15,15,15,15,15,15
15,15,15,15,15,15,15,15,15,15,15,15,15
15,15,15,15,15,15,15,15,15,15,15,15,15
15,15,15,15,15,15,15,15,15,15,15,15,15
endlayer

layer
15,15,15,15,15,15,15,15,15,15,15,15,15
15,15,15,15,15,15,15,15,15,15,15,15,15
15,15,15,15,15,15,15,15,15,15,15,15,15
15,15,15,15,15,15,15,15,15,15,15,15,15
15,15,15,15,15,15,15,15,8,15,15,15,15
15,15,15,15,15,15,15,11,5,9,15,15,15
15,15,15,15,15,15,15,15,10,15,15,15,15
15,15,15,15,15,15,15,15,15,15,15,15,15
15,15,15,15,15,15,15,15,15,15,15,15,15
15,15,15,15,15,15,15,15,15,15,15,15,15
15,15,15,15,15,15,15,15,15,15,15,15,15
15,15,15,15,15,15,15,15,15,15,15,15,15
15,15,15,15,15,15,15,15,15,15,15,15,15
endlayer

layer
15,15,15,15,15,15,15,15,15,15,15,15,15
15,15,15,15,15,15,15,15,15,15,15,15,15
15,15,15,15,15,15,15,15,15,15,15,15,15
15,15,15,15,15,15,15,15,15,15,15,15,15
15,15,15,15,15,15,15,15,8,15,15,15,15
15,15,15,15,15,15,15,11,5,9,15,15,15
15,15,15,15,15,15,15,15,10,15,15,15,15
15,15,15,15,15,15,15,15,15,15,15,15,15
15,15,15,15,15,15,15,15,15,15,15,15,15
15,15,15,15,15,15,15,15,15,15,15,15,15
15,15,15,15,15,15,15,15,15,15,15,15,15
15,15,15,15,15,15,15,15,15,15,15,15,15
15,15,15,15,15,15,15,15,15,15,15,15,15
endlayer

layer
15,15,15,15,15,15,15,15,15,15,15,15,15
15,15,15,15,15,15,15,15,15,15,15,15,15
15,15,15,15,15,15,15,15,15,15,15,15,15
15,15,15,15,15,15,15,15,15,15,15,15,15
15,15,15,15,15,15,15,15,8,15,15,15,15
15,15,15,15,15,15,15,11,5,9,15,15,15
15,15,15,15,15,15,15,15,10,15,15,15,15
15,15,15,15,15,15,15,15,15,15,15,15,15
15,15,15,15,15,15,15,15,15,15,15,15,15
15,15,15,15,15,15,15,15,15,15,15,15,15
15,15,15,15,15,15,15,15,15,15,15,15,15
15,15,15,15,15,15,15,15,15,10,15,15,15
15,15,15,15,15,15,15,15,15,15,15,15,15
endlayer

layer
15,15,15,15,15,15,15,15,15,15,15,15,15
15,15,15,15,15,15,15,15,15,15,15,15,15
15,15,15,15,15,15,15,15,15,15,15,15,15
15,15,15,15,15,15,15,15,15,15,15,15,15
15,15,15,15,15,15,15,15,8,15,15,15,15
15,15,15,15,15,15,15,11,5,9,15,15,15
15,15,15,15,15,15,15,15,10,15,15,15,15
15,15,15,15,15,15,15,15,15,15,15,15,15
15,15,15,15,15,15,15,15,10,15,15,15,15
15,15,15,15,15,15,15,15,15,15,15,15,15
15,15,15,15,15,15,15,15,15,15,15,10,15
15,15,15,15,15,15,15,10,15,10,10,15,15
15,15,15,15,15,15,15,15,15,15,15,15,15
endlayer

layer
15,15,15,15,15,15,15,15,15,15,15,8,15
15,15,15,15,15,15,15,15,15,15,15,15,15
15,15,15,15,15,15,15,15,15,15,15,15,15
15,15,15,15,15,15,15,15,15,15,15,15,15
15,15,11,15,15,15,15,15,8,15,15,15,15
15,15,15,15,15,15,15,11,5,9,15,15,15
15,15,15,15,15,15,15,15,10,15,15,15,15
15,15,11,15,15,15,15,15,15,15,15,15,15
15,15,15,15,15,15,15,15,10,15,15,15,15
15,15,15,15,11,15,15,15,15,15,15,15,15
15,15,15,15,15,15,15,15,15,15,15,10,15
15,15,15,15,15,15,15,10,10,10,10,15,15
15,15,15,15,15,15,15,15,15,15,15,15,15
endlayer

layer
15,15,15,15,15,15,15,15,15,15,15,8,15
15,15,15,15,15,15,15,15,15,15,15,15,15
15,15,15,11,15,15,15,15,15,15,15,15,15
15,15,15,15,15,15,15,15,15,15,15,15,15
15,15,11,15,15,15,15,15,8,15,15,15,15
15,15,15,15,15,15,15,15,5,9,15,15,15
15,15,11,15,15,15,15,15,10,15,15,15,15
15,15,11,15,15,15,15,15,15,15,15,15,15
15,15,15,15,15,15,15,15,10,15,15,15,15
15,15,15,15,11,15,15,15,15,15,15,15,10
15,15,15,15,15,15,15,15,15,15,15,10,15
15,15,15,15,15,15,15,10,10,10,10,15,15
15,15,15,15,15,15,15,15,15,15,15,15,15
endlayer

layer
15,15,15,15,15,8,15,15,15,15,15,8,15
15,15,15,15,15,15,15,15,15,15,15,15,15
15,15,15,11,15,15,15,15,15,15,15,15,15
15,15,15,15,15,15,15,15,15,15,15,15,15
15,15,11,15,15,15,15,15,8,12,15,15,15
15,15,15,15,15,15,15,15,5,9,15,15,15
15,15,11,15,15,15,15,15,10,15,15,15,15
15,15,11,15,15,15,15,15,15,15,15,15,15
15,15,15,15,15,15,15,15,10,15,15,15,15
15,15,15,15,11,15,15,15,15,15,15,15,10
15,15,15,15,15,10,15,15,15,15,15,10,15
15,15,15,15,15,15,15,10,10,10,10,15,15
15,15,15,15,15,15,15,15,15,15,15,15,15
endlayer

layer
15,15,15,15,15,8,15,15,15,15,15,8,15
15,15,15,15,15,15,15,15,15,15,15,15,15
15,15,15,11,15,15,15,15,15,15,15,15,15
15,15,11,15,15,15,15,13,13,13,15,15,15
15,15,11,15,15,15,14,14,14,14,14,15,15
15,15,15,15,15,15,14,14,5,14,14,15,15
15,15,11,15,15,15,14,14,14,14,14,15,15
15,15,11,15,15,15,15,14,14,14,15,15,15
15,15,15,15,15,15,15,15,10,15,15,15,15
15,15,15,15,11,15,15,15,15,15,15,15,10
15,15,15,15,15,10,15,15,15,15,15,10,15
15,15,15,15,15,15,10,10,10,10,10,15,15
15,15,15,15,15,15,15,15,15,15,15,15,15
endlayer

layer
15,15,15,15,15,8,13,13,13,13,13,8,15
15,15,15,15,8,13,13,13,13,14,13,13,9
15,15,15,11,13,13,13,13,13,14,14,14,13
15,15,11,13,13,13,13,13,13,14,14,14,13
15,15,11,13,13,13,13,13,13,14,14,14,13
15,15,11,13,14,14,14,14,5,14,14,14,14
15,15,11,13,14,14,14,14,14,14,14,14,14
15,15,11,13,14,14,14,14,14,14,14,14,14
15,15,15,10,14,14,14,14,14,14,14,14,14
15,15,15,15,11,14,14,14,14,14,14,14,10
15,15,15,15,15,10,14,14,14,14,14,10,15
15,15,15,15,15,15,10,10,10,10,10,15,15
15,15,15,15,15,15,15,15,15,15,15,15,15
endlayer

layer
15,15,15,15,15,15,15,15,15,15,15,15,15
15,15,15,15,15,15,15,15,13,15,15,15,15
15,15,15,15,15,15,15,15,13,15,15,15,15
15,15,15,15,15,15,15,13,13,14,15,15,15
15,15,15,15,15,15,13,13,13,14,14,15,15
15,15,15,15,13,13,13,13,13,13,13,13,13
15,15,15,15,15,15,13,13,13,13,13,15,15
15,15,15,15,15,15,15,13,13,13,15,15,15
15,15,15,15,15,15,15,15,13,15,15,15,15
15,15,15,15,15,15,15,15,13,15,15,15,15
15,15,15,15,15,15,15,15,15,15,15,15,15
15,15,15,15,15,15,15,15,15,15,15,15,15
15,15,15,15,15,15,15,15,15,15,15,15,15
endlayer

layer
15,15,15,15,15,15,15,15,15,15,15,15,15
15,15,15,15,15,15,15,15,15,15,15,15,15
15,15,15,15,15,15,15,15,15,15,15,15,15
15,15,15,15,15,15,15,15,13,15,15,15,15
15,15,15,15,15,15,15,15,13,15,15,15,15
15,15,15,15,15,15,13,13,13,13,13,15,15
15,15,15,15,15,15,15,15,13,15,15,15,15
15,15,15,15,15,15,15,15,13,15,15,15,15
15,15,15,15,15,15,15,15,15,15,15,15,15
15,15,15,15,15,15,15,15,15,15,15,15,15
15,15,15,15,15,15,15,15,15,15,15,15,15
15,15,15,15,15,15,15,15,15,15,15,15,15
15,15,15,15,15,15,15,15,15,15,15,15,15
endlayer

layer
15,15,15,15,15,15,15,15,15,15,15,15,15
15,15,15,15,15,15,15,15,15,15,15,15,15
15,15,15,15,15,15,15,15,15,15,15,15,15
15,15,15,15,15,15,15,15,15,15,15,15,15
15,15,15,15,15,15,15,15,13,15,15,15,15
15,15,15,15,15,15,15,13,13,13,15,15,15
15,15,15,15,15,15,15,15,13,15,15,15,15
15,15,15,15,15,15,15,15,15,15,15,15,15
15,15,15,15,15,15,15,15,15,15,15,15,15
15,15,15,15,15,15,15,15,15,15,15,15,15
15,15,15,15,15,15,15,15,15,15,15,15,15
15,15,15,15,15,15,15,15,15,15,15,15,15
15,15,15,15,15,15,15,15,15,15,15,15,15
endlayer

