# 坠毁飞船的生成文件
# 特点是破损的小飞船上覆盖苔石、树叶、沙砾和浮冰，有四个地牢箱子和一个僵尸刷怪笼
# 在水星的水面生成

weight=1
embed_into_distance=4
acceptable_target_blocks=water
unacceptable_target_blocks=
dimensions=5,16,12
allowable_overhang=0
max_leveling=0
leveling_buffer=0
preserve_water=0
preserve_lava=0
biomesToSpawnIn=<plains>

rule1=0,100,minecraft:mossy_cobblestone-0
rule2=0,100,chisel:factory-8
rule3=0,100,chisel:futura-1
rule4=0,100,minecraft:leaves-7
rule5=0,100,chisel:factory-4
rule6=0,100,chisel:factory-6
rule7=0,100,chisel:technical-14
rule8=0,100,minecraft:packed_ice-0
rule9=0,100,appliedenergistics2:energy_cell-0
rule10=0,100,ChestGenHook:chests/simple_dungeon:5-5
rule11=0,100,minecraft:sand-0
rule12=0,100,MobSpawner:Zombie
rule13=0,100,ChestGenHook:chests/simple_dungeon:5-4
rule14=0,100,extrautils2:decorativeglass-3
rule15=0,100,minecraft:preserveBlock

layer
15,15,15,15,3,2,1,1,15,15,15,15
15,15,15,15,3,3,3,3,3,15,15,15
15,15,15,15,3,2,2,2,3,15,15,15
15,15,15,15,15,15,15,15,15,15,15,15
15,15,15,2,2,2,2,2,2,2,4,15
15,15,2,5,5,5,5,5,5,2,2,2
15,6,5,5,5,5,5,5,5,5,5,2
15,6,5,5,5,5,5,5,5,5,5,2
15,15,2,5,5,5,5,5,5,2,2,2
15,4,4,2,2,2,2,2,2,2,15,15
15,15,15,15,15,4,15,15,4,15,15,15
15,15,15,15,3,2,2,2,3,15,15,15
15,15,15,15,3,3,3,3,3,15,15,15
15,15,15,15,3,2,2,2,3,15,15,15
15,15,15,15,15,15,15,15,15,15,15,15
15,15,15,15,15,15,15,15,15,15,15,15
endlayer

layer
15,15,15,15,3,3,15,3,15,15,15,15
15,15,15,15,7,15,15,15,15,15,15,15
15,15,15,15,3,3,3,3,3,15,15,15
15,15,15,15,15,3,15,3,15,15,15,15
15,15,15,5,2,2,2,2,2,8,4,15
15,6,6,6,11,11,11,10,10,2,9,2
15,7,11,11,11,15,15,15,15,15,15,15
15,11,12,11,11,15,15,15,15,15,15,15
15,6,6,6,11,11,11,13,13,2,9,2
15,8,8,5,2,2,2,2,2,4,15,15
15,15,15,15,4,3,15,3,1,15,15,15
15,15,15,15,3,3,3,3,3,15,15,15
15,15,15,15,15,15,15,15,4,15,15,15
15,15,15,15,3,3,3,3,3,15,15,15
15,15,15,15,15,15,15,15,15,15,15,15
15,15,15,15,15,15,15,15,15,15,15,15
endlayer

layer
15,15,15,15,15,1,15,2,3,15,15,15
15,15,15,15,3,3,3,3,3,15,15,15
15,15,15,15,8,2,2,2,3,15,15,15
15,15,15,15,15,1,1,1,15,15,15,15
15,15,15,11,5,2,2,2,2,8,4,15
15,6,6,6,11,15,11,11,11,2,2,2
15,1,15,15,15,15,15,15,15,15,15,14
15,1,15,15,15,15,15,15,15,15,15,14
15,6,6,6,15,15,15,15,15,2,2,2
15,8,8,4,5,2,2,2,2,1,4,15
15,15,15,15,4,4,1,1,1,15,15,15
15,15,15,15,11,2,2,2,3,15,15,15
15,15,15,15,3,3,3,3,3,15,15,15
15,15,15,15,15,15,2,4,15,15,15,15
15,15,15,15,15,15,15,15,15,15,15,15
15,15,15,15,15,15,15,15,15,15,15,15
endlayer

layer
15,15,15,15,15,15,15,15,15,15,15,15
15,15,15,15,1,8,8,8,15,15,15,15
15,15,15,15,8,8,11,11,15,15,15,15
15,15,15,15,15,11,1,1,15,15,15,15
15,15,15,11,11,1,1,1,1,15,15,15
15,11,11,5,5,5,5,5,2,2,4,15
15,6,2,2,2,2,2,2,2,2,2,4
15,6,2,2,2,2,2,2,2,2,2,15
15,11,11,5,5,5,5,5,2,2,4,15
15,15,8,11,4,1,1,1,1,1,15,15
15,15,15,15,11,1,1,1,11,15,15,15
15,15,15,15,8,11,4,11,8,15,15,15
15,15,15,15,15,8,8,4,8,15,15,15
15,15,15,15,15,15,15,15,15,15,15,15
15,15,15,15,15,15,15,15,15,15,15,15
15,15,15,15,15,15,15,15,15,15,15,15
endlayer

layer
15,15,15,15,15,15,15,15,15,15,15,15
15,15,15,15,15,15,15,15,15,15,15,15
15,15,15,15,15,15,15,15,15,15,15,15
15,15,15,15,15,15,15,15,15,15,15,15
15,15,15,15,15,15,15,15,15,15,15,15
15,15,15,15,15,15,15,15,15,8,4,15
15,15,15,15,15,15,15,8,8,4,15,15
15,15,15,15,15,15,15,4,4,15,15,15
15,15,15,15,15,4,4,15,15,15,15,15
15,15,15,15,15,15,15,15,15,15,15,15
15,15,15,15,15,15,15,15,15,15,15,15
15,15,15,15,15,15,15,15,15,15,15,15
15,15,15,15,15,15,15,15,15,15,15,15
15,15,15,15,15,15,15,15,15,15,15,15
15,15,15,15,15,15,15,15,15,15,15,15
15,15,15,15,15,15,15,15,15,15,15,15
endlayer

