# 太阳遗迹的生成文件
# 特点是由神庙苔石建成且附有砂砾，具有守卫者刷怪笼和杀死所有玩家的命令方块、被太阳液体吞没和附带机器方块和机器框架的工程压印模具宝箱
# 在水星的水底生成

weight=1
embed_into_distance=66
acceptable_target_blocks=water
unacceptable_target_blocks=
dimensions=11,19,19
allowable_overhang=0
max_leveling=0
leveling_buffer=0
preserve_water=0
preserve_lava=0
biomesToSpawnIn=<plains>

rule1=0,100,minecraft:gravel-0
rule2=0,100,chisel:templemossy-1
rule3=0,100,tconstruct:clear_stained_glass-4
rule4=0,100,chisel:templemossy-10
rule5=0,100,chisel:templemossy-9
rule6=0,100,chisel:templemossy-2
rule7=0,100,chisel:templemossy-5
rule8=0,100,minecraft:stone_slab-8
rule9=0,100,minecraft:stone_slab-0
rule10=0,100,MobSpawner:minecraft:guardian
rule11=0,100,enderio:block_fluid_liquid_sunshine-0
rule12=0,100,minecraft:sea_lantern-0
rule13=0,100,CommandBlock: /kill @a
rule14=0,100,IInventory;minecraft:trapped_chest;thermalexpansion:frame#1#0#0+extrautils2:machine#1#0#1+extrautils2:machine#1#0#7+thermalexpansion:frame#1#0#8+extrautils2:machine#1#0#9+appliedenergistics2:material#1#14#13+extrautils2:machine#1#0#17+thermalexpansion:frame#1#0#18+extrautils2:machine#1#0#19+extrautils2:machine#1#0#25+thermalexpansion:frame#1#0#26-4
rule15=0,100,chisel:templemossy-0
rule16=0,100,minecraft:water-0

layer
1,1,1,2,3,3,3,1,1,1,1,1,3,3,3,2,1,1,1
1,4,5,4,4,6,6,6,6,6,6,6,6,6,4,4,5,4,1
1,5,6,6,6,6,6,5,5,5,5,5,7,7,7,7,7,5,1
2,4,6,4,4,4,6,5,4,4,4,5,7,4,4,4,7,4,2
3,4,6,4,4,4,6,5,4,4,4,5,7,4,4,4,7,4,3
3,6,6,4,4,4,6,5,4,4,4,5,7,4,4,4,7,6,3
3,6,6,6,6,6,6,5,5,5,5,5,7,7,7,7,7,6,3
1,6,4,4,4,4,4,6,6,6,6,6,7,7,7,7,7,6,1
1,6,4,5,5,5,4,6,5,5,5,6,7,5,5,5,7,6,1
1,6,4,5,5,5,4,6,5,13,5,6,7,5,5,5,7,6,1
1,6,4,5,5,5,4,6,5,5,5,6,7,5,5,5,7,6,1
3,6,4,4,4,4,4,6,6,6,6,6,7,7,7,7,7,6,1
3,6,4,4,4,4,4,5,5,5,5,5,6,6,6,6,6,6,1
3,6,4,7,7,7,4,5,7,7,7,5,6,7,7,7,6,6,3
3,4,4,7,7,7,4,5,7,7,7,5,6,7,7,7,6,4,3
2,4,4,7,7,7,4,5,7,7,7,5,6,7,7,7,6,4,3
1,5,4,4,4,4,4,5,5,5,5,5,6,6,6,6,6,5,2
1,4,5,4,4,6,6,6,6,6,6,6,6,6,4,4,5,4,1
1,1,1,2,3,3,3,1,1,1,1,1,1,3,3,3,2,1,1
endlayer

layer
1,1,1,2,3,3,1,1,1,1,1,1,1,3,3,2,1,1,1
1,4,5,4,6,7,7,7,8,9,8,7,7,7,6,4,5,4,1
1,5,10,5,11,11,11,8,9,11,9,8,0,0,0,5,10,5,1
2,4,5,6,6,11,11,11,11,11,11,11,11,11,6,6,5,4,2
3,6,11,6,12,5,5,5,2,2,2,5,5,5,12,6,11,6,3
3,7,11,11,5,11,11,11,11,11,11,11,11,11,5,11,11,7,3
1,7,11,11,5,11,11,11,11,11,11,11,11,11,5,11,11,7,1
1,7,8,11,5,11,11,5,11,11,11,5,11,11,5,11,8,7,1
1,8,9,11,2,11,11,11,11,11,11,11,11,11,2,11,9,8,1
1,9,11,11,2,11,11,11,11,5,11,11,11,11,2,11,11,9,1
1,8,9,11,2,11,11,11,11,11,11,11,11,11,2,11,9,8,1
1,7,8,11,5,11,11,5,11,11,11,5,11,11,5,11,8,7,1
3,7,0,11,5,11,11,11,11,11,11,11,11,11,5,11,11,7,1
3,7,11,11,5,11,11,11,11,11,11,11,11,11,5,11,11,7,1
3,6,11,6,12,5,5,5,2,2,2,5,5,5,12,6,11,6,3
2,4,5,6,6,11,11,11,11,11,11,11,11,11,6,6,5,4,3
1,5,10,5,11,11,11,8,9,11,9,8,11,11,11,5,10,5,2
1,4,5,4,6,7,7,7,8,9,8,7,7,7,6,4,5,4,1
1,1,1,2,3,3,1,1,1,1,1,1,1,1,3,3,2,1,1
endlayer

layer
1,1,1,2,3,1,1,1,1,1,1,1,1,1,3,2,1,1,1
1,4,5,6,6,6,7,7,8,8,8,7,7,6,6,6,5,4,1
1,5,4,5,11,8,9,11,11,11,11,11,9,8,0,5,4,5,1
2,6,5,4,11,11,11,11,11,11,11,11,11,11,0,4,5,6,2
3,6,11,11,11,5,7,7,7,2,7,7,7,5,11,11,11,6,3
1,6,8,11,5,11,11,11,11,11,11,11,11,11,5,11,8,6,1
1,7,9,11,7,11,11,11,11,11,11,11,11,11,7,11,9,7,1
1,7,11,11,7,11,11,5,11,11,11,5,11,11,7,11,11,7,1
1,8,11,11,7,11,11,11,11,11,11,11,11,11,7,11,11,8,1
1,8,11,11,2,11,11,11,11,14,11,11,11,11,2,11,11,8,1
1,8,0,11,7,11,11,11,11,11,11,11,11,11,7,11,11,8,1
1,7,0,11,7,11,11,5,11,11,11,5,11,11,7,11,11,7,1
1,7,9,11,7,11,11,11,11,11,11,11,11,11,7,11,9,7,1
3,6,8,11,5,11,11,11,11,11,11,11,11,11,5,11,8,6,1
3,6,11,11,11,5,7,7,7,2,7,7,7,5,11,11,11,6,1
2,6,5,4,11,11,11,11,11,11,11,11,11,11,11,4,5,6,3
1,5,4,5,11,8,9,11,11,11,11,11,9,8,11,5,4,5,2
1,4,5,6,6,6,7,7,8,8,8,7,7,6,6,6,5,4,1
1,1,1,2,3,1,1,1,1,1,1,1,1,1,1,3,2,1,1
endlayer

layer
1,1,1,2,1,1,1,1,1,1,1,1,1,1,1,2,1,1,1
1,6,5,6,6,6,6,7,15,6,15,7,6,6,6,6,5,6,1
1,5,4,11,9,11,11,11,11,11,11,11,11,11,9,11,4,5,1
2,6,11,4,8,11,11,11,11,11,11,11,11,11,8,4,11,6,2
1,6,9,8,11,5,7,7,7,2,7,7,7,5,0,8,9,6,1
1,6,11,11,5,11,11,11,11,11,11,11,11,11,5,11,11,6,1
1,6,11,11,7,11,11,11,11,11,11,11,11,11,7,11,11,6,1
1,7,11,11,7,11,11,5,8,15,8,5,11,11,7,11,11,7,1
1,15,11,11,7,11,11,8,11,11,11,8,11,11,7,11,11,15,1
1,6,11,11,2,11,11,15,11,11,11,15,11,11,2,11,11,8,1
1,15,11,11,7,11,11,8,11,11,11,8,11,11,7,11,11,15,1
1,7,11,11,7,11,11,5,8,15,8,5,11,11,7,11,11,7,1
1,6,11,11,7,11,11,11,11,11,11,11,11,11,7,11,11,6,1
1,6,11,11,5,11,11,11,11,11,11,11,11,11,5,11,11,6,1
3,6,9,8,11,5,7,7,7,2,7,7,7,5,11,8,9,6,1
2,6,11,4,8,11,11,11,11,11,11,11,11,11,8,4,11,6,1
1,5,4,11,9,11,11,11,11,11,11,11,11,11,9,11,4,5,2
1,6,5,6,6,6,6,7,15,6,15,7,6,6,6,6,5,6,1
1,1,1,2,1,1,1,1,1,1,1,1,1,1,1,1,2,1,1
endlayer

layer
1,1,1,1,1,1,1,1,1,1,1,1,1,1,1,1,1,1,1
1,1,1,15,15,15,15,15,15,15,15,15,15,15,15,15,1,1,1
1,1,4,11,11,11,11,11,11,11,11,11,11,11,11,11,4,1,1
1,15,11,4,11,11,11,11,11,11,11,11,11,11,11,4,11,15,2
1,15,11,11,9,5,4,4,2,2,2,4,4,5,9,11,11,15,1
1,15,11,11,5,15,3,3,3,3,3,3,3,15,5,11,11,15,1
1,15,11,11,4,3,11,11,11,11,11,11,11,3,4,11,11,15,1
1,15,11,11,4,3,11,11,11,11,11,11,11,3,4,11,11,15,1
1,15,11,11,2,3,11,11,9,7,9,11,11,3,2,11,11,15,1
1,15,11,11,2,3,11,11,7,15,7,11,11,3,2,11,11,15,1
1,15,11,11,2,3,11,11,9,7,9,11,11,3,2,11,11,15,1
1,15,11,11,4,3,11,11,11,11,11,11,11,3,4,11,11,15,1
1,15,11,11,4,3,11,11,11,11,11,11,11,3,4,11,11,15,1
1,15,11,11,5,15,3,3,3,3,3,3,3,15,5,11,11,15,1
1,15,11,11,9,5,4,4,2,2,2,4,4,5,9,11,11,15,1
2,15,11,4,11,11,11,11,11,11,11,11,11,11,11,5,11,15,1
1,1,4,11,11,11,11,11,11,11,11,11,11,11,11,11,4,1,1
1,1,1,15,15,15,15,15,15,15,15,15,15,15,15,15,1,1,1
1,1,1,2,1,1,1,1,1,1,1,1,1,1,1,1,1,1,1
endlayer

layer
1,1,1,1,1,1,1,1,1,1,1,1,1,1,1,1,1,1,1
1,1,1,1,3,3,1,1,1,1,1,1,1,3,3,1,1,1,1
1,1,4,6,0,8,6,6,6,6,6,6,6,8,0,6,4,1,1
1,1,6,4,0,0,0,0,0,0,0,0,0,0,0,4,6,1,1
1,3,0,0,0,0,5,15,15,15,15,15,5,0,0,0,0,3,1
1,3,8,0,0,5,0,0,0,0,0,0,0,5,0,0,8,3,1
1,1,6,0,5,0,0,0,0,0,0,0,0,0,5,0,6,1,1
1,1,6,0,15,0,0,0,0,0,0,0,0,0,15,0,6,1,1
1,1,6,0,15,0,0,0,0,0,0,0,0,0,15,0,6,1,1
1,1,6,0,15,0,0,0,0,0,0,0,0,0,15,0,6,1,1
1,1,6,0,15,0,0,0,0,0,0,0,0,0,15,0,6,1,1
1,1,6,0,15,0,0,0,0,0,0,0,0,0,15,0,6,1,1
1,1,6,0,5,0,0,0,0,0,0,0,0,0,5,0,6,1,1
1,3,9,0,0,5,0,0,0,0,0,0,0,0,0,0,8,3,1
1,3,0,0,0,0,5,15,15,15,15,15,5,0,0,0,0,3,1
1,1,6,4,0,0,0,0,0,0,0,0,0,0,0,4,6,1,1
1,1,4,6,0,8,6,6,6,6,6,6,6,8,0,6,4,1,1
1,1,1,1,3,3,1,1,1,1,1,1,1,3,3,1,1,1,1
1,1,1,1,1,1,1,1,1,1,1,1,1,1,1,1,1,1,1
endlayer

layer
16,16,16,16,16,16,16,16,16,16,16,16,16,16,16,16,16,16,16
16,16,16,16,16,16,16,1,16,16,16,1,1,1,16,16,16,16,16
16,16,16,16,7,7,3,3,3,3,3,3,3,7,7,16,16,16,16
16,16,16,4,0,0,0,0,0,0,0,0,0,0,0,4,16,16,16
16,16,7,0,0,0,5,2,2,2,2,2,5,0,0,0,7,16,16
16,16,7,0,0,5,0,0,0,0,0,0,0,5,0,0,7,16,16
16,16,3,0,5,0,0,0,0,0,0,0,0,0,5,0,3,16,16
16,16,3,0,2,0,0,0,0,0,0,0,0,0,2,0,3,16,16
16,16,3,0,2,0,0,0,0,0,0,0,0,0,2,0,3,1,16
16,16,3,0,2,0,0,0,0,0,0,0,0,0,2,0,3,16,16
16,16,3,0,2,0,0,0,0,0,0,0,0,0,2,0,3,16,16
16,16,3,0,2,0,0,0,0,0,0,0,0,0,2,0,3,16,16
16,16,3,0,5,0,0,0,0,0,0,0,0,0,5,0,3,16,16
16,16,7,0,0,5,0,0,0,0,0,0,0,0,0,0,7,16,16
16,16,7,0,0,0,5,2,2,2,2,2,5,0,0,0,7,16,16
16,16,16,4,0,0,0,0,0,0,0,0,0,0,0,4,16,16,16
16,16,16,16,7,7,3,3,3,3,3,3,3,7,7,16,16,16,16
16,16,16,16,16,16,16,1,1,1,1,1,1,0,1,16,16,16,16
16,16,16,16,16,16,16,16,16,16,16,16,16,16,16,16,16,16,16
endlayer

layer
16,16,16,16,16,16,16,16,16,16,16,16,16,16,16,16,16,16,16
16,16,16,16,16,16,16,16,16,16,16,16,16,16,16,16,16,16,16
16,16,16,16,16,16,16,1,16,16,1,1,1,1,16,16,16,16,16
16,16,16,4,15,15,15,15,15,15,15,15,15,15,15,4,16,16,16
16,16,16,15,0,0,5,6,6,6,6,6,5,0,0,15,16,16,16
16,16,16,15,0,0,5,8,8,8,8,8,5,0,0,15,16,16,16
16,16,16,15,5,5,5,0,0,0,0,0,5,5,5,15,1,16,16
16,16,16,15,6,8,0,0,0,0,0,0,0,8,6,15,1,16,16
16,16,16,15,6,8,0,0,0,0,0,0,0,8,6,15,16,16,16
16,16,16,15,6,8,0,0,0,0,0,0,0,8,6,15,16,16,16
16,16,16,15,6,8,0,0,0,0,0,0,0,8,6,15,16,16,16
16,16,16,15,6,8,0,0,0,0,0,0,0,8,6,15,16,16,16
16,16,16,15,5,5,5,0,0,0,0,0,5,5,5,15,16,16,16
16,16,16,15,0,0,5,8,8,8,8,8,5,0,0,15,16,16,16
16,16,16,15,0,0,5,6,6,6,6,6,5,0,0,15,16,16,16
16,16,16,4,15,15,15,15,15,15,15,15,15,15,15,4,16,16,16
16,16,16,16,16,16,16,1,1,1,1,1,16,16,1,16,16,16,16
16,16,16,16,16,16,16,16,16,16,16,16,16,16,16,16,16,16,16
16,16,16,16,16,16,16,16,16,16,16,16,16,16,16,16,16,16,16
endlayer

layer
16,16,16,16,16,16,16,16,16,16,16,16,16,16,16,16,16,16,16
16,16,16,16,16,16,16,16,16,16,16,16,16,16,16,16,16,16,16
16,16,16,16,16,16,16,16,16,16,16,1,16,16,16,16,16,16,16
16,16,16,16,5,5,16,1,16,1,16,16,16,5,5,16,16,16,16
16,16,16,5,12,12,5,1,16,16,16,16,5,12,12,5,16,16,16
16,16,16,5,12,12,5,1,1,16,16,16,5,12,12,5,16,16,16
16,16,16,16,5,5,7,7,7,7,7,7,7,5,5,1,16,16,16
16,16,16,16,16,16,7,0,0,4,0,0,7,16,1,16,16,16,16
16,16,16,16,16,16,7,0,0,0,0,0,7,16,16,1,16,16,16
16,16,16,16,16,16,7,4,0,0,0,4,7,16,16,16,16,16,16
16,16,16,16,16,16,7,0,0,0,0,0,7,16,16,16,16,16,16
16,16,16,16,16,16,7,0,0,4,0,0,7,16,1,16,16,16,16
16,16,16,16,5,5,7,7,7,7,7,7,7,5,5,16,16,16,16
16,16,16,5,12,12,5,16,16,16,16,16,5,12,12,5,16,16,16
16,16,16,5,12,12,5,1,16,16,16,16,5,12,12,5,16,16,16
16,16,16,16,5,5,1,16,16,16,16,16,16,5,5,1,16,16,16
16,16,16,16,16,16,16,1,1,1,16,16,16,16,16,16,16,16,16
16,16,16,16,16,16,16,16,16,16,16,16,16,16,16,16,16,16,16
16,16,16,16,16,16,16,16,16,16,16,16,16,16,16,16,16,16,16
endlayer

layer
16,16,16,16,16,16,16,16,16,16,16,16,16,16,16,16,16,16,16
16,16,16,16,16,16,16,16,16,16,16,16,16,16,16,16,16,16,16
16,16,16,16,16,16,16,16,16,16,16,16,16,16,16,16,16,16,16
16,16,16,16,16,16,16,16,16,16,16,16,16,16,16,16,16,16,16
16,16,16,16,2,2,16,16,16,16,16,16,1,2,2,1,16,16,16
16,16,16,16,2,2,16,16,16,16,16,16,16,2,2,16,16,16,16
16,16,16,16,16,16,1,16,16,16,16,1,16,16,16,16,16,16,16
16,16,16,16,16,16,16,2,2,15,2,2,16,16,16,16,16,16,16
16,16,16,16,16,16,1,2,0,0,0,2,16,16,16,16,16,16,16
16,16,16,16,16,16,1,15,4,0,4,15,16,16,16,16,16,16,16
16,16,16,16,16,16,16,2,0,0,0,2,16,16,16,16,16,16,16
16,16,16,16,16,16,16,2,2,15,2,2,16,16,16,16,16,16,16
16,16,16,16,16,16,16,1,16,16,16,16,16,16,1,16,16,16,16
16,16,16,16,2,2,16,16,16,16,16,16,16,2,2,16,16,16,16
16,16,16,16,2,2,16,16,16,16,16,16,16,2,2,1,16,16,16
16,16,16,16,16,1,16,16,16,16,16,16,16,16,16,16,16,16,16
16,16,16,16,16,16,16,16,16,16,16,16,16,16,16,16,16,16,16
16,16,16,16,16,16,16,16,16,16,16,16,16,16,16,16,16,16,16
16,16,16,16,16,16,16,16,16,16,16,16,16,16,16,16,16,16,16
endlayer

layer
16,16,16,16,16,16,16,16,16,16,16,16,16,16,16,16,16,16,16
16,16,16,16,16,16,16,16,16,16,16,16,16,16,16,16,16,16,16
16,16,16,16,16,16,16,16,16,16,16,16,16,16,16,16,16,16,16
16,16,16,16,16,16,16,16,16,16,16,16,16,16,16,16,16,16,16
16,16,16,16,16,16,16,16,16,16,16,16,16,16,16,16,16,16,16
16,16,16,16,16,16,16,16,16,16,16,16,16,16,16,16,16,16,16
16,16,16,16,16,16,16,16,16,16,16,16,16,16,16,16,16,16,16
16,16,16,16,16,16,16,16,16,16,16,16,16,16,16,16,16,16,16
16,16,16,16,16,16,16,16,7,7,4,16,16,16,16,16,16,16,16
16,16,16,16,16,16,16,16,16,4,16,16,16,16,16,16,16,16,16
16,16,16,16,16,16,16,1,4,4,4,16,16,16,16,16,16,16,16
16,16,16,16,16,16,16,16,16,16,16,16,16,16,16,16,16,16,16
16,16,16,16,16,16,16,16,16,16,16,16,16,16,16,16,16,16,16
16,16,16,16,16,16,16,16,16,16,16,16,16,16,1,16,16,16,16
16,16,16,16,16,1,16,16,16,16,16,16,16,16,16,16,16,16,16
16,16,16,16,16,16,16,16,16,16,16,16,16,16,16,16,16,16,16
16,16,16,16,16,16,16,16,16,16,16,16,16,16,16,16,16,16,16
16,16,16,16,16,16,16,16,16,16,16,16,16,16,16,16,16,16,16
16,16,16,16,16,16,16,16,16,16,16,16,16,16,16,16,16,16,16
endlayer

