# 试验站的生成文件
# 特点是由工厂方块、科技设备和两个地牢箱子组成
# 在水星的表面生成

weight=1
embed_into_distance=1
acceptable_target_blocks=water
unacceptable_target_blocks=
dimensions=7,17,19
allowable_overhang=0
max_leveling=0
leveling_buffer=0
preserve_water=0
preserve_lava=0
biomesToSpawnIn=<plains>

rule1=0,100,chisel:laboratory-11
rule2=0,100,chisel:factory-13
rule3=0,100,chisel:factory-5
rule4=0,100,chisel:factory-4
rule5=0,100,chisel:factory-11
rule6=0,100,chisel:factory-10
rule7=0,100,minecraft:stone_slab-7
rule8=0,100,chisel:factory-12
rule9=0,100,chisel:tyrian-11
rule10=0,100,IInventory;minecraft:chest;mekanism:Ingot#11#1#0+mekanism:Ingot#3#4#1-5
rule11=0,100,ChestGenHook:chests/simple_dungeon:5-5
rule12=0,100,minecraft:leaves-6
rule13=0,100,chisel:futura-4
rule14=0,100,ChestGenHook:chests/simple_dungeon:5-3
rule15=0,100,mekanism:machineblock-1
rule16=0,100,mekanism:machineblock-2
rule17=0,100,mekanismgenerators:generator-1
rule18=0,100,minecraft:preserveBlock

layer
18,18,18,18,18,18,18,1,2,2,1,18,18,18,18,18,18,18,18
18,18,18,18,18,1,2,5,5,4,3,2,1,18,18,18,18,18,18
18,18,18,18,1,3,3,4,4,4,3,5,5,1,18,18,18,18,18
18,18,18,1,5,5,3,4,4,4,3,3,4,5,1,18,18,18,18
18,18,18,2,5,4,4,4,3,4,4,4,4,4,2,18,18,18,18
18,18,1,3,3,3,4,3,3,3,4,4,4,4,5,1,18,18,18
18,18,2,3,4,4,4,4,4,3,4,3,3,3,5,2,18,18,18
18,18,2,3,4,4,3,3,3,3,4,4,4,3,3,2,18,18,18
18,18,1,3,5,5,4,3,5,5,4,3,4,3,6,1,18,18,18
18,18,18,2,3,5,4,3,4,4,4,3,4,4,2,18,18,18,18
18,18,18,1,3,3,4,3,4,4,4,3,3,4,1,18,18,18,18
18,18,18,18,1,3,3,3,5,5,3,3,3,1,18,18,18,18,18
18,18,18,18,18,1,2,3,3,4,5,2,1,18,18,18,18,18,18
18,18,18,18,18,18,18,1,2,2,1,18,18,18,18,18,18,18,18
18,18,18,18,18,18,18,18,18,18,18,18,18,18,18,18,18,18,18
18,18,18,18,18,18,18,18,18,18,18,18,18,18,18,18,18,18,18
18,18,18,18,18,18,18,18,18,18,18,18,18,18,18,18,18,18,18
endlayer

layer
18,18,18,18,18,18,18,18,18,18,18,18,18,18,18,18,18,18,18
18,18,18,18,18,18,7,8,18,18,8,7,18,18,18,18,18,18,18
18,18,18,18,18,18,8,9,18,18,9,8,7,18,18,18,18,18,18
18,18,18,18,18,18,12,12,18,18,11,10,18,18,18,18,18,18,18
18,18,18,7,8,12,18,18,18,18,18,18,18,8,7,18,18,18,18
18,18,18,8,9,12,18,18,18,18,18,18,18,9,8,18,18,18,18
18,18,18,18,18,18,18,18,13,13,18,18,18,18,7,18,18,18,18
18,18,18,18,18,18,18,18,14,13,18,18,18,18,18,18,18,18,18
18,18,18,8,9,18,18,18,18,18,18,18,18,9,8,18,18,18,18
18,18,18,7,8,18,18,18,18,18,18,18,18,8,7,18,18,18,18
18,18,18,18,18,18,18,18,18,18,16,15,18,18,18,18,18,18,18
18,18,18,18,18,7,8,9,18,18,9,8,18,18,18,18,18,18,18
18,18,18,18,18,18,7,8,18,18,8,7,18,18,18,18,18,18,18
18,18,18,18,18,18,18,18,18,18,18,18,18,18,18,18,18,18,18
18,18,18,18,18,18,18,18,18,18,18,18,18,18,18,18,18,18,18
18,18,18,18,18,18,18,18,18,18,18,18,18,18,18,18,18,18,18
18,18,18,18,18,18,18,18,18,18,18,18,18,18,18,18,18,18,18
endlayer

layer
18,18,18,18,18,18,18,18,18,18,18,18,18,18,18,18,18,18,18
18,18,18,18,18,18,18,7,18,18,18,18,18,18,18,18,18,18,18
18,18,18,18,18,18,18,9,18,18,9,18,18,18,18,18,18,18,18
18,18,18,18,18,18,18,17,18,18,18,18,18,18,18,18,18,18,18
18,18,18,18,18,18,18,18,18,18,18,18,18,18,18,18,18,18,18
18,18,18,7,9,18,18,18,18,18,18,18,18,9,7,18,18,18,18
18,18,18,18,18,18,18,18,13,13,18,18,18,18,18,18,18,18,18
18,18,18,18,18,18,18,18,18,13,18,18,18,18,18,18,18,18,18
18,18,18,18,9,18,18,18,18,18,18,18,18,9,18,18,18,18,18
18,18,18,18,7,18,18,18,18,18,18,18,18,7,18,18,18,18,18
18,18,18,18,18,18,18,18,18,18,12,12,18,18,18,18,18,18,18
18,18,18,18,18,18,18,9,18,18,9,18,18,18,18,18,18,18,18
18,18,18,18,18,18,18,7,18,18,7,18,18,18,18,18,18,18,18
18,18,18,18,18,18,18,18,18,18,18,18,18,18,18,18,18,18,18
18,18,18,18,18,18,18,18,18,18,18,18,18,18,18,18,18,18,18
18,18,18,18,18,18,18,18,18,18,18,18,18,18,18,18,18,18,18
18,18,18,18,18,18,18,18,18,18,18,18,18,18,18,18,18,18,18
endlayer

layer
18,18,18,18,18,18,18,18,18,18,18,18,18,18,18,18,18,18,18
18,18,18,18,18,18,18,18,18,18,18,18,18,18,18,18,18,18,18
18,18,18,18,18,18,18,9,18,18,9,18,18,18,18,18,18,18,18
18,18,18,18,18,18,18,18,18,18,18,18,18,18,18,18,18,18,18
18,18,18,18,18,18,18,18,18,18,18,18,18,18,18,18,18,18,18
18,18,18,18,9,18,18,18,18,18,18,18,18,9,18,18,18,18,18
18,18,18,18,18,18,18,18,18,13,18,18,18,18,18,18,18,18,18
18,18,18,18,18,18,18,18,18,13,18,18,18,18,18,18,18,18,18
18,18,18,18,9,18,18,18,18,18,18,18,18,9,18,18,18,18,18
18,18,18,18,18,18,18,18,18,18,18,18,18,18,18,18,18,18,18
18,18,18,18,18,18,18,18,18,18,18,18,18,18,18,18,18,18,18
18,18,18,18,18,18,18,9,18,18,9,18,18,18,18,18,18,18,18
18,18,18,18,18,18,18,18,18,18,18,18,18,18,18,18,18,18,18
18,18,18,18,18,18,18,18,18,18,18,18,18,18,18,18,18,18,18
18,18,18,18,18,18,18,18,18,18,18,18,18,18,18,18,18,18,18
18,18,18,18,18,18,18,18,18,18,18,18,18,18,18,18,18,18,18
18,18,18,18,18,18,18,18,18,18,18,18,18,18,18,18,18,18,18
endlayer

layer
18,18,18,18,18,18,18,18,18,18,18,18,18,18,18,18,18,18,18
18,18,18,18,18,18,18,18,18,18,18,18,18,18,18,18,18,18,18
18,18,18,18,18,18,18,9,18,18,7,18,18,18,18,18,18,18,18
18,18,18,18,18,18,18,18,18,18,18,18,18,18,18,18,18,18,18
18,18,18,18,18,18,18,18,18,18,18,18,18,18,18,18,18,18,18
18,18,18,18,18,18,18,18,18,18,18,18,18,18,18,18,18,18,18
18,18,18,18,18,18,18,18,18,13,18,18,18,18,18,18,18,18,18
18,18,18,18,18,18,18,18,18,18,18,18,18,18,18,18,18,18,18
18,18,18,18,9,18,18,18,18,18,18,18,18,9,18,18,18,18,18
18,18,18,18,18,18,18,18,18,18,18,18,18,18,18,18,18,18,18
18,18,18,18,18,18,18,18,18,18,18,18,18,18,18,18,18,18,18
18,18,18,18,18,18,18,7,18,18,9,18,18,18,18,18,18,18,18
18,18,18,18,18,18,18,18,18,18,18,18,18,18,18,18,18,18,18
18,18,18,18,18,18,18,18,18,18,18,18,18,18,18,18,18,18,18
18,18,18,18,18,18,18,18,18,18,18,18,18,18,18,18,18,18,18
18,18,18,18,18,18,18,18,18,18,18,18,18,18,18,18,18,18,18
18,18,18,18,18,18,18,18,18,18,18,18,18,18,18,18,18,18,18
endlayer

layer
18,18,18,18,18,18,18,18,18,18,18,18,18,18,18,18,18,18,18
18,18,18,18,18,18,18,18,18,18,18,18,18,18,18,18,18,18,18
18,18,18,18,18,18,18,9,18,18,18,18,18,18,18,18,18,18,18
18,18,18,18,18,18,18,18,18,18,18,18,18,18,18,18,18,18,18
18,18,18,18,18,18,18,18,18,18,18,18,18,18,18,18,18,18,18
18,18,18,18,18,18,18,18,18,18,18,18,18,18,18,18,18,18,18
18,18,18,18,18,18,18,18,18,18,18,18,18,18,18,18,18,18,18
18,18,18,18,18,18,18,18,18,18,18,18,18,18,18,18,18,18,18
18,18,18,18,7,18,18,18,18,18,18,18,18,18,18,18,18,18,18
18,18,18,18,18,18,18,18,18,18,18,18,18,18,18,18,18,18,18
18,18,18,18,18,18,18,18,18,18,18,18,18,18,18,18,18,18,18
18,18,18,18,18,18,18,18,18,18,9,18,18,18,18,18,18,18,18
18,18,18,18,18,18,18,18,18,18,18,18,18,18,18,18,18,18,18
18,18,18,18,18,18,18,18,18,18,18,18,18,18,18,18,18,18,18
18,18,18,18,18,18,18,18,18,18,18,18,18,18,18,18,18,18,18
18,18,18,18,18,18,18,18,18,18,18,18,18,18,18,18,18,18,18
18,18,18,18,18,18,18,18,18,18,18,18,18,18,18,18,18,18,18
endlayer

layer
18,18,18,18,18,18,18,18,18,18,18,18,18,18,18,18,18,18,18
18,18,18,18,18,18,18,18,18,18,18,18,18,18,18,18,18,18,18
18,18,18,18,18,18,18,7,18,18,18,18,18,18,18,18,18,18,18
18,18,18,18,18,18,18,18,18,18,18,18,18,18,18,18,18,18,18
18,18,18,18,18,18,18,18,18,18,18,18,18,18,18,18,18,18,18
18,18,18,18,18,18,18,18,18,18,18,18,18,18,18,18,18,18,18
18,18,18,18,18,18,18,18,18,18,18,18,18,18,18,18,18,18,18
18,18,18,18,18,18,18,18,18,18,18,18,18,18,18,18,18,18,18
18,18,18,18,18,18,18,18,18,18,18,18,18,18,18,18,18,18,18
18,18,18,18,18,18,18,18,18,18,18,18,18,18,18,18,18,18,18
18,18,18,18,18,18,18,18,18,18,18,18,18,18,18,18,18,18,18
18,18,18,18,18,18,18,18,18,18,18,18,18,18,18,18,18,18,18
18,18,18,18,18,18,18,18,18,18,18,18,18,18,18,18,18,18,18
18,18,18,18,18,18,18,18,18,18,18,18,18,18,18,18,18,18,18
18,18,18,18,18,18,18,18,18,18,18,18,18,18,18,18,18,18,18
18,18,18,18,18,18,18,18,18,18,18,18,18,18,18,18,18,18,18
18,18,18,18,18,18,18,18,18,18,18,18,18,18,18,18,18,18,18
endlayer

