# 水磨遗迹生成文件
# 特点是由水磨石建成且附有砂砾，具有守卫者和远古守卫者刷怪笼、中庭被水淹没、仅在走廊出现的巫水和附带机器方块和机器框架的运算压印模具宝箱
# 在水星的水底生成

weight=1
embed_into_distance=66
acceptable_target_blocks=water
unacceptable_target_blocks=
dimensions=11,19,19
allowable_overhang=0
max_leveling=0
leveling_buffer=0
preserve_water=0
preserve_lava=0
biomesToSpawnIn=<plains>

rule1=0,100,minecraft:gravel-0
rule2=0,100,chisel:waterstone1-1
rule3=0,100,tconstruct:clear_stained_glass-11
rule4=0,100,chisel:waterstone1-11
rule5=0,100,chisel:waterstone1-12
rule6=0,100,chisel:waterstone-7
rule7=0,100,chisel:waterstone1-8
rule8=0,100,minecraft:stone_slab-8
rule9=0,100,minecraft:stone_slab-0
rule10=0,100,MobSpawner:minecraft:guardian
rule11=0,100,exnihilocreatio:witchwater-0
rule12=0,100,exnihilocreatio:witchwater-0
rule13=0,100,minecraft:sea_lantern-0
rule14=0,100,minecraft:water-0
rule15=0,100,exnihilocreatio:witchwater-0
rule16=0,100,IInventory;minecraft:chest;thermalexpansion:frame#1#0#0+extrautils2:machine#1#0#1+extrautils2:machine#1#0#7+thermalexpansion:frame#1#0#8+extrautils2:machine#1#0#9+appliedenergistics2:material#1#13#13+extrautils2:machine#1#0#17+thermalexpansion:frame#1#0#18+extrautils2:machine#1#0#19+extrautils2:machine#1#0#25+thermalexpansion:frame#1#0#26-4
rule17=0,100,chisel:waterstone1-6
rule18=0,100,MobSpawner:minecraft:elder_guardian

layer
1,1,1,2,3,3,3,1,1,1,1,1,3,3,3,2,1,1,1
1,4,5,4,4,6,6,6,6,6,6,6,6,6,4,4,5,4,1
1,5,6,6,6,6,6,5,5,5,5,5,7,7,7,7,7,5,1
2,4,6,4,4,4,6,5,4,4,4,5,7,4,4,4,7,4,2
3,4,6,4,4,4,6,5,4,4,4,5,7,4,4,4,7,4,3
3,6,6,4,4,4,6,5,4,4,4,5,7,4,4,4,7,6,3
3,6,6,6,6,6,6,5,5,5,5,5,7,7,7,7,7,6,3
1,6,4,4,4,4,4,6,6,6,6,6,7,7,7,7,7,6,1
1,6,4,5,5,5,4,6,5,5,5,6,7,5,5,5,7,6,1
1,6,4,5,5,5,4,6,5,5,5,6,7,5,5,5,7,6,1
1,6,4,5,5,5,4,6,5,5,5,6,7,5,5,5,7,6,1
3,6,4,4,4,4,4,6,6,6,6,6,7,7,7,7,7,6,1
3,6,4,4,4,4,4,5,5,5,5,5,6,6,6,6,6,6,1
3,6,4,7,7,7,4,5,7,7,7,5,6,7,7,7,6,6,3
3,4,4,7,7,7,4,5,7,7,7,5,6,7,7,7,6,4,3
2,4,4,7,7,7,4,5,7,7,7,5,6,7,7,7,6,4,3
1,5,4,4,4,4,4,5,5,5,5,5,6,6,6,6,6,5,2
1,4,5,4,4,6,6,6,6,6,6,6,6,6,4,4,5,4,1
1,1,1,2,3,3,3,1,1,1,1,1,1,3,3,3,2,1,1
endlayer

layer
1,1,1,2,3,3,1,1,1,1,1,1,1,3,3,2,1,1,1
1,4,5,4,6,7,7,7,8,9,8,7,7,7,6,4,5,4,1
1,5,10,5,11,12,12,8,9,12,9,8,12,12,11,5,10,5,1
2,4,5,6,6,12,12,12,12,12,12,12,12,12,6,6,5,4,2
3,6,11,6,13,5,5,5,2,2,2,5,5,5,13,6,11,6,3
3,7,12,12,5,14,14,14,14,14,14,14,14,14,5,12,12,7,3
1,7,12,12,5,14,14,14,14,14,14,14,14,14,5,12,11,7,1
1,7,8,12,5,14,14,5,14,14,14,5,14,14,5,12,8,7,1
1,8,9,12,2,14,14,14,14,14,14,14,14,14,2,12,9,8,1
1,9,12,12,2,14,14,14,14,18,14,14,14,14,2,12,12,9,1
1,8,9,12,2,14,14,14,14,14,14,14,14,14,2,12,9,8,1
1,7,8,12,5,14,14,5,14,14,14,5,14,14,5,12,8,7,1
3,7,12,12,5,14,14,14,14,14,14,14,14,14,5,12,12,7,1
3,7,12,12,5,14,14,14,14,14,14,14,14,14,5,12,12,7,1
3,6,12,6,13,5,5,5,2,2,2,5,5,5,13,6,11,6,3
2,4,5,6,6,12,15,15,12,12,12,12,12,12,6,6,5,4,3
1,5,10,5,12,12,12,8,9,12,9,8,12,12,11,5,10,5,2
1,4,5,4,6,7,7,7,8,9,8,7,7,7,6,4,5,4,1
1,1,1,2,3,3,1,1,1,1,1,1,1,1,3,3,2,1,1
endlayer

layer
1,1,1,2,3,1,1,1,1,1,1,1,1,1,3,2,1,1,1
1,4,5,6,6,6,7,7,8,8,8,7,7,6,6,6,5,4,1
1,5,4,5,0,8,9,12,12,12,12,12,9,8,0,5,4,5,1
2,6,5,4,0,12,12,12,12,12,12,12,12,12,0,4,5,6,2
3,6,0,0,0,5,7,7,7,2,7,7,7,5,0,0,0,6,3
1,6,8,12,5,14,14,14,14,14,14,14,14,14,5,12,8,6,1
1,7,9,12,7,14,14,14,14,14,14,14,14,14,7,12,9,7,1
1,7,12,12,7,14,14,5,14,14,14,5,14,14,7,12,12,7,1
1,8,12,12,7,14,14,14,14,14,14,14,14,14,7,12,12,8,1
1,8,12,12,2,14,14,14,14,16,14,14,14,14,2,12,12,8,1
1,8,12,12,7,14,14,14,14,14,14,14,14,14,7,12,12,8,1
1,7,12,12,7,14,14,5,14,14,14,5,14,14,7,12,12,7,1
1,7,9,15,7,14,14,14,14,14,14,14,14,14,7,12,9,7,1
3,6,8,12,5,14,14,14,14,14,14,14,14,14,5,12,8,6,1
3,6,12,15,0,5,7,7,7,2,7,7,7,5,0,0,0,6,1
2,6,5,4,15,12,12,12,12,12,12,12,12,12,0,4,5,6,3
1,5,4,5,12,8,9,12,12,12,12,12,9,8,0,5,4,5,2
1,4,5,6,6,6,7,7,8,8,8,7,7,6,6,6,5,4,1
1,1,1,2,3,1,1,1,1,1,1,1,1,1,1,3,2,1,1
endlayer

layer
1,1,1,2,1,1,1,1,1,1,1,1,1,1,1,2,1,1,1
1,6,5,6,6,6,6,7,17,6,17,7,6,6,6,6,5,6,1
1,5,4,15,9,12,12,12,12,12,15,12,15,15,9,12,4,5,1
2,6,12,4,8,12,12,12,15,12,12,12,12,12,8,4,15,6,2
1,6,9,8,0,5,7,7,7,2,7,7,7,5,0,8,9,6,1
1,6,12,12,5,14,14,14,14,14,14,14,14,14,5,12,12,6,1
1,6,12,12,7,14,14,14,14,14,14,14,14,14,7,12,12,6,1
1,7,12,12,7,14,14,5,8,17,8,5,14,14,7,12,12,7,1
1,17,12,12,7,14,14,8,14,14,14,8,14,14,7,12,12,17,1
1,6,12,12,2,14,14,17,14,14,14,17,14,14,2,12,12,8,1
1,17,12,15,7,14,14,8,14,14,14,8,14,14,7,12,12,17,1
1,7,12,15,7,14,14,5,8,17,8,5,14,14,7,12,12,7,1
1,6,12,15,7,14,14,14,14,14,14,14,14,14,7,12,12,6,1
1,6,15,15,5,14,14,14,14,14,14,14,14,14,5,12,15,6,1
3,6,9,8,0,5,7,7,7,2,7,7,7,5,0,8,9,6,1
2,6,15,4,8,12,12,12,12,12,12,12,12,15,8,4,15,6,1
1,5,4,15,9,12,12,12,12,12,12,12,12,15,9,15,4,5,2
1,6,5,6,6,6,6,7,17,6,17,7,6,6,6,6,5,6,1
1,1,1,2,1,1,1,1,1,1,1,1,1,1,1,1,2,1,1
endlayer

layer
1,1,1,1,1,1,1,1,1,1,1,1,1,1,1,1,1,1,1
1,1,1,17,17,17,17,17,17,17,17,17,17,17,17,17,1,1,1
1,1,4,15,15,15,15,15,15,15,15,15,15,15,15,15,4,1,1
1,17,15,4,15,15,15,15,15,15,15,15,15,15,15,4,15,17,2
1,17,15,15,9,5,4,4,2,2,2,4,4,5,9,15,15,17,1
1,17,15,15,5,17,3,3,3,3,3,3,3,17,5,15,15,17,1
1,17,15,15,4,3,14,14,14,14,14,14,14,3,4,15,15,17,1
1,17,15,15,4,3,14,14,14,14,14,14,14,3,4,15,15,17,1
1,17,15,15,2,3,14,14,9,7,9,14,14,3,2,15,15,17,1
1,17,15,15,2,3,14,14,7,17,7,14,14,3,2,15,15,17,1
1,17,15,15,2,3,14,14,9,7,9,14,14,3,2,15,15,17,1
1,17,15,15,4,3,14,14,14,14,14,14,14,3,4,15,15,17,1
1,17,15,15,4,3,14,14,14,14,14,14,14,3,4,15,15,17,1
1,17,15,15,5,17,3,3,3,3,3,3,3,17,5,15,15,17,1
1,17,15,15,9,5,4,4,2,2,2,4,4,5,9,15,15,17,1
2,17,15,4,15,15,15,15,15,15,15,15,15,15,15,5,15,17,1
1,1,4,15,15,15,15,15,15,15,15,15,15,15,15,15,4,1,1
1,1,1,17,17,17,17,17,17,17,17,17,17,17,17,17,1,1,1
1,1,1,2,1,1,1,1,1,1,1,1,1,1,1,1,1,1,1
endlayer

layer
1,1,1,1,1,1,1,1,1,1,1,1,1,1,1,1,1,1,1
1,1,1,1,3,3,1,1,1,1,1,1,1,3,3,1,1,1,1
1,1,4,6,0,8,6,6,6,6,6,6,6,8,0,6,4,1,1
1,1,6,4,0,0,0,0,0,0,0,0,0,0,0,4,6,1,1
1,3,0,0,0,0,5,17,17,17,17,17,5,0,0,0,0,3,1
1,3,8,0,0,5,0,0,0,0,0,0,0,5,0,0,8,3,1
1,1,6,0,5,0,0,0,0,0,0,0,0,0,5,0,6,1,1
1,1,6,0,17,0,0,0,0,0,0,0,0,0,17,0,6,1,1
1,1,6,0,17,0,0,0,0,0,0,0,0,0,17,0,6,1,1
1,1,6,0,17,0,0,0,0,0,0,0,0,0,17,0,6,1,1
1,1,6,0,17,0,0,0,0,0,0,0,0,0,17,0,6,1,1
1,1,6,0,17,0,0,0,0,0,0,0,0,0,17,0,6,1,1
1,1,6,0,5,0,0,0,0,0,0,0,0,0,5,0,6,1,1
1,3,9,0,0,5,0,0,0,0,0,0,0,0,0,0,8,3,1
1,3,0,0,0,0,5,17,17,17,17,17,5,0,0,0,0,3,1
1,1,6,4,0,0,0,0,0,0,0,0,0,0,0,4,6,1,1
1,1,4,6,0,8,6,6,6,6,6,6,6,8,0,6,4,1,1
1,1,1,1,3,3,1,1,1,1,1,1,1,3,3,1,1,1,1
1,1,1,1,1,1,1,1,1,1,1,1,1,1,1,1,1,1,1
endlayer

layer
14,14,14,14,14,14,14,14,14,14,14,14,14,14,14,14,14,14,14
14,14,14,14,14,14,14,1,14,14,14,1,1,1,14,14,14,14,14
14,14,14,14,7,7,3,3,3,3,3,3,3,7,7,14,14,14,14
14,14,14,4,0,0,0,0,0,0,0,0,0,0,0,4,14,14,14
14,14,7,0,0,0,5,2,2,2,2,2,5,0,0,0,7,14,14
14,14,7,0,0,5,0,0,0,0,0,0,0,5,0,0,7,14,14
14,14,3,0,5,0,0,0,0,0,0,0,0,0,5,0,3,14,14
14,14,3,0,2,0,0,0,0,0,0,0,0,0,2,0,3,14,14
14,14,3,0,2,0,0,0,0,0,0,0,0,0,2,0,3,1,14
14,14,3,0,2,0,0,0,0,0,0,0,0,0,2,0,3,14,14
14,14,3,0,2,0,0,0,0,0,0,0,0,0,2,0,3,14,14
14,14,3,0,2,0,0,0,0,0,0,0,0,0,2,0,3,14,14
14,14,3,0,5,0,0,0,0,0,0,0,0,0,5,0,3,14,14
14,14,7,0,0,5,0,0,0,0,0,0,0,0,0,0,7,14,14
14,14,7,0,0,0,5,2,2,2,2,2,5,0,0,0,7,14,14
14,14,14,4,0,0,0,0,0,0,0,0,0,0,0,4,14,14,14
14,14,14,14,7,7,3,3,3,3,3,3,3,7,7,14,14,14,14
14,14,14,14,14,14,14,1,1,1,1,1,1,0,1,14,14,14,14
14,14,14,14,14,14,14,14,14,14,14,14,14,14,14,14,14,14,14
endlayer

layer
14,14,14,14,14,14,14,14,14,14,14,14,14,14,14,14,14,14,14
14,14,14,14,14,14,14,14,14,14,14,14,14,14,14,14,14,14,14
14,14,14,14,14,14,14,1,14,14,1,1,1,1,14,14,14,14,14
14,14,14,4,17,17,17,17,17,17,17,17,17,17,17,4,14,14,14
14,14,14,17,0,0,5,6,6,6,6,6,5,0,0,17,14,14,14
14,14,14,17,0,0,5,8,8,8,8,8,5,0,0,17,14,14,14
14,14,14,17,5,5,5,0,0,0,0,0,5,5,5,17,1,14,14
14,14,14,17,6,8,0,0,0,0,0,0,0,8,6,17,1,14,14
14,14,14,17,6,8,0,0,0,0,0,0,0,8,6,17,14,14,14
14,14,14,17,6,8,0,0,0,0,0,0,0,8,6,17,14,14,14
14,14,14,17,6,8,0,0,0,0,0,0,0,8,6,17,14,14,14
14,14,14,17,6,8,0,0,0,0,0,0,0,8,6,17,14,14,14
14,14,14,17,5,5,5,0,0,0,0,0,5,5,5,17,14,14,14
14,14,14,17,0,0,5,8,8,8,8,8,5,0,0,17,14,14,14
14,14,14,17,0,0,5,6,6,6,6,6,5,0,0,17,14,14,14
14,14,14,4,17,17,17,17,17,17,17,17,17,17,17,4,14,14,14
14,14,14,14,14,14,14,1,1,1,1,1,14,14,1,14,14,14,14
14,14,14,14,14,14,14,14,14,14,14,14,14,14,14,14,14,14,14
14,14,14,14,14,14,14,14,14,14,14,14,14,14,14,14,14,14,14
endlayer

layer
14,14,14,14,14,14,14,14,14,14,14,14,14,14,14,14,14,14,14
14,14,14,14,14,14,14,14,14,14,14,14,14,14,14,14,14,14,14
14,14,14,14,14,14,14,14,14,14,14,1,14,14,14,14,14,14,14
14,14,14,14,5,5,14,1,14,1,14,14,14,5,5,14,14,14,14
14,14,14,5,13,13,5,1,14,14,14,14,5,13,13,5,14,14,14
14,14,14,5,13,13,5,1,1,14,14,14,5,13,13,5,14,14,14
14,14,14,14,5,5,7,7,7,7,7,7,7,5,5,1,14,14,14
14,14,14,14,14,14,7,0,0,4,0,0,7,14,1,14,14,14,14
14,14,14,14,14,14,7,0,0,0,0,0,7,14,14,1,14,14,14
14,14,14,14,14,14,7,4,0,0,0,4,7,14,14,14,14,14,14
14,14,14,14,14,14,7,0,0,0,0,0,7,14,14,14,14,14,14
14,14,14,14,14,14,7,0,0,4,0,0,7,14,1,14,14,14,14
14,14,14,14,5,5,7,7,7,7,7,7,7,5,5,14,14,14,14
14,14,14,5,13,13,5,14,14,14,14,14,5,13,13,5,14,14,14
14,14,14,5,13,13,5,1,14,14,14,14,5,13,13,5,14,14,14
14,14,14,14,5,5,1,14,14,14,14,14,14,5,5,1,14,14,14
14,14,14,14,14,14,14,1,1,1,14,14,14,14,14,14,14,14,14
14,14,14,14,14,14,14,14,14,14,14,14,14,14,14,14,14,14,14
14,14,14,14,14,14,14,14,14,14,14,14,14,14,14,14,14,14,14
endlayer

layer
14,14,14,14,14,14,14,14,14,14,14,14,14,14,14,14,14,14,14
14,14,14,14,14,14,14,14,14,14,14,14,14,14,14,14,14,14,14
14,14,14,14,14,14,14,14,14,14,14,14,14,14,14,14,14,14,14
14,14,14,14,14,14,14,14,14,14,14,14,14,14,14,14,14,14,14
14,14,14,14,2,2,14,14,14,14,14,14,1,2,2,1,14,14,14
14,14,14,14,2,2,14,14,14,14,14,14,14,2,2,14,14,14,14
14,14,14,14,14,14,1,14,14,14,14,1,14,14,14,14,14,14,14
14,14,14,14,14,14,14,2,2,17,2,2,14,14,14,14,14,14,14
14,14,14,14,14,14,1,2,0,0,0,2,14,14,14,14,14,14,14
14,14,14,14,14,14,1,17,4,0,4,17,14,14,14,14,14,14,14
14,14,14,14,14,14,14,2,0,0,0,2,14,14,14,14,14,14,14
14,14,14,14,14,14,14,2,2,17,2,2,14,14,14,14,14,14,14
14,14,14,14,14,14,14,1,14,14,14,14,14,14,1,14,14,14,14
14,14,14,14,2,2,14,14,14,14,14,14,14,2,2,14,14,14,14
14,14,14,14,2,2,14,14,14,14,14,14,14,2,2,1,14,14,14
14,14,14,14,14,1,14,14,14,14,14,14,14,14,14,14,14,14,14
14,14,14,14,14,14,14,14,14,14,14,14,14,14,14,14,14,14,14
14,14,14,14,14,14,14,14,14,14,14,14,14,14,14,14,14,14,14
14,14,14,14,14,14,14,14,14,14,14,14,14,14,14,14,14,14,14
endlayer

layer
14,14,14,14,14,14,14,14,14,14,14,14,14,14,14,14,14,14,14
14,14,14,14,14,14,14,14,14,14,14,14,14,14,14,14,14,14,14
14,14,14,14,14,14,14,14,14,14,14,14,14,14,14,14,14,14,14
14,14,14,14,14,14,14,14,14,14,14,14,14,14,14,14,14,14,14
14,14,14,14,14,14,14,14,14,14,14,14,14,14,14,14,14,14,14
14,14,14,14,14,14,14,14,14,14,14,14,14,14,14,14,14,14,14
14,14,14,14,14,14,14,14,14,14,14,14,14,14,14,14,14,14,14
14,14,14,14,14,14,14,14,14,14,14,14,14,14,14,14,14,14,14
14,14,14,14,14,14,14,14,7,7,4,14,14,14,14,14,14,14,14
14,14,14,14,14,14,14,14,14,4,14,14,14,14,14,14,14,14,14
14,14,14,14,14,14,14,1,4,4,4,14,14,14,14,14,14,14,14
14,14,14,14,14,14,14,14,14,14,14,14,14,14,14,14,14,14,14
14,14,14,14,14,14,14,14,14,14,14,14,14,14,14,14,14,14,14
14,14,14,14,14,14,14,14,14,14,14,14,14,14,1,14,14,14,14
14,14,14,14,14,1,14,14,14,14,14,14,14,14,14,14,14,14,14
14,14,14,14,14,14,14,14,14,14,14,14,14,14,14,14,14,14,14
14,14,14,14,14,14,14,14,14,14,14,14,14,14,14,14,14,14,14
14,14,14,14,14,14,14,14,14,14,14,14,14,14,14,14,14,14,14
14,14,14,14,14,14,14,14,14,14,14,14,14,14,14,14,14,14,14
endlayer

