# 海洋哨岗的生成文件
# 特点是由海晶石建成且附有砂砾，具有守卫者刷怪笼和一个地牢箱子
# 在水星的水底生成

weight=1
embed_into_distance=64
acceptable_target_blocks=water
unacceptable_target_blocks=
dimensions=9,9,9
allowable_overhang=0
max_leveling=0
leveling_buffer=0
preserve_water=0
preserve_lava=0
biomesToSpawnIn=<plains>

rule1=0,100,minecraft:gravel-0
rule2=0,100,chisel:prismarine2-4
rule3=0,100,minecraft:water-0
rule4=0,100,minecraft:sea_lantern-0
rule5=0,100,chisel:prismarine-11
rule6=0,100,chisel:prismarine1-2
rule7=0,100,minecraft:prismarine-2
rule8=0,100,minecraft:water-8
rule9=0,100,ChestGenHook:chests/simple_dungeon:5-5
rule10=0,100,MobSpawner:minecraft:guardian
rule11=0,100,chisel:glass-14
rule12=0,100,chisel:obsidian-13
rule13=0,100,chisel:obsidian-4

layer
1,1,1,1,1,1,1,1,1
1,1,2,1,1,1,2,1,1
1,2,3,1,1,1,1,2,1
1,1,1,1,1,1,1,1,1
1,1,1,1,1,1,1,1,1
1,1,1,1,1,1,1,1,1
1,2,1,1,1,1,1,2,1
1,1,2,1,1,1,2,1,1
1,1,1,1,1,1,1,1,1
endlayer

layer
1,1,1,1,1,1,1,1,1
1,1,2,1,1,1,2,1,1
1,2,3,1,1,1,1,2,1
1,1,1,1,1,1,1,1,1
1,1,1,1,1,1,1,1,1
1,1,1,1,1,1,1,1,1
1,2,1,1,1,1,1,2,1
1,1,2,1,1,1,2,1,1
1,1,1,1,1,1,1,1,1
endlayer

layer
1,1,1,1,1,1,1,1,1
1,1,2,1,1,1,2,1,1
1,2,4,5,5,5,4,2,1
1,1,5,6,6,6,5,3,1
1,1,5,6,6,6,5,3,1
1,1,5,6,6,6,5,3,1
1,2,4,5,5,5,4,2,1
1,1,2,1,1,1,2,1,1
1,1,1,1,1,1,1,1,1
endlayer

layer
1,1,1,1,1,1,1,1,1
1,1,2,1,1,1,2,1,1
1,2,7,7,8,7,7,2,1
1,1,7,3,1,3,7,3,1
1,1,1,3,9,1,1,3,1
1,1,7,3,1,3,7,3,1
1,2,7,7,1,7,7,2,1
1,1,2,1,1,1,2,1,1
1,1,1,1,1,1,1,1,1
endlayer

layer
3,3,5,3,1,3,5,3,3
3,3,5,3,3,1,5,3,3
5,5,7,3,3,3,7,5,5
1,3,3,3,3,3,3,3,1
1,3,3,3,10,3,3,3,3
3,1,3,3,3,3,3,3,1
5,5,7,3,3,3,7,5,5
3,1,5,3,1,3,5,3,3
3,3,5,1,1,3,5,3,3
endlayer

layer
3,3,7,3,3,3,7,3,3
3,3,11,3,11,3,11,3,3
7,11,7,3,3,3,7,11,7
3,3,3,3,3,3,3,3,3
3,11,3,3,3,3,3,11,3
3,3,3,3,3,3,3,3,3
7,11,7,3,3,3,7,11,7
3,3,11,3,11,3,11,3,3
3,3,7,1,3,3,7,3,3
endlayer

layer
3,3,3,3,3,3,3,3,3
3,12,12,2,2,2,12,12,3
3,12,12,13,13,13,12,12,1
3,2,13,13,13,13,13,2,3
3,2,13,13,13,13,13,2,3
3,2,13,13,13,13,13,2,3
3,12,12,13,13,13,12,12,1
3,12,12,2,2,2,12,12,3
3,3,3,3,3,3,3,3,3
endlayer

layer
3,3,3,3,3,3,3,3,3
3,3,3,3,3,3,3,3,3
3,3,6,5,5,5,6,3,3
3,3,5,3,1,3,5,3,3
3,3,5,1,4,1,5,3,3
3,3,5,3,1,3,5,1,3
3,3,6,5,5,5,6,3,3
3,3,3,3,3,3,3,3,3
3,3,3,3,3,3,3,3,3
endlayer

layer
3,3,3,3,3,3,3,3,3
3,2,3,3,3,3,3,2,3
3,3,2,3,1,3,2,3,3
3,3,3,3,3,3,3,3,3
3,3,3,1,1,3,1,3,3
3,3,3,3,3,3,1,3,3
3,3,2,3,3,3,2,3,3
3,2,3,3,3,3,3,2,3
3,3,3,3,3,3,3,3,3
endlayer

